Workbook

Sheet Dashboard
A1: APW 2026/27 – Parametric six-way shuttle warehouse: optimizer dashboard
A2: Only the lift and shuttle data are fixed (sheet 'Equipment'). Change any blue cell: the optimizer re-derives lifts, lanes, shuttles and cost for every combination of lane depth N_C × tiers N_T and picks the best one.
A4: INPUTS (blue on yellow) | B4: Value | C4: Unit | E4: RESULT | F4: Optimal design | G4: Manual design
A5: Requirements and operation | E5: Lane depth N_C | F5: =IF(n_feas=0,"n/a",INDEX(Optimizer!$B$8:$B$227,best_i)) -> 8 | G5: =Optimizer!B7 -> 8
A6: Required effective capacity | B6: 4000 | C6: pallets | E6: Tiers N_T | F6: =IF(n_feas=0,"n/a",INDEX(Optimizer!$C$8:$C$227,best_i)) -> 8 | G6: =Optimizer!C7 -> 8
A7: Pallets per SKU | B7: 6 | C7: pallets | E7: Lifts | F7: =IF(n_feas=0,"n/a",INDEX(Optimizer!$G$8:$G$227,best_i)) -> 2 | G7: =Optimizer!G7 -> 2
A8: Inbound rate | B8: 40 | C8: pallets/h | E8: Lanes per side N_L | F8: =IF(n_feas=0,"n/a",INDEX(Optimizer!$H$8:$H$227,best_i)) -> 40 | G8: =Optimizer!H7 -> 40
A9: Outbound rate (during working hours) | B9: 60 | C9: pallets/h | E9: Aisle length (m) | F9: =IF(n_feas=0,"n/a",INDEX(Optimizer!$I$8:$I$227,best_i)) -> 40 | G9: =Optimizer!I7 -> 40
A10: Inbound hours per day | B10: 24 | C10: h | E10: Block depth (m) | F10: =IF(n_feas=0,"n/a",INDEX(Optimizer!$J$8:$J$227,best_i)) -> 22.1 | G10: =Optimizer!J7 -> 22.1
A11: Outbound hours per day | B11: 16 | C11: h | E11: Rack height (m) | F11: =IF(n_feas=0,"n/a",INDEX(Optimizer!$K$8:$K$227,best_i)) -> 17.2 | G11: =Optimizer!K7 -> 17.2
A12: Peak design factor (1.25 = +25 %) | B12: 1 | C12: x | E12: D/W | F12: =IF(n_feas=0,"n/a",INDEX(Optimizer!$AA$8:$AA$227,best_i)) -> 0.26 | G12: =Optimizer!AA7 -> 0.26
A13: Building limits | E13: Net positions | F13: =IF(n_feas=0,"n/a",INDEX(Optimizer!$R$8:$R$227,best_i)) -> 4736 | G13: =Optimizer!R7 -> 4736
A14: Maximum rack height available | B14: 20 | C14: m | E14: Effective positions | F14: =IF(n_feas=0,"n/a",INDEX(Optimizer!$S$8:$S$227,best_i)) -> 4025.6 | G14: =Optimizer!S7 -> 4025.6
A15: Constrain footprint to the building below? | B15: Yes | E15: Footprint (m²) | F15: =IF(n_feas=0,"n/a",INDEX(Optimizer!$T$8:$T$227,best_i)) -> 884 | G15: =Optimizer!T7 -> 884
A16: Building length | B16: 45 | C16: m | E16: Shuttle cycle (s) | F16: =IF(n_feas=0,"n/a",INDEX(Optimizer!$O$8:$O$227,best_i)) -> 87.781007 | G16: =Optimizer!O7 -> 87.781007
A17: Building width | B17: 30 | C17: m | E17: Shuttles incl. spares | F17: =IF(n_feas=0,"n/a",INDEX(Optimizer!$Q$8:$Q$227,best_i)) -> 12 | G17: =Optimizer!Q7 -> 12
A18: Lane policy and ABC distribution | E18: Lift utilization | F18: =IF(n_feas=0,"n/a",INDEX(Optimizer!$AB$8:$AB$227,best_i)) -> 0.37582341 | G18: =Optimizer!AB7 -> 0.37582341
A19: Lane depth N_C | B19: Free (optimize N_C) | E19: Lift util., one lift down | F19: =IF(n_feas=0,"n/a",INDEX(Optimizer!$AC$8:$AC$227,best_i)) -> 0.75164683 | G19: =Optimizer!AC7 -> 0.75164683
A20: Distribution of transactions over tiers | B20: ABC | E20: Lift energy (kWh/day) | F20: =IF(n_feas=0,"n/a",INDEX(Optimizer!$AD$8:$AD$227,best_i)) -> 12.93612 | G20: =Optimizer!AD7 -> 12.93612
A21: Tiers for class A (lowest) | B21: 2 | C21: tiers | E21: Total cost (EUR) | F21: =IF(n_feas=0,"n/a",INDEX(Optimizer!$Z$8:$Z$227,best_i)) -> 2223124 | G21: =Optimizer!Z7 -> 2223124
A22: Tiers for class B | B22: 3 | C22: tiers | E22: Cost per effective pallet (EUR) | F22: =IF(n_feas=0,"n/a",INDEX(Optimizer!$Z$8:$Z$227,best_i)/INDEX(Optimizer!$S$8:$S$227,best_i)) -> 552.24662 | G22: =Optimizer!Z7/Optimizer!S7 -> 552.24662
A23: Share of transactions class A | B23: 0.8 | E23: Feasible? | F23: =IF(n_feas=0,"NO feasible design",IF(INDEX(Optimizer!$AE$8:$AE$227,best_i)=1,"Yes","No")) -> Yes | G23: =IF(Optimizer!AE7=1,"Yes","No – "&Optimizer!AH7) -> Yes
A24: Share of transactions class B | B24: 0.15 | E24: =IF(n_feas=0,"No design satisfies the constraints: relax height / footprint / lane policy.","Designs satisfying all constraints: "&n_feas&" of 220") -> Designs satisfying all constraints: 12 of 220
A25: Share of transactions class C | B25: 0.05
A26: Pallet and rack geometry | E26: Top 5 | F26: N_C | G26: N_T | H26: Lifts | I26: N_L | J26: Shuttles | K26: Cycle (s) | L26: Cost (EUR)
A27: Lane pitch across lanes u_w (pallet 850 + 150 upright) | B27: 1 | C27: m | E27: 1 | F27: =Chart_data!C82 -> 8 | G27: =Chart_data!D82 -> 8 | H27: =Chart_data!E82 -> 2 | I27: =Chart_data!F82 -> 40 | J27: =Chart_data!G82 -> 12 | K27: =Chart_data!L82 -> 87.781007 | L27: =Chart_data!M82 -> 2223124
A28: Position pitch along lane u_d (pallet 1250 + 50) | B28: 1.3 | C28: m | E28: 2 | F28: =Chart_data!C83 -> 10 | G28: =Chart_data!D83 -> 7 | H28: =Chart_data!E83 -> 2 | I28: =Chart_data!F83 -> 37 | J28: =Chart_data!G83 -> 11 | K28: =Chart_data!L83 -> 89.467691 | L28: =Chart_data!M83 -> 2231554.6
A29: Vertical pitch u_h (pallet 1700 + 450 rail zone) | B29: 2.15 | C29: m | E29: 3 | F29: =Chart_data!C84 -> 8 | G29: =Chart_data!D84 -> 9 | H29: =Chart_data!E84 -> 2 | I29: =Chart_data!F84 -> 36 | J29: =Chart_data!G84 -> 13 | K29: =Chart_data!L84 -> 87.058262 | L29: =Chart_data!M84 -> 2241087.8
A30: Cross-aisle width (slide: 1300 mm) | B30: 1.3 | C30: m | E30: 4 | F30: =Chart_data!C85 -> 10 | G30: =Chart_data!D85 -> 8 | H30: =Chart_data!E85 -> 2 | I30: =Chart_data!F85 -> 33 | J30: =Chart_data!G85 -> 12 | K30: =Chart_data!L85 -> 88.743429 | L30: =Chart_data!M85 -> 2245764.9
A31: Offset aisle centre → first slot / lift | B31: 1.3 | C31: m | E31: 5 | F31: =Chart_data!C86 -> 12 | G31: =Chart_data!D86 -> 8 | H31: =Chart_data!E86 -> 2 | I31: =Chart_data!F86 -> 28 | J31: =Chart_data!G86 -> 12 | K31: =Chart_data!L86 -> 90.062663 | L31: =Chart_data!M86 -> 2254510
A32: Headroom above racks | B32: 1.5 | C32: m | E32: Tip: switch 'Lane depth N_C' to 'Free', the objective or ABC to see how the optimum moves.
A33: Honeycombing factor f | B33: 0.2
A34: Lanes replaced by each lift shaft | B34: 3 | C34: lanes | E34: IN / OUT bays and lifts (optimal design)
A35: Average fill ratio | B35: 0.85 | E35: Lift layout used | F35: =lift_layout -> Equispaced
A36: Design rules | E36: Lift positions in aisle (m) | F36: =IF(Bay_position!B12="","",IF(0>0," / ","")&TEXT(Bay_position!B12,"0.0"))&IF(Bay_position!B13="","",IF(1>0," / ","")&TEXT(Bay_position!B13,"0.0"))&IF(Bay_position!B14="","",IF(2>0," / ","")&TEXT(Bay_position!B14,"0.0"))&IF(Bay_position!B15="","",IF(3>0," / ","")&TEXT(Bay_position!B15,"0.0"))&IF(Bay_position!B16="","",IF(4>0," / ","")&TEXT(Bay_position!B16,"0.0"))&IF(Bay_position!B17="","",IF(5>0," / ","")&TEXT(Bay_position!B17,"0.0")) -> 10.0 / 30.0
A37: Max utilization (normal operation) | B37: 0.75 | E37: Mean shuttle aisle leg (s) | F37: =sum_ta -> 7.2819788
A38: Max lift utilization with one lift down | B38: 0.95 | E38: Shuttle cycle with this layout (s) | F38: =sum_cyc -> 87.8211
A39: N+1 redundancy on lifts | B39: Yes | E39: Mean conveyor length (m) | F39: =sum_cv -> 33.45
A40: Minimum shuttles per active tier (0.4 ≈ roaming pool) | B40: 1 | C40: shuttles | E40: Mean conveyor time (s) | F40: =sum_ct -> 83.625
A41: Spare shuttles | B41: 2 | C41: shuttles | E41: Installed ground conveyor (m) | F41: =sum_trunk -> 119.2
...

Sheet Equipment
A1: LIFT AND SHUTTLE DATA – fixed by the assignment
A3: Parameter | B3: Value | C3: Unit | D3: Note
A4: Shuttle max speed | B4: 1.4 | C4: m/s
A5: Shuttle acceleration = deceleration | B5: 0.5 | C5: m/s²
A6: Direction change time | B6: 4 | C6: s
A7: Shuttle load/unload (rack / conveyor) | B7: 25 | C7: s
A8: Lift max speed | B8: 1 | C8: m/s
A9: Lift acceleration | B9: 0.7 | C9: m/s²
A10: Lift positioning time | B10: 1 | C10: s
A11: Lift load/unload with chain conveyor | B11: 7 | C11: s
A12: Lift load/unload with shuttle | B12: 25 | C12: s
A13: Lift interface at the tiers | B13: Shuttle | D13: 'Shuttle' = 25 s hand-over; 'Chain' = chain conveyor buffer at each tier (7 s)
A14: Interface time used (t_I) | B14: =IF(lift_iface="Chain",t_ch,t_lift_sh) -> 25
A16: Reference data (not used in the equations): shuttle 1045×890×197 mm, 260 kg, capacity 1000 kg, battery 8 h; lift 470 kg, capacity 1800 kg, 16 kW.
A18: Derived values
A19: Peak transactions (in + out) | B19: =(lam_in+lam_out)*peak_factor -> 100 | C19: tx/h
A20: Pallet movements per day | B20: =lam_in*hours_in+lam_out*hours_out -> 1920 | C20: mov/day
A21: Positions to build (capacity / fill) | B21: =cap_req/fill -> 4705.8824 | C21: pallets
A23: Shuttle battery 50 V × 30 Ah (slide) | B23: 1.5 | C23: kWh | D23: Runtime 8 h (slide); not used in the equations

Sheet README
A1: APW 2026/27 – Parametric warehouse optimizer: how it works
A3: What it does
A4: Given the requirements (capacity, flows, SKU size, building limits, costs), it explores every combination of lane depth N_C and number of tiers N_T and, for each one, derives the number of lifts, the number of lanes, the aisle length, the shuttle fleet, the cost and the feasibility. The best design is shown on the Dashboard, together with a manual design for comparison.
A6: What is fixed
A7: Only the lift and shuttle kinematics (sheet Equipment). Everything else is an input on the Dashboard.
A9: Derivation of each design (sheet Optimizer)
A10: 1. Lifts: lift workload = peak rate × share of transactions above tier 1 × mean lift cycle / 3600. Lifts n = max(ceil(workload/ρ_max), ceil(workload/ρ_fail)+1 if N+1).
A11: 2. Lanes: N_L = ceil((required positions/(N_C·N_T) + n·lanes per lift)/2). Aisle length = N_L·u_w, block depth = 2·N_C·u_d + aisle width.
A12: 3. Shuttle cycle = 2·25 + 2·4 + 2·(mean aisle leg to the nearest lift) + 2·(mean in-lane leg with honeycombing); lifts equally spaced at (2k−1)L/(2n), mean distance L/(4n).
A13: 4. Shuttles per tier = max(min per tier, ceil(tier load × cycle / (3600 ρ_max))); fleet = sum + spares.
A14: 5. Cost = lifts + shuttles + rack positions + building (footprint × €/m² + volume × €/m³). Costs are ASSUMPTIONS: replace them with real quotes.
A15: 6. Feasible = height ≤ maximum, lane policy respected, footprint inside the building (if constrained). The best feasible design minimizes the chosen objective.
... A30: Geometry now follows the professor's slides: pallet 850×1250×1700 mm, lane pitch 1.00 m (850 + 150 upright), position pitch 1.30 m, vertical pitch 2.15 m (1700 + 450 rail zone), cross-aisle 1.3 m. The vertical pitch and lane pitch are my reading of the drawings: confirm with the professor.

Sheet Optimizer
A1: OPTIMIZER – all combinations of lane depth N_C × tiers N_T (formulas only)
A3: N_C values explored → | B3: 2 | C3: 3 | D3: 4 | E3: 5 | F3: 6 | G3: 8 | H3: 10 | I3: 12 | J3: 16 | K3: 20 | L3: 24
A4: Best score / row / feasible designs → | B4: =MIN(AG8:AG227) -> 2223124 | D4: =MATCH(B4,AG8:AG227,0) -> 108 | F4: =COUNTIF(AE8:AE227,1) -> 12
AJ5: Objective by N_T (rows) and N_C (columns); infeasible = NA
A6: # | B6: N_C | C6: N_T | D6: p lift users | E6: Lift cycle (s) | F6: Lift-equiv. busy | G6: Lifts n | H6: N_L per side | I6: Aisle L (m) | J6: Block depth (m) | K6: Rack height (m) | L6: dmax (m) | M6: t_aisle (s) | N6: t_lane (s) | O6: Shuttle cycle (s) | P6: Σ shuttles needed | Q6: Shuttles + spares | R6: Net positions | S6: Effective positions | T6: Footprint (m²) | U6: Volume (m³) | V6: Cost lifts | W6: Cost shuttles | X6: Cost rack | Y6: Cost building | Z6: Total cost (EUR) | AA6: D/W | AB6: Lift util | AC6: Lift util, one down | AD6: Lift energy (kWh/day) | AE6: Feasible | AF6: Objective | AG6: Score | AH6: Why not | AJ6: N_T \ N_C | AK6: =B3 -> 2 | AL6: =C3 -> 3 | AM6: =D3 -> 4 | AN6: =E3 -> 5 | AO6: =F3 -> 6 | AP6: =G3 -> 8 | AQ6: =H3 -> 10 | AR6: =I3 -> 12 | ... AU6: =L3 -> 24
A7: 0 | B7: =NC_man -> 8 | C7: =NT_man -> 8 | D7: =INDEX(Tc_pl,C7) -> 0.6 | E7: =INDEX(Tc_S,C7) -> 45.09881 | F7: =lam_total*D7*E7/3600 -> 0.75164683 | G7: =IF(F7<=0.000000000001,0,MAX(ROUNDUP(F7/rho_max-0.000000001,0),IF(redund="Yes",ROUNDUP(F7/rho_fail-0.000000001,0)+1,0))) -> 2 | H7: =MAX(1,ROUNDUP((P_req/(B7*C7)+G7*lpl)/2-0.000000001,0)) -> 40 | I7: =H7*u_w -> 40 | J7: =2*B7*u_d+aisle_w -> 22.1 | K7: =C7*u_h -> 17.2 | L7: =IF(G7=0,I7,I7/(2*G7)) -> 10 | M7: =((IF((lane_off+(L7))<=(v_sh^2/a_sh),(4/3)*(lane_off+(L7))^1.5/SQRT(a_sh),(4/3)*(v_sh^2/a_sh)^1.5/SQRT(a_sh)+((lane_off+(L7))^2-(v_sh^2/a_sh)^2)/(2*v_sh)+(v_sh/a_sh)*((lane_off+(L7))-(v_sh^2/a_sh))))-(IF((lane_off)<=(v_sh^2/a_sh),(4/3)*(lane_off)^1.5/SQRT(a_sh),(4/3)*(v_sh^2/a_sh)^1.5/SQRT(a_sh)+((lane_off)^2-(v_sh^2/a_sh)^2)/(2*v_sh)+(v_sh/a_sh)*((lane_off)-(v_sh^2/a_sh)))))/(L7) -> 7.2619322 | N7: =IF(((B7-1)*u_d/2*(1+f_hc)+lane_off)<=0,0,IF(((B7-1)*u_d/2*(1+f_hc)+lane_off)>=v_sh^2/a_sh,((B7-1)*u_d/2*(1+f_hc)+lane_off)/v_sh+v_sh/a_sh,2*SQRT(((B7-1)*u_d/2*(1+f_hc)+lane_off)/a_sh))) -> 7.6285714 | O7: =2*t_sh+2*t_turn+2*M7+2*N7 -> 87.781007 | P7: =SUMPRODUCT((Tc_idx<=C7)*(ROUNDUP(lam_total*INDEX(Tc_P,C7,0)*O7/(3600*rho_max)-0.000000001,0)+(ROUNDUP(lam_total*INDEX(Tc_P,C7,0)*O7/(3600*rho_max)-0.000000001,0)<min_sh)*(min_sh-ROUNDUP(lam_total*INDEX(Tc_P,C7,0)*O7/(3600*rho_max)-0.000000001,0)))) -> 10 | Q7: =ROUNDUP(P7-0.000000001,0)+spares -> 12 | R7: =B7*C7*(2*H7-G7*lpl) -> 4736 | S7: =R7*fill -> 4025.6 | T7: =I7*J7 -> 884 | U7: =T7*(K7+headroom) -> 16530.8 | V7: =G7*c_lift -> 300000 | W7: =Q7*c_shut -> 600000 | X7: =R7*c_pos -> 473600 | Y7: =T7*c_m2+U7*c_m3 -> 849524 | Z7: =SUM(V7:Y7) -> 2223124 | AA7: =B7*u_d/(H7*u_w) -> 0.26 | AB7: =IF(G7=0,0,F7/G7) -> 0.37582341 | AC7: =IF(G7>1,F7/(G7-1),"n/a") -> 0.75164683 | AD7: =moves_day*m_pallet*9.81*INDEX(Tc_mh,C7)/3600000 -> 12.93612 | AE7: =IF(AND(K7<=H_max,H7<=300,OR(lane_policy="Free (optimize N_C)",B7=sku_pal),OR(env_use="No",AND(I7<=L_bldg,J7<=W_bldg),AND(I7<=W_bldg,J7<=L_bldg))),1,0) -> 1 | AF7: =IF(obj_mode="Total cost",Z7,IF(obj_mode="Shuttle cycle",O7,T7)) -> 2223124 | AH7: =IF(AE7=1,"",IF(K7>H_max,"height",IF(AND(lane_policy<>"Free (optimize N_C)",B7<>sku_pal),"lane policy","footprint"))) | AJ7: 1 | AK7: =IF(AE8=1,AF8,NA()) -> #N/A | AL7: =IF(AE28=1,AF28,NA()) -> #N/A | AM7: =IF(AE48=1,AF48,NA()) -> #N/A | AN7: =IF(AE68=1,AF68,NA()) -> #N/A | AO7: =IF(AE88=1,AF88,NA()) -> #N/A | AP7: =IF(AE108=1,AF108,NA()) -> #N/A | AQ7: =IF(AE128=1,AF128,NA()) -> #N/A | AR7: =IF(AE148=1,AF148,NA()) -> #N/A | AS7: =IF(AE168=1,AF168,NA()) -> #N/A | AT7: =IF(AE188=1,AF188,NA()) -> #N/A | AU7: =IF(AE208=1,AF208,NA()) -> #N/A
A8: 1 | B8: =$B$3 -> 2 | C8: 1 | D8: =INDEX(Tc_pl,C8) -> 0 | E8: =INDEX(Tc_S,C8) -> 0 | F8: =lam_total*D8*E8/3600 -> 0 | G8: =IF(F8<=0.000000000001,0,MAX(ROUNDUP(F8/rho_max-0.000000001,0),IF(redund="Yes",ROUNDUP(F8/rho_fail-0.000000001,0)+1,0))) -> 0 | H8: =MAX(1,ROUNDUP((P_req/(B8*C8)+G8*lpl)/2-0.000000001,0)) -> 1177 | I8: =H8*u_w -> 1177 | J8: =2*B8*u_d+aisle_w -> 6.5 | K8: =C8*u_h -> 2.15 | L8: =IF(G8=0,I8,I8/(2*G8)) -> 1177 | M8: =((IF((lane_off+(L8))<=(v_sh^2/a_sh),(4/3)*(lane_off+(L8))^1.5/SQRT(a_sh),(4/3)*(v_sh^2/a_sh)^1.5/SQRT(a_sh)+((lane_off+(L8))^2-(v_sh^2/a_sh)^2)/(2*v_sh)+(v_sh/a_sh)*((lane_off+(L8))-(v_sh^2/a_sh))))-(IF((lane_off)<=(v_sh^2/a_sh),(4/3)*(lane_off)^1.5/SQRT(a_sh),(4/3)*(v_sh^2/a_sh)^1.5/SQRT(a_sh)+((lane_off)^2-(v_sh^2/a_sh)^2)/(2*v_sh)+(v_sh/a_sh)*((lane_off)-(v_sh^2/a_sh)))))/(L8) -> 424.08539 | N8: =IF(((B8-1)*u_d/2*(1+f_hc)+lane_off)<=0,0,IF(((B8-1)*u_d/2*(1+f_hc)+lane_off)>=v_sh^2/a_sh,((B8-1)*u_d/2*(1+f_hc)+lane_off)/v_sh+v_sh/a_sh,2*SQRT(((B8-1)*u_d/2*(1+f_hc)+lane_off)/a_sh))) -> 4.0792156 | O8: =2*t_sh+2*t_turn+2*M8+2*N8 -> 914.32921 | P8: =SUMPRODUCT((Tc_idx<=C8)*(ROUNDUP(lam_total*INDEX(Tc_P,C8,0)*O8/(3600*rho_max)-0.000000001,0)+(ROUNDUP(lam_total*INDEX(Tc_P,C8,0)*O8/(3600*rho_max)-0.000000001,0)<min_sh)*(min_sh-ROUNDUP(lam_total*INDEX(Tc_P,C8,0)*O8/(3600*rho_max)-0.000000001,0)))) -> 34 | Q8: =ROUNDUP(P8-0.000000001,0)+spares -> 36 | R8: =B8*C8*(2*H8-G8*lpl) -> 4708 | S8: =R8*fill -> 4001.8 | T8: =I8*J8 -> 7650.5 | U8: =T8*(K8+headroom) -> 27924.325 | V8: =G8*c_lift -> 0 | W8: =Q8*c_shut -> 1800000 | X8: =R8*c_pos -> 470800 | Y8: =T8*c_m2+U8*c_m3 -> 3897929.8 | Z8: =SUM(V8:Y8) -> 6168729.8 | AA8: =B8*u_d/(H8*u_w) -> 0.0022090059 | AB8: =IF(G8=0,0,F8/G8) -> 0 | AC8: =IF(G8>1,F8/(G8-1),"n/a") -> n/a | AD8: =moves_day*m_pallet*9.81*INDEX(Tc_mh,C8)/3600000 -> 0 | AE8: =IF(AND(K8<=H_max,H8<=300,OR(lane_policy="Free (optimize N_C)",B8=sku_pal),OR(env_use="No",AND(I8<=L_bldg,J8<=W_bldg),AND(I8<=W_bldg,J8<=L_bldg))),1,0) -> 0 | AF8: =IF(obj_mode="Total cost",Z8,IF(obj_mode="Shuttle cycle",O8,T8)) -> 6168729.8 | AG8: =IF(AE8=1,AF8*(1+A8*0.0000000001),1E+099) -> 1e+99 | AH8: =IF(AE8=1,"",IF(K8>H_max,"height",IF(AND(lane_policy<>"Free (optimize N_C)",B8<>sku_pal),"lane policy","footprint"))) -> footprint | AJ8: 2 | AK8: =IF(AE9=1,AF9,NA()) -> #N/A | AL8: =IF(AE29=1,AF29,NA()) -> #N/A | AM8: =IF(AE49=1,AF49,NA()) -> #N/A | AN8: =IF(AE69=1,AF69,NA()) -> #N/A | AO8: =IF(AE89=1,AF89,NA()) -> #N/A | AP8: =IF(AE109=1,AF109,NA()) -> #N/A | AQ8: =IF(AE129=1,AF129,NA()) -> #N/A | AR8: =IF(AE149=1,AF149,NA()) -> #N/A | AS8: =IF(AE169=1,AF169,NA()) -> #N/A | AT8: =IF(AE189=1,AF189,NA()) -> #N/A | AU8: =IF(AE209=1,AF209,NA()) -> #N/A
A9: 2 | B9: =$B$3 -> 2 | C9: 2 | D9: =INDEX(Tc_pl,C9) -> 0.5 | E9: =INDEX(Tc_S,C9) -> 41.157143 | F9: =lam_total*D9*E9/3600 -> 0.57162698 | G9: =IF(F9<=0.000000000001,0,MAX(ROUNDUP(F9/rho_max-0.000000001,0),IF(redund="Yes",ROUNDUP(F9/rho_fail-0.000000001,0)+1,0))) -> 2 | H9: =MAX(1,ROUNDUP((P_req/(B9*C9)+G9*lpl)/2-0.000000001,0)) -> 592 | I9: =H9*u_w -> 592 | J9: =2*B9*u_d+aisle_w -> 6.5 | K9: =C9*u_h -> 4.3 | L9: =IF(G9=0,I9,I9/(2*G9)) -> 148 | M9: =((IF((lane_off+(L9))<=(v_sh^2/a_sh),(4/3)*(lane_off+(L9))^1.5/SQRT(a_sh),(4/3)*(v_sh^2/a_sh)^1.5/SQRT(a_sh)+((lane_off+(L9))^2-(v_sh^2/a_sh)^2)/(2*v_sh)+(v_sh/a_sh)*((lane_off+(L9))-(v_sh^2/a_sh))))-(IF((lane_off)<=(v_sh^2/a_sh),(4/3)*(lane_off)^1.5/SQRT(a_sh),(4/3)*(v_sh^2/a_sh)^1.5/SQRT(a_sh)+((lane_off)^2-(v_sh^2/a_sh)^2)/(2*v_sh)+(v_sh/a_sh)*((lane_off)-(v_sh^2/a_sh)))))/(L9) -> 56.583142 | N9: =IF(((B9-1)*u_d/2*(1+f_hc)+lane_off)<=0,0,IF(((B9-1)*u_d/2*(1+f_hc)+lane_off)>=v_sh^2/a_sh,((B9-1)*u_d/2*(1+f_hc)+lane_off)/v_sh+v_sh/a_sh,2*SQRT(((B9-1)*u_d/2*(1+f_hc)+lane_off)/a_sh))) -> 4.0792156 | O9: =2*t_sh+2*t_turn+2*M9+2*N9 -> 179.32472 | P9: =SUMPRODUCT((Tc_idx<=C9)*(ROUNDUP(lam_total*INDEX(Tc_P,C9,0)*O9/(3600*rho_max)-0.000000001,0)+(ROUNDUP(lam_total*INDEX(Tc_P,C9,0)*O9/(3600*rho_max)-0.000000001,0)<min_sh)*(min_sh-ROUNDUP(lam_total*INDEX(Tc_P,C9,0)*O9/(3600*rho_max)-0.000000001,0)))) -> 8 | Q9: =ROUNDUP(P9-0.000000001,0)+spares -> 10 | R9: =B9*C9*(2*H9-G9*lpl) -> 4712 | S9: =R9*fill -> 4005.2 | T9: =I9*J9 -> 3848 | U9: =T9*(K9+headroom) -> 22318.4 | V9: =G9*c_lift -> 300000 | W9: =Q9*c_shut -> 500000 | X9: =R9*c_pos -> 471200 | Y9: =T9*c_m2+U9*c_m3 -> 2208752 | Z9: =SUM(V9:Y9) -> 3479952 | AA9: =B9*u_d/(H9*u_w) -> 0.0043918919 | AB9: =IF(G9=0,0,F9/G9) -> 0.28581349 | AC9: =IF(G9>1,F9/(G9-1),"n/a") -> 0.57162698 | AD9: =moves_day*m_pallet*9.81*INDEX(Tc_mh,C9)/3600000 -> 5.6244 | AE9: =IF(AND(K9<=H_max,H9<=300,OR(lane_policy="Free (optimize N_C)",B9=sku_pal),OR(env_use="No",AND(I9<=L_bldg,J9<=W_bldg),AND(I9<=W_bldg,J9<=L_bldg))),1,0) -> 0 | AF9: =IF(obj_mode="Total cost",Z9,IF(obj_mode="Shuttle cycle",O9,T9)) -> 3479952 | AG9: =IF(AE9=1,AF9*(1+A9*0.0000000001),1E+099) -> 1e+99 | AH9: =IF(AE9=1,"",IF(K9>H_max,"height",IF(AND(lane_policy<>"Free (optimize N_C)",B9<>sku_pal),"lane policy","footprint"))) -> footprint | AJ9: 3 | AK9: =IF(AE10=1,AF10,NA()) -> #N/A | AL9: =IF(AE30=1,AF30,NA()) -> #N/A | AM9: =IF(AE50=1,AF50,NA()) -> #N/A | AN9: =IF(AE70=1,AF70,NA()) -> #N/A | AO9: =IF(AE90=1,AF90,NA()) -> #N/A | AP9: =IF(AE110=1,AF110,NA()) -> #N/A | AQ9: =IF(AE130=1,AF130,NA()) -> #N/A | AR9: =IF(AE150=1,AF150,NA()) -> #N/A | AS9: =IF(AE170=1,AF170,NA()) -> #N/A | AT9: =IF(AE190=1,AF190,NA()) -> #N/A | AU9: =IF(AE210=1,AF210,NA()) -> #N/A
A10: 3 | B10: =$B$3 -> 2 | C10: 3 | D10: =INDEX(Tc_pl,C10) -> 0.52941176 | E10: =INDEX(Tc_S,C10) -> 41.634921 | F10: =lam_total*D10*E10/3600 -> 0.61227824 | G10: =IF(F10<=0.000000000001,0,MAX(ROUNDUP(F10/rho_max-0.000000001,0),IF(redund="Yes",ROUNDUP(F10/rho_fail-0.000000001,0)+1,0))) -> 2 | H10: =MAX(1,ROUNDUP((P_req/(B10*C10)+G10*lpl)/2-0.000000001,0)) -> 396 | I10: =H10*u_w -> 396 | J10: =2*B10*u_d+aisle_w -> 6.5 | K10: =C10*u_h -> 6.45 | L10: =IF(G10=0,I10,I10/(2*G10)) -> 99 | M10: =((IF((lane_off+(L10))<=(v_sh^2/a_sh),(4/3)*(lane_off+(L10))^1.5/SQRT(a_sh),(4/3)*(v_sh^2/a_sh)^1.5/SQRT(a_sh)+((lane_off+(L10))^2-(v_sh^2/a_sh)^2)/(2*v_sh)+(v_sh/a_sh)*((lane_off+(L10))-(v_sh^2/a_sh))))-(IF((lane_off)<=(v_sh^2/a_sh),(4/3)*(lane_off)^1.5/SQRT(a_sh),(4/3)*(v_sh^2/a_sh)^1.5/SQRT(a_sh)+((lane_off)^2-(v_sh^2/a_sh)^2)/(2*v_sh)+(v_sh/a_sh)*((lane_off)-(v_sh^2/a_sh)))))/(L10) -> 39.081869 | N10: =IF(((B10-1)*u_d/2*(1+f_hc)+lane_off)<=0,0,IF(((B10-1)*u_d/2*(1+f_hc)+lane_off)>=v_sh^2/a_sh,((B10-1)*u_d/2*(1+f_hc)+lane_off)/v_sh+v_sh/a_sh,2*SQRT(((B10-1)*u_d/2*(1+f_hc)+lane_off)/a_sh))) -> 4.0792156 | O10: =2*t_sh+2*t_turn+2*M10+2*N10 -> 144.32217 | P10: =SUMPRODUCT((Tc_idx<=C10)*(ROUNDUP(lam_total*INDEX(Tc_P,C10,0)*O10/(3600*rho_max)-0.000000001,0)+(ROUNDUP(lam_total*INDEX(Tc_P,C10,0)*O10/(3600*rho_max)-0.000000001,0)<min_sh)*(min_sh-ROUNDUP(lam_total*INDEX(Tc_P,C10,0)*O10/(3600*rho_max)-0.000000001,0)))) -> 7 | Q10: =ROUNDUP(P10-0.000000001,0)+spares -> 9 | R10: =B10*C10*(2*H10-G10*lpl) -> 4716 | S10: =R10*fill -> 4008.6 | T10: =I10*J10 -> 2574 | U10: =T10*(K10+headroom) -> 20463.3 | V10: =G10*c_lift -> 300000 | W10: =Q10*c_shut -> 450000 | X10: =R10*c_pos -> 471600 | Y10: =T10*c_m2+U10*c_m3 -> 1643499 | Z10: =SUM(V10:Y10) -> 2865099 | AA10: =B10*u_d/(H10*u_w) -> 0.0065656566 | AB10: =IF(G10=0,0,F10/G10) -> 0.30613912 | AC10: =IF(G10>1,F10/(G10-1),"n/a") -> 0.61227824 | AD10: =moves_day*m_pallet*9.81*INDEX(Tc_mh,C10)/3600000 -> 6.6169412 | AE10: =IF(AND(K10<=H_max,H10<=300,OR(lane_policy="Free (optimize N_C)",B10=sku_pal),OR(env_use="No",AND(I10<=L_bldg,J10<=W_bldg),AND(I10<=W_bldg,J10<=L_bldg))),1,0) -> 0 | AF10: =IF(obj_mode="Total cost",Z10,IF(obj_mode="Shuttle cycle",O10,T10)) -> 2865099 | AG10: =IF(AE10=1,AF10*(1+A10*0.0000000001),1E+099) -> 1e+99 | AH10: =IF(AE10=1,"",IF(K10>H_max,"height",IF(AND(lane_policy<>"Free (optimize N_C)",B10<>sku_pal),"lane policy","footprint"))) -> footprint | AJ10: 4 | AK10: =IF(AE11=1,AF11,NA()) -> #N/A | AL10: =IF(AE31=1,AF31,NA()) -> #N/A | AM10: =IF(AE51=1,AF51,NA()) -> #N/A | AN10: =IF(AE71=1,AF71,NA()) -> #N/A | AO10: =IF(AE91=1,AF91,NA()) -> #N/A | AP10: =IF(AE111=1,AF111,NA()) -> #N/A | AQ10: =IF(AE131=1,AF131,NA()) -> #N/A | AR10: =IF(AE151=1,AF151,NA()) -> #N/A | AS10: =IF(AE171=1,AF171,NA()) -> #N/A | AT10: =IF(AE191=1,AF191,NA()) -> #N/A | AU10: =IF(AE211=1,AF211,NA()) -> #N/A
A11: 4 | B11: =$B$3 -> 2 | C11: 4 | D11: =INDEX(Tc_pl,C11) -> 0.55555556 | E11: =INDEX(Tc_S,C11) -> 42.447143 | F11: =lam_total*D11*E11/3600 -> 0.6550485 | G11: =IF(F11<=0.000000000001,0,MAX(ROUNDUP(F11/rho_max-0.000000001,0),IF(redund="Yes",ROUNDUP(F11/rho_fail-0.000000001,0)+1,0))) -> 2 | H11: =MAX(1,ROUNDUP((P_req/(B11*C11)+G11*lpl)/2-0.000000001,0)) -> 298 | I11: =H11*u_w -> 298 | J11: =2*B11*u_d+aisle_w -> 6.5 | K11: =C11*u_h -> 8.6 | L11: =IF(G11=0,I11,I11/(2*G11)) -> 74.5 | M11: =((IF((lane_off+(L11))<=(v_sh^2/a_sh),(4/3)*(lane_off+(L11))^1.5/SQRT(a_sh),(4/3)*(v_sh^2/a_sh)^1.5/SQRT(a_sh)+((lane_off+(L11))^2-(v_sh^2/a_sh)^2)/(2*v_sh)+(v_sh/a_sh)*((lane_off+(L11))-(v_sh^2/a_sh))))-(IF((lane_off)<=(v_sh^2/a_sh),(4/3)*(lane_off)^1.5/SQRT(a_sh),(4/3)*(v_sh^2/a_sh)^1.5/SQRT(a_sh)+((lane_off)^2-(v_sh^2/a_sh)^2)/(2*v_sh)+(v_sh/a_sh)*((lane_off)-(v_sh^2/a_sh)))))/(L11) -> 30.330605 | N11: =IF(((B11-1)*u_d/2*(1+f_hc)+lane_off)<=0,0,IF(((B11-1)*u_d/2*(1+f_hc)+lane_off)>=v_sh^2/a_sh,((B11-1)*u_d/2*(1+f_hc)+lane_off)/v_sh+v_sh/a_sh,2*SQRT(((B11-1)*u_d/2*(1+f_hc)+lane_off)/a_sh))) -> 4.0792156 | O11: =2*t_sh+2*t_turn+2*M11+2*N11 -> 126.81964 | P11: =SUMPRODUCT((Tc_idx<=C11)*(ROUNDUP(lam_total*INDEX(Tc_P,C11,0)*O11/(3600*rho_max)-0.000000001,0)+(ROUNDUP(lam_total*INDEX(Tc_P,C11,0)*O11/(3600*rho_max)-0.000000001,0)<min_sh)*(min_sh-ROUNDUP(lam_total*INDEX(Tc_P,C11,0)*O11/(3600*rho_max)-0.000000001,0)))) -> 8 | Q11: =ROUNDUP(P11-0.000000001,0)+spares -> 10 | R11: =B11*C11*(2*H11-G11*lpl) -> 4720 | S11: =R11*fill -> 4012 | T11: =I11*J11 -> 1937 | U11: =T11*(K11+headroom) -> 19563.7 | V11: =G11*c_lift -> 300000 | W11: =Q11*c_shut -> 500000 | X11: =R11*c_pos -> 472000 | Y11: =T11*c_m2+U11*c_m3 -> 1361711 | Z11: =SUM(V11:Y11) -> 2633711 | AA11: =B11*u_d/(H11*u_w) -> 0.0087248322 | AB11: =IF(G11=0,0,F11/G11) -> 0.32752425 | AC11: =IF(G11>1,F11/(G11-1),"n/a") -> 0.6550485 | AD11: =moves_day*m_pallet*9.81*INDEX(Tc_mh,C11)/3600000 -> 8.1241333 | AE11: =IF(AND(K11<=H_max,H11<=300,OR(lane_policy="Free (optimize N_C)",B11=sku_pal),OR(env_use="No",AND(I11<=L_bldg,J11<=W_bldg),AND(I11<=W_bldg,J11<=L_bldg))),1,0) -> 0 | AF11: =IF(obj_mode="Total cost",Z11,IF(obj_mode="Shuttle cycle",O11,T11)) -> 2633711 | AG11: =IF(AE11=1,AF11*(1+A11*0.0000000001),1E+099) -> 1e+99 | AH11: =IF(AE11=1,"",IF(K11>H_max,"height",IF(AND(lane_policy<>"Free (optimize N_C)",B11<>sku_pal),"lane policy","footprint"))) -> footprint | AJ11: 5 | AK11: =IF(AE12=1,AF12,NA()) -> #N/A | AL11: =IF(AE32=1,AF32,NA()) -> #N/A | AM11: =IF(AE52=1,AF52,NA()) -> #N/A | AN11: =IF(AE72=1,AF72,NA()) -> #N/A | AO11: =IF(AE92=1,AF92,NA()) -> #N/A | AP11: =IF(AE112=1,AF112,NA()) -> #N/A | AQ11: =IF(AE132=1,AF132,NA()) -> #N/A | AR11: =IF(AE152=1,AF152,NA()) -> #N/A | AS11: =IF(AE172=1,AF172,NA()) -> #N/A | AT11: =IF(AE192=1,AF192,NA()) -> #N/A | AU11: =IF(AE212=1,AF212,NA()) -> #N/A
A12: 5 | B12: =$B$3 -> 2 | C12: 5 | D12: =INDEX(Tc_pl,C12) -> 0.57894737 | E12: =INDEX(Tc_S,C12) -> 43.502597 | F12: =lam_total*D12*E12/3600 -> 0.69960317 | G12: =IF(F12<=0.000000000001,0,MAX(ROUNDUP(F12/rho_max-0.000000001,0),IF(redund="Yes",ROUNDUP(F12/rho_fail-0.000000001,0)+1,0))) -> 2 | H12: =MAX(1,ROUNDUP((P_req/(B12*C12)+G12*lpl)/2-0.000000001,0)) -> 239 | I12: =H12*u_w -> 239 | J12: =2*B12*u_d+aisle_w -> 6.5 | K12: =C12*u_h -> 10.75 | L12: =IF(G12=0,I12,I12/(2*G12)) -> 59.75 | M12: =((IF((lane_off+(L12))<=(v_sh^2/a_sh),(4/3)*(lane_off+(L12))^1.5/SQRT(a_sh),(4/3)*(v_sh^2/a_sh)^1.5/SQRT(a_sh)+((lane_off+(L12))^2-(v_sh^2/a_sh)^2)/(2*v_sh)+(v_sh/a_sh)*((lane_off+(L12))-(v_sh^2/a_sh))))-(IF((lane_off)<=(v_sh^2/a_sh),(4/3)*(lane_off)^1.5/SQRT(a_sh),(4/3)*(v_sh^2/a_sh)^1.5/SQRT(a_sh)+((lane_off)^2-(v_sh^2/a_sh)^2)/(2*v_sh)+(v_sh/a_sh)*((lane_off)-(v_sh^2/a_sh)))))/(L12) -> 25.061486 | N12: =IF(((B12-1)*u_d/2*(1+f_hc)+lane_off)<=0,0,IF(((B12-1)*u_d/2*(1+f_hc)+lane_off)>=v_sh^2/a_sh,((B12-1)*u_d/2*(1+f_hc)+lane_off)/v_sh+v_sh/a_sh,2*SQRT(((B12-1)*u_d/2*(1+f_hc)+lane_off)/a_sh))) -> 4.0792156 | O12: =2*t_sh+2*t_turn+2*M12+2*N12 -> 116.2814 | P12: =SUMPRODUCT((Tc_idx<=C12)*(ROUNDUP(lam_total*INDEX(Tc_P,C12,0)*O12/(3600*rho_max)-0.000000001,0)+(ROUNDUP(lam_total*INDEX(Tc_P,C12,0)*O12/(3600*rho_max)-0.000000001,0)<min_sh)*(min_sh-ROUNDUP(lam_total*INDEX(Tc_P,C12,0)*O12/(3600*rho_max)-0.000000001,0)))) -> 7 | Q12: =ROUNDUP(P12-0.000000001,0)+spares -> 9 | R12: =B12*C12*(2*H12-G12*lpl) -> 4720 | S12: =R12*fill -> 4012 | T12: =I12*J12 -> 1553.5 | U12: =T12*(K12+headroom) -> 19030.375 | V12: =G12*c_lift -> 300000 | W12: =Q12*c_shut -> 450000 | X12: =R12*c_pos -> 472000 | Y12: =T12*c_m2+U12*c_m3 -> 1192311.2 | Z12: =SUM(V12:Y12) -> 2414311.2 | AA12: =B12*u_d/(H12*u_w) -> 0.010878661 | AB12: =IF(G12=0,0,F12/G12) -> 0.34980159 | AC12: =IF(G12>1,F12/(G12-1),"n/a") -> 0.69960317 | AD12: =moves_day*m_pallet*9.81*INDEX(Tc_mh,C12)/3600000 -> 10.064716 | AE12: =IF(AND(K12<=H_max,H12<=300,OR(lane_policy="Free (optimize N_C)",B12=sku_pal),OR(env_use="No",AND(I12<=L_bldg,J12<=W_bldg),AND(I12<=W_bldg,J12<=L_bldg))),1,0) -> 0 | AF12: =IF(obj_mode="Total cost",Z12,IF(obj_mode="Shuttle cycle",O12,T12)) -> 2414311.2 | AG12: =IF(AE12=1,AF12*(1+A12*0.0000000001),1E+099) -> 1e+99 | AH12: =IF(AE12=1,"",IF(K12>H_max,"height",IF(AND(lane_policy<>"Free (optimize N_C)",B12<>sku_pal),"lane policy","footprint"))) -> footprint | AJ12: 6 | AK12: =IF(AE13=1,AF13,NA()) -> #N/A | AL12: =IF(AE33=1,AF33,NA()) -> #N/A | AM12: =IF(AE53=1,AF53,NA()) -> #N/A | AN12: =IF(AE73=1,AF73,NA()) -> #N/A | AO12: =IF(AE93=1,AF93,NA()) -> #N/A | AP12: =IF(AE113=1,AF113,NA()) -> #N/A | AQ12: =IF(AE133=1,AF133,NA()) -> 2256684.8 | AR12: =IF(AE153=1,AF153,NA()) -> #N/A | AS12: =IF(AE173=1,AF173,NA()) -> 2279398.4 | AT12: =IF(AE193=1,AF193,NA()) -> #N/A | AU12: =IF(AE213=1,AF213,NA()) -> #N/A
A13: 6 | B13: =$B$3 -> 2 | C13: 6 | D13: =INDEX(Tc_pl,C13) -> 0.6 | E13: =INDEX(Tc_S,C13) -> 44.740476 | F13: =lam_total*D13*E13/3600 -> 0.7456746 | G13: =IF(F13<=0.000000000001,0,MAX(ROUNDUP(F13/rho_max-0.000000001,0),IF(redund="Yes",ROUNDUP(F13/rho_fail-0.000000001,0)+1,0))) -> 2 | H13: =MAX(1,ROUNDUP((P_req/(B13*C13)+G13*lpl)/2-0.000000001,0)) -> 200 | I13: =H13*u_w -> 200 | J13: =2*B13*u_d+aisle_w -> 6.5 | K13: =C13*u_h -> 12.9 | L13: =IF(G13=0,I13,I13/(2*G13)) -> 50 | M13: =((IF((lane_off+(L13))<=(v_sh^2/a_sh),(4/3)*(lane_off+(L13))^1.5/SQRT(a_sh),(4/3)*(v_sh^2/a_sh)^1.5/SQRT(a_sh)+((lane_off+(L13))^2-(v_sh^2/a_sh)^2)/(2*v_sh)+(v_sh/a_sh)*((lane_off+(L13))-(v_sh^2/a_sh))))-(IF((lane_off)<=(v_sh^2/a_sh),(4/3)*(lane_off)^1.5/SQRT(a_sh),(4/3)*(v_sh^2/a_sh)^1.5/SQRT(a_sh)+((lane_off)^2-(v_sh^2/a_sh)^2)/(2*v_sh)+(v_sh/a_sh)*((lane_off)-(v_sh^2/a_sh)))))/(L13) -> 21.578101 | N13: =IF(((B13-1)*u_d/2*(1+f_hc)+lane_off)<=0,0,IF(((B13-1)*u_d/2*(1+f_hc)+lane_off)>=v_sh^2/a_sh,((B13-1)*u_d/2*(1+f_hc)+lane_off)/v_sh+v_sh/a_sh,2*SQRT(((B13-1)*u_d/2*(1+f_hc)+lane_off)/a_sh))) -> 4.0792156 | O13: =2*t_sh+2*t_turn+2*M13+2*N13 -> 109.31463 | P13: =SUMPRODUCT((Tc_idx<=C13)*(ROUNDUP(lam_total*INDEX(Tc_P,C13,0)*O13/(3600*rho_max)-0.000000001,0)+(ROUNDUP(lam_total*INDEX(Tc_P,C13,0)*O13/(3600*rho_max)-0.000000001,0)<min_sh)*(min_sh-ROUNDUP(lam_total*INDEX(Tc_P,C13,0)*O13/(3600*rho_max)-0.000000001,0)))) -> 8 | Q13: =ROUNDUP(P13-0.000000001,0)+spares -> 10 | R13: =B13*C13*(2*H13-G13*lpl) -> 4728 | S13: =R13*fill -> 4018.8 | T13: =I13*J13 -> 1300 | U13: =T13*(K13+headroom) -> 18720 | V13: =G13*c_lift -> 300000 | W13: =Q13*c_shut -> 500000 | X13: =R13*c_pos -> 472800 | Y13: =T13*c_m2+U13*c_m3 -> 1081600 | Z13: =SUM(V13:Y13) -> 2354400 | AA13: =B13*u_d/(H13*u_w) -> 0.013 | AB13: =IF(G13=0,0,F13/G13) -> 0.3728373 | AC13: =IF(G13>1,F13/(G13-1),"n/a") -> 0.7456746 | AD13: =moves_day*m_pallet*9.81*INDEX(Tc_mh,C13)/3600000 -> 12.37368 | AE13: =IF(AND(K13<=H_max,H13<=300,OR(lane_policy="Free (optimize N_C)",B13=sku_pal),OR(env_use="No",AND(I13<=L_bldg,J13<=W_bldg),AND(I13<=W_bldg,J13<=L_bldg))),1,0) -> 0 | AF13: =IF(obj_mode="Total cost",Z13,IF(obj_mode="Shuttle cycle",O13,T13)) -> 2354400 | AG13: =IF(AE13=1,AF13*(1+A13*0.0000000001),1E+099) -> 1e+99 | AH13: =IF(AE13=1,"",IF(K13>H_max,"height",IF(AND(lane_policy<>"Free (optimize N_C)",B13<>sku_pal),"lane policy","footprint"))) -> footprint | AJ13: 7 | AK13: =IF(AE14=1,AF14,NA()) -> #N/A | AL13: =IF(AE34=1,AF34,NA()) -> #N/A | AM13: =IF(AE54=1,AF54,NA()) -> #N/A | AN13: =IF(AE74=1,AF74,NA()) -> #N/A | AO13: =IF(AE94=1,AF94,NA()) -> #N/A | AP13: =IF(AE114=1,AF114,NA()) -> #N/A | AQ13: =IF(AE134=1,AF134,NA()) -> 2231554.6 | AR13: =IF(AE154=1,AF154,NA()) -> #N/A | AS13: =IF(AE174=1,AF174,NA()) -> 2304296.2 | AT13: =IF(AE194=1,AF194,NA()) -> #N/A | AU13: =IF(AE214=1,AF214,NA()) -> #N/A
A14: 7 | B14: =$B$3 -> 2 | C14: 7 | D14: =INDEX(Tc_pl,C14) -> 0.6 | E14: =INDEX(Tc_S,C14) -> 44.919643 | F14: =lam_total*D14*E14/3600 -> 0.74866071 | G14: =IF(F14<=0.000000000001,0,MAX(ROUNDUP(F14/rho_max-0.000000001,0),IF(redund="Yes",ROUNDUP(F14/rho_fail-0.000000001,0)+1,0))) -> 2 | H14: =MAX(1,ROUNDUP((P_req/(B14*C14)+G14*lpl)/2-0.000000001,0)) -> 172 | I14: =H14*u_w -> 172 | J14: =2*B14*u_d+aisle_w -> 6.5 | K14: =C14*u_h -> 15.05 | L14: =IF(G14=0,I14,I14/(2*G14)) -> 43 | M14: =((IF((lane_off+(L14))<=(v_sh^2/a_sh),(4/3)*(lane_off+(L14))^1.5/SQRT(a_sh),(4/3)*(v_sh^2/a_sh)^1.5/SQRT(a_sh)+((lane_off+(L14))^2-(v_sh^2/a_sh)^2)/(2*v_sh)+(v_sh/a_sh)*((lane_off+(L14))-(v_sh^2/a_sh))))-(IF((lane_off)<=(v_sh^2/a_sh),(4/3)*(lane_off)^1.5/SQRT(a_sh),(4/3)*(v_sh^2/a_sh)^1.5/SQRT(a_sh)+((lane_off)^2-(v_sh^2/a_sh)^2)/(2*v_sh)+(v_sh/a_sh)*((lane_off)-(v_sh^2/a_sh)))))/(L14) -> 19.076861 | N14: =IF(((B14-1)*u_d/2*(1+f_hc)+lane_off)<=0,0,IF(((B14-1)*u_d/2*(1+f_hc)+lane_off)>=v_sh^2/a_sh,((B14-1)*u_d/2*(1+f_hc)+lane_off)/v_sh+v_sh/a_sh,2*SQRT(((B14-1)*u_d/2*(1+f_hc)+lane_off)/a_sh))) -> 4.0792156 | O14: =2*t_sh+2*t_turn+2*M14+2*N14 -> 104.31215 | P14: =SUMPRODUCT((Tc_idx<=C14)*(ROUNDUP(lam_total*INDEX(Tc_P,C14,0)*O14/(3600*rho_max)-0.000000001,0)+(ROUNDUP(lam_total*INDEX(Tc_P,C14,0)*O14/(3600*rho_max)-0.000000001,0)<min_sh)*(min_sh-ROUNDUP(lam_total*INDEX(Tc_P,C14,0)*O14/(3600*rho_max)-0.000000001,0)))) -> 9 | Q14: =ROUNDUP(P14-0.000000001,0)+spares -> 11 | R14: =B14*C14*(2*H14-G14*lpl) -> 4732 | S14: =R14*fill -> 4022.2 | T14: =I14*J14 -> 1118 | U14: =T14*(K14+headroom) -> 18502.9 | V14: =G14*c_lift -> 300000 | W14: =Q14*c_shut -> 550000 | X14: =R14*c_pos -> 473200 | Y14: =T14*c_m2+U14*c_m3 -> 1002287 | Z14: =SUM(V14:Y14) -> 2325487 | AA14: =B14*u_d/(H14*u_w) -> 0.015116279 | AB14: =IF(G14=0,0,F14/G14) -> 0.37433036 | AC14: =IF(G14>1,F14/(G14-1),"n/a") -> 0.74866071 | AD14: =moves_day*m_pallet*9.81*INDEX(Tc_mh,C14)/3600000 -> 12.6549 | AE14: =IF(AND(K14<=H_max,H14<=300,OR(lane_policy="Free (optimize N_C)",B14=sku_pal),OR(env_use="No",AND(I14<=L_bldg,J14<=W_bldg),AND(I14<=W_bldg,J14<=L_bldg))),1,0) -> 0 | AF14: =IF(obj_mode="Total cost",Z14,IF(obj_mode="Shuttle cycle",O14,T14)) -> 2325487 | AG14: =IF(AE14=1,AF14*(1+A14*0.0000000001),1E+099) -> 1e+99 | AH14: =IF(AE14=1,"",IF(K14>H_max,"height",IF(AND(lane_policy<>"Free (optimize N_C)",B14<>sku_pal),"lane policy","footprint"))) -> footprint | AJ14: 8 | AK14: =IF(AE15=1,AF15,NA()) -> #N/A | AL14: =IF(AE35=1,AF35,NA()) -> #N/A | AM14: =IF(AE55=1,AF55,NA()) -> #N/A | AN14: =IF(AE75=1,AF75,NA()) -> #N/A | AO14: =IF(AE95=1,AF95,NA()) -> #N/A | AP14: =IF(AE115=1,AF115,NA()) -> 2223124 | AQ14: =IF(AE135=1,AF135,NA()) -> 2245764.9 | AR14: =IF(AE155=1,AF155,NA()) -> 2254510 | AS14: =IF(AE175=1,AF175,NA()) -> 2293391.8 | AT14: =IF(AE195=1,AF195,NA()) -> #N/A | AU14: =IF(AE215=1,AF215,NA()) -> #N/A
A15: 8 | B15: =$B$3 -> 2 | C15: 8 | D15: =INDEX(Tc_pl,C15) -> 0.6 | E15: =INDEX(Tc_S,C15) -> 45.09881 | F15: =lam_total*D15*E15/3600 -> 0.75164683 | G15: =IF(F15<=0.000000000001,0,MAX(ROUNDUP(F15/rho_max-0.000000001,0),IF(redund="Yes",ROUNDUP(F15/rho_fail-0.000000001,0)+1,0))) -> 2 | H15: =MAX(1,ROUNDUP((P_req/(B15*C15)+G15*lpl)/2-0.000000001,0)) -> 151 | I15: =H15*u_w -> 151 | J15: =2*B15*u_d+aisle_w -> 6.5 | K15: =C15*u_h -> 17.2 | L15: =IF(G15=0,I15,I15/(2*G15)) -> 37.75 | M15: =((IF((lane_off+(L15))<=(v_sh^2/a_sh),(4/3)*(lane_off+(L15))^1.5/SQRT(a_sh),(4/3)*(v_sh^2/a_sh)^1.5/SQRT(a_sh)+((lane_off+(L15))^2-(v_sh^2/a_sh)^2)/(2*v_sh)+(v_sh/a_sh)*((lane_off+(L15))-(v_sh^2/a_sh))))-(IF((lane_off)<=(v_sh^2/a_sh),(4/3)*(lane_off)^1.5/SQRT(a_sh),(4/3)*(v_sh^2/a_sh)^1.5/SQRT(a_sh)+((lane_off)^2-(v_sh^2/a_sh)^2)/(2*v_sh)+(v_sh/a_sh)*((lane_off)-(v_sh^2/a_sh)))))/(L15) -> 17.20063 | N15: =IF(((B15-1)*u_d/2*(1+f_hc)+lane_off)<=0,0,IF(((B15-1)*u_d/2*(1+f_hc)+lane_off)>=v_sh^2/a_sh,((B15-1)*u_d/2*(1+f_hc)+lane_off)/v_sh+v_sh/a_sh,2*SQRT(((B15-1)*u_d/2*(1+f_hc)+lane_off)/a_sh))) -> 4.0792156 | O15: =2*t_sh+2*t_turn+2*M15+2*N15 -> 100.55969 | P15: =SUMPRODUCT((Tc_idx<=C15)*(ROUNDUP(lam_total*INDEX(Tc_P,C15,0)*O15/(3600*rho_max)-0.000000001,0)+(ROUNDUP(lam_total*INDEX(Tc_P,C15,0)*O15/(3600*rho_max)-0.000000001,0)<min_sh)*(min_sh-ROUNDUP(lam_total*INDEX(Tc_P,C15,0)*O15/(3600*rho_max)-0.000000001,0)))) -> 10 | Q15: =ROUNDUP(P15-0.000000001,0)+spares -> 12 | R15: =B15*C15*(2*H15-G15*lpl) -> 4736 | S15: =R15*fill -> 4025.6 | T15: =I15*J15 -> 981.5 | U15: =T15*(K15+headroom) -> 18354.05 | V15: =G15*c_lift -> 300000 | W15: =Q15*c_shut -> 600000 | X15: =R15*c_pos -> 473600 | Y15: =T15*c_m2+U15*c_m3 -> 943221.5 | Z15: =SUM(V15:Y15) -> 2316821.5 | AA15: =B15*u_d/(H15*u_w) -> 0.017218543 | AB15: =IF(G15=0,0,F15/G15) -> 0.37582341 | AC15: =IF(G15>1,F15/(G15-1),"n/a") -> 0.75164683 | AD15: =moves_day*m_pallet*9.81*INDEX(Tc_mh,C15)/3600000 -> 12.93612 | AE15: =IF(AND(K15<=H_max,H15<=300,OR(lane_policy="Free (optimize N_C)",B15=sku_pal),OR(env_use="No",AND(I15<=L_bldg,J15<=W_bldg),AND(I15<=W_bldg,J15<=L_bldg))),1,0) -> 0 | AF15: =IF(obj_mode="Total cost",Z15,IF(obj_mode="Shuttle cycle",O15,T15)) -> 2316821.5 | AG15: =IF(AE15=1,AF15*(1+A15*0.0000000001),1E+099) -> 1e+99 | AH15: =IF(AE15=1,"",IF(K15>H_max,"height",IF(AND(lane_policy<>"Free (optimize N_C)",B15<>sku_pal),"lane policy","footprint"))) -> footprint | AJ15: 9 | AK15: =IF(AE16=1,AF16,NA()) -> #N/A | AL15: =IF(AE36=1,AF36,NA()) -> #N/A | AM15: =IF(AE56=1,AF56,NA()) -> #N/A | AN15: =IF(AE76=1,AF76,NA()) -> #N/A | AO15: =IF(AE96=1,AF96,NA()) -> #N/A | AP15: =IF(AE116=1,AF116,NA()) -> 2241087.8 | AQ15: =IF(AE136=1,AF136,NA()) -> 2275884.5 | AR15: =IF(AE156=1,AF156,NA()) -> 2258418.8 | AS15: =IF(AE176=1,AF176,NA()) -> 2319479 | AT15: =IF(AE196=1,AF196,NA()) -> #N/A | AU15: =IF(AE216=1,AF216,NA()) -> #N/A
A16: 9 | B16: =$B$3 -> 2 | C16: 9 | D16: =INDEX(Tc_pl,C16) -> 0.6 | E16: =INDEX(Tc_S,C16) -> 45.277976 | F16: =lam_total*D16*E16/3600 -> 0.75463294 | G16: =IF(F16<=0.000000000001,0,MAX(ROUNDUP(F16/rho_max-0.000000001,0),IF(redund="Yes",ROUNDUP(F16/rho_fail-0.000000001,0)+1,0))) -> 2 | H16: =MAX(1,ROUNDUP((P_req/(B16*C16)+G16*lpl)/2-0.000000001,0)) -> 134 | I16: =H16*u_w -> 134 | J16: =2*B16*u_d+aisle_w -> 6.5 | K16: =C16*u_h -> 19.35 | L16: =IF(G16=0,I16,I16/(2*G16)) -> 33.5 | M16: =((IF((lane_off+(L16))<=(v_sh^2/a_sh),(4/3)*(lane_off+(L16))^1.5/SQRT(a_sh),(4/3)*(v_sh^2/a_sh)^1.5/SQRT(a_sh)+((lane_off+(L16))^2-(v_sh^2/a_sh)^2)/(2*v_sh)+(v_sh/a_sh)*((lane_off+(L16))-(v_sh^2/a_sh))))-(IF((lane_off)<=(v_sh^2/a_sh),(4/3)*(lane_off)^1.5/SQRT(a_sh),(4/3)*(v_sh^2/a_sh)^1.5/SQRT(a_sh)+((lane_off)^2-(v_sh^2/a_sh)^2)/(2*v_sh)+(v_sh/a_sh)*((lane_off)-(v_sh^2/a_sh)))))/(L16) -> 15.681494 | N16: =IF(((B16-1)*u_d/2*(1+f_hc)+lane_off)<=0,0,IF(((B16-1)*u_d/2*(1+f_hc)+lane_off)>=v_sh^2/a_sh,((B16-1)*u_d/2*(1+f_hc)+lane_off)/v_sh+v_sh/a_sh,2*SQRT(((B16-1)*u_d/2*(1+f_hc)+lane_off)/a_sh))) -> 4.0792156 | O16: =2*t_sh+2*t_turn+2*M16+2*N16 -> 97.521418 | P16: =SUMPRODUCT((Tc_idx<=C16)*(ROUNDUP(lam_total*INDEX(Tc_P,C16,0)*O16/(3600*rho_max)-0.000000001,0)+(ROUNDUP(lam_total*INDEX(Tc_P,C16,0)*O16/(3600*rho_max)-0.000000001,0)<min_sh)*(min_sh-ROUNDUP(lam_total*INDEX(Tc_P,C16,0)*O16/(3600*rho_max)-0.000000001,0)))) -> 11 | Q16: =ROUNDUP(P16-0.000000001,0)+spares -> 13 | R16: =B16*C16*(2*H16-G16*lpl) -> 4716 | S16: =R16*fill -> 4008.6 | T16: =I16*J16 -> 871 | U16: =T16*(K16+headroom) -> 18160.35 | V16: =G16*c_lift -> 300000 | W16: =Q16*c_shut -> 650000 | X16: =R16*c_pos -> 471600 | Y16: =T16*c_m2+U16*c_m3 -> 893210.5 | Z16: =SUM(V16:Y16) -> 2314810.5 | AA16: =B16*u_d/(H16*u_w) -> 0.019402985 | AB16: =IF(G16=0,0,F16/G16) -> 0.37731647 | AC16: =IF(G16>1,F16/(G16-1),"n/a") -> 0.75463294 | AD16: =moves_day*m_pallet*9.81*INDEX(Tc_mh,C16)/3600000 -> 13.21734 | AE16: =IF(AND(K16<=H_max,H16<=300,OR(lane_policy="Free (optimize N_C)",B16=sku_pal),OR(env_use="No",AND(I16<=L_bldg,J16<=W_bldg),AND(I16<=W_bldg,J16<=L_bldg))),1,0) -> 0 | AF16: =IF(obj_mode="Total cost",Z16,IF(obj_mode="Shuttle cycle",O16,T16)) -> 2314810.5 | AG16: =IF(AE16=1,AF16*(1+A16*0.0000000001),1E+099) -> 1e+99 | AH16: =IF(AE16=1,"",IF(K16>H_max,"height",IF(AND(lane_policy<>"Free (optimize N_C)",B16<>sku_pal),"lane policy","footprint"))) -> footprint | AJ16: 10 | AK16: =IF(AE17=1,AF17,NA()) -> #N/A | AL16: =IF(AE37=1,AF37,NA()) -> #N/A | AM16: =IF(AE57=1,AF57,NA()) -> #N/A | AN16: =IF(AE77=1,AF77,NA()) -> #N/A | AO16: =IF(AE97=1,AF97,NA()) -> #N/A | AP16: =IF(AE117=1,AF117,NA()) -> #N/A | AQ16: =IF(AE137=1,AF137,NA()) -> #N/A | AR16: =IF(AE157=1,AF157,NA()) -> #N/A | AS16: =IF(AE177=1,AF177,NA()) -> #N/A | AT16: =IF(AE197=1,AF197,NA()) -> #N/A | AU16: =IF(AE217=1,AF217,NA()) -> #N/A
A17: 10 | B17: =$B$3 -> 2 | C17: 10 | D17: =INDEX(Tc_pl,C17) -> 0.6 | E17: =INDEX(Tc_S,C17) -> 45.457143 | F17: =lam_total*D17*E17/3600 -> 0.75761905 | G17: =IF(F17<=0.000000000001,0,MAX(ROUNDUP(F17/rho_max-0.000000001,0),IF(redund="Yes",ROUNDUP(F17/rho_fail-0.000000001,0)+1,0))) -> 2 | H17: =MAX(1,ROUNDUP((P_req/(B17*C17)+G17*lpl)/2-0.000000001,0)) -> 121 | I17: =H17*u_w -> 121 | J17: =2*B17*u_d+aisle_w -> 6.5 | K17: =C17*u_h -> 21.5 | L17: =IF(G17=0,I17,I17/(2*G17)) -> 30.25 | M17: =((IF((lane_off+(L17))<=(v_sh^2/a_sh),(4/3)*(lane_off+(L17))^1.5/SQRT(a_sh),(4/3)*(v_sh^2/a_sh)^1.5/SQRT(a_sh)+((lane_off+(L17))^2-(v_sh^2/a_sh)^2)/(2*v_sh)+(v_sh/a_sh)*((lane_off+(L17))-(v_sh^2/a_sh))))-(IF((lane_off)<=(v_sh^2/a_sh),(4/3)*(lane_off)^1.5/SQRT(a_sh),(4/3)*(v_sh^2/a_sh)^1.5/SQRT(a_sh)+((lane_off)^2-(v_sh^2/a_sh)^2)/(2*v_sh)+(v_sh/a_sh)*((lane_off)-(v_sh^2/a_sh)))))/(L17) -> 14.519558 | N17: =IF(((B17-1)*u_d/2*(1+f_hc)+lane_off)<=0,0,IF(((B17-1)*u_d/2*(1+f_hc)+lane_off)>=v_sh^2/a_sh,((B17-1)*u_d/2*(1+f_hc)+lane_off)/v_sh+v_sh/a_sh,2*SQRT(((B17-1)*u_d/2*(1+f_hc)+lane_off)/a_sh))) -> 4.0792156 | O17: =2*t_sh+2*t_turn+2*M17+2*N17 -> 95.197548 | P17: =SUMPRODUCT((Tc_idx<=C17)*(ROUNDUP(lam_total*INDEX(Tc_P,C17,0)*O17/(3600*rho_max)-0.000000001,0)+(ROUNDUP(lam_total*INDEX(Tc_P,C17,0)*O17/(3600*rho_max)-0.000000001,0)<min_sh)*(min_sh-ROUNDUP(lam_total*INDEX(Tc_P,C17,0)*O17/(3600*rho_max)-0.000000001,0)))) -> 12 | Q17: =ROUNDUP(P17-0.000000001,0)+spares -> 14 | R17: =B17*C17*(2*H17-G17*lpl) -> 4720 | S17: =R17*fill -> 4012 | T17: =I17*J17 -> 786.5 | U17: =T17*(K17+headroom) -> 18089.5 | V17: =G17*c_lift -> 300000 | W17: =Q17*c_shut -> 700000 | X17: =R17*c_pos -> 472000 | Y17: =T17*c_m2+U17*c_m3 -> 857285 | Z17: =SUM(V17:Y17) -> 2329285 | AA17: =B17*u_d/(H17*u_w) -> 0.021487603 | AB17: =IF(G17=0,0,F17/G17) -> 0.37880952 | AC17: =IF(G17>1,F17/(G17-1),"n/a") -> 0.75761905 | AD17: =moves_day*m_pallet*9.81*INDEX(Tc_mh,C17)/3600000 -> 13.49856 | AE17: =IF(AND(K17<=H_max,H17<=300,OR(lane_policy="Free (optimize N_C)",B17=sku_pal),OR(env_use="No",AND(I17<=L_bldg,J17<=W_bldg),AND(I17<=W_bldg,J17<=L_bldg))),1,0) -> 0 | AF17: =IF(obj_mode="Total cost",Z17,IF(obj_mode="Shuttle cycle",O17,T17)) -> 2329285 | AG17: =IF(AE17=1,AF17*(1+A17*0.0000000001),1E+099) -> 1e+99 | AH17: =IF(AE17=1,"",IF(K17>H_max,"height",IF(AND(lane_policy<>"Free (optimize N_C)",B17<>sku_pal),"lane policy","footprint"))) -> height | AJ17: 11 | AK17: =IF(AE18=1,AF18,NA()) -> #N/A | AL17: =IF(AE38=1,AF38,NA()) -> #N/A | AM17: =IF(AE58=1,AF58,NA()) -> #N/A | AN17: =IF(AE78=1,AF78,NA()) -> #N/A | AO17: =IF(AE98=1,AF98,NA()) -> #N/A | AP17: =IF(AE118=1,AF118,NA()) -> #N/A | AQ17: =IF(AE138=1,AF138,NA()) -> #N/A | AR17: =IF(AE158=1,AF158,NA()) -> #N/A | AS17: =IF(AE178=1,AF178,NA()) -> #N/A | AT17: =IF(AE198=1,AF198,NA()) -> #N/A | AU17: =IF(AE218=1,AF218,NA()) -> #N/A
A18: 11 | B18: =$B$3 -> 2 | C18: 11 | D18: =INDEX(Tc_pl,C18) -> 0.6 | E18: =INDEX(Tc_S,C18) -> 45.63631 | F18: =lam_total*D18*E18/3600 -> 0.76060516 | G18: =IF(F18<=0.000000000001,0,MAX(ROUNDUP(F18/rho_max-0.000000001,0),IF(redund="Yes",ROUNDUP(F18/rho_fail-0.000000001,0)+1,0))) -> 2 | H18: =MAX(1,ROUNDUP((P_req/(B18*C18)+G18*lpl)/2-0.000000001,0)) -> 110 | I18: =H18*u_w -> 110 | J18: =2*B18*u_d+aisle_w -> 6.5 | K18: =C18*u_h -> 23.65 | L18: =IF(G18=0,I18,I18/(2*G18)) -> 27.5 | M18: =((IF((lane_off+(L18))<=(v_sh^2/a_sh),(4/3)*(lane_off+(L18))^1.5/SQRT(a_sh),(4/3)*(v_sh^2/a_sh)^1.5/SQRT(a_sh)+((lane_off+(L18))^2-(v_sh^2/a_sh)^2)/(2*v_sh)+(v_sh/a_sh)*((lane_off+(L18))-(v_sh^2/a_sh))))-(IF((lane_off)<=(v_sh^2/a_sh),(4/3)*(lane_off)^1.5/SQRT(a_sh),(4/3)*(v_sh^2/a_sh)^1.5/SQRT(a_sh)+((lane_off)^2-(v_sh^2/a_sh)^2)/(2*v_sh)+(v_sh/a_sh)*((lane_off)-(v_sh^2/a_sh)))))/(L18) -> 13.536157 | N18: =IF(((B18-1)*u_d/2*(1+f_hc)+lane_off)<=0,0,IF(((B18-1)*u_d/2*(1+f_hc)+lane_off)>=v_sh^2/a_sh,((B18-1)*u_d/2*(1+f_hc)+lane_off)/v_sh+v_sh/a_sh,2*SQRT(((B18-1)*u_d/2*(1+f_hc)+lane_off)/a_sh))) -> 4.0792156 | O18: =2*t_sh+2*t_turn+2*M18+2*N18 -> 93.230746 | P18: =SUMPRODUCT((Tc_idx<=C18)*(ROUNDUP(lam_total*INDEX(Tc_P,C18,0)*O18/(3600*rho_max)-0.000000001,0)+(ROUNDUP(lam_total*INDEX(Tc_P,C18,0)*O18/(3600*rho_max)-0.000000001,0)<min_sh)*(min_sh-ROUNDUP(lam_total*INDEX(Tc_P,C18,0)*O18/(3600*rho_max)-0.000000001,0)))) -> 13 | Q18: =ROUNDUP(P18-0.000000001,0)+spares -> 15 | R18: =B18*C18*(2*H18-G18*lpl) -> 4708 | S18: =R18*fill -> 4001.8 | T18: =I18*J18 -> 715 | U18: =T18*(K18+headroom) -> 17982.25 | V18: =G18*c_lift -> 300000 | W18: =Q18*c_shut -> 750000 | X18: =R18*c_pos -> 470800 | Y18: =T18*c_m2+U18*c_m3 -> 825467.5 | Z18: =SUM(V18:Y18) -> 2346267.5 | AA18: =B18*u_d/(H18*u_w) -> 0.023636364 | AB18: =IF(G18=0,0,F18/G18) -> 0.38030258 | AC18: =IF(G18>1,F18/(G18-1),"n/a") -> 0.76060516 | AD18: =moves_day*m_pallet*9.81*INDEX(Tc_mh,C18)/3600000 -> 13.77978 | AE18: =IF(AND(K18<=H_max,H18<=300,OR(lane_policy="Free (optimize N_C)",B18=sku_pal),OR(env_use="No",AND(I18<=L_bldg,J18<=W_bldg),AND(I18<=W_bldg,J18<=L_bldg))),1,0) -> 0 | AF18: =IF(obj_mode="Total cost",Z18,IF(obj_mode="Shuttle cycle",O18,T18)) -> 2346267.5 | AG18: =IF(AE18=1,AF18*(1+A18*0.0000000001),1E+099) -> 1e+99 | AH18: =IF(AE18=1,"",IF(K18>H_max,"height",IF(AND(lane_policy<>"Free (optimize N_C)",B18<>sku_pal),"lane policy","footprint"))) -> height | AJ18: 12 | AK18: =IF(AE19=1,AF19,NA()) -> #N/A | AL18: =IF(AE39=1,AF39,NA()) -> #N/A | AM18: =IF(AE59=1,AF59,NA()) -> #N/A | AN18: =IF(AE79=1,AF79,NA()) -> #N/A | AO18: =IF(AE99=1,AF99,NA()) -> #N/A | AP18: =IF(AE119=1,AF119,NA()) -> #N/A | AQ18: =IF(AE139=1,AF139,NA()) -> #N/A | AR18: =IF(AE159=1,AF159,NA()) -> #N/A | AS18: =IF(AE179=1,AF179,NA()) -> #N/A | AT18: =IF(AE199=1,AF199,NA()) -> #N/A | AU18: =IF(AE219=1,AF219,NA()) -> #N/A
A19: 12 | B19: =$B$3 -> 2 | C19: 12 | D19: =INDEX(Tc_pl,C19) -> 0.6 | E19: =INDEX(Tc_S,C19) -> 45.815476 | F19: =lam_total*D19*E19/3600 -> 0.76359127 | G19: =IF(F19<=0.000000000001,0,MAX(ROUNDUP(F19/rho_max-0.000000001,0),IF(redund="Yes",ROUNDUP(F19/rho_fail-0.000000001,0)+1,0))) -> 2 | H19: =MAX(1,ROUNDUP((P_req/(B19*C19)+G19*lpl)/2-0.000000001,0)) -> 102 | I19: =H19*u_w -> 102 | J19: =2*B19*u_d+aisle_w -> 6.5 | K19: =C19*u_h -> 25.8 | L19: =IF(G19=0,I19,I19/(2*G19)) -> 25.5 | M19: =((IF((lane_off+(L19))<=(v_sh^2/a_sh),(4/3)*(lane_off+(L19))^1.5/SQRT(a_sh),(4/3)*(v_sh^2/a_sh)^1.5/SQRT(a_sh)+((lane_off+(L19))^2-(v_sh^2/a_sh)^2)/(2*v_sh)+(v_sh/a_sh)*((lane_off+(L19))-(v_sh^2/a_sh))))-(IF((lane_off)<=(v_sh^2/a_sh),(4/3)*(lane_off)^1.5/SQRT(a_sh),(4/3)*(v_sh^2/a_sh)^1.5/SQRT(a_sh)+((lane_off)^2-(v_sh^2/a_sh)^2)/(2*v_sh)+(v_sh/a_sh)*((lane_off)-(v_sh^2/a_sh)))))/(L19) -> 12.820786 | N19: =IF(((B19-1)*u_d/2*(1+f_hc)+lane_off)<=0,0,IF(((B19-1)*u_d/2*(1+f_hc)+lane_off)>=v_sh^2/a_sh,((B19-1)*u_d/2*(1+f_hc)+lane_off)/v_sh+v_sh/a_sh,2*SQRT(((B19-1)*u_d/2*(1+f_hc)+lane_off)/a_sh))) -> 4.0792156 | O19: =2*t_sh+2*t_turn+2*M19+2*N19 -> 91.800003 | P19: =SUMPRODUCT((Tc_idx<=C19)*(ROUNDUP(lam_total*INDEX(Tc_P,C19,0)*O19/(3600*rho_max)-0.000000001,0)+(ROUNDUP(lam_total*INDEX(Tc_P,C19,0)*O19/(3600*rho_max)-0.000000001,0)<min_sh)*(min_sh-ROUNDUP(lam_total*INDEX(Tc_P,C19,0)*O19/(3600*rho_max)-0.000000001,0)))) -> 14 | Q19: =ROUNDUP(P19-0.000000001,0)+spares -> 16 | R19: =B19*C19*(2*H19-G19*lpl) -> 4752 | S19: =R19*fill -> 4039.2 | T19: =I19*J19 -> 663 | U19: =T19*(K19+headroom) -> 18099.9 | V19: =G19*c_lift -> 300000 | W19: =Q19*c_shut -> 800000 | X19: =R19*c_pos -> 475200 | Y19: =T19*c_m2+U19*c_m3 -> 808197 | Z19: =SUM(V19:Y19) -> 2383397 | AA19: =B19*u_d/(H19*u_w) -> 0.025490196 | AB19: =IF(G19=0,0,F19/G19) -> 0.38179563 | AC19: =IF(G19>1,F19/(G19-1),"n/a") -> 0.76359127 | AD19: =moves_day*m_pallet*9.81*INDEX(Tc_mh,C19)/3600000 -> 14.061 | AE19: =IF(AND(K19<=H_max,H19<=300,OR(lane_policy="Free (optimize N_C)",B19=sku_pal),OR(env_use="No",AND(I19<=L_bldg,J19<=W_bldg),AND(I19<=W_bldg,J19<=L_bldg))),1,0) -> 0 | AF19: =IF(obj_mode="Total cost",Z19,IF(obj_mode="Shuttle cycle",O19,T19)) -> 2383397 | AG19: =IF(AE19=1,AF19*(1+A19*0.0000000001),1E+099) -> 1e+99 | AH19: =IF(AE19=1,"",IF(K19>H_max,"height",IF(AND(lane_policy<>"Free (optimize N_C)",B19<>sku_pal),"lane policy","footprint"))) -> height | AJ19: 13 | AK19: =IF(AE20=1,AF20,NA()) -> #N/A | AL19: =IF(AE40=1,AF40,NA()) -> #N/A | AM19: =IF(AE60=1,AF60,NA()) -> #N/A | AN19: =IF(AE80=1,AF80,NA()) -> #N/A | AO19: =IF(AE100=1,AF100,NA()) -> #N/A | AP19: =IF(AE120=1,AF120,NA()) -> #N/A | AQ19: =IF(AE140=1,AF140,NA()) -> #N/A | AR19: =IF(AE160=1,AF160,NA()) -> #N/A | AS19: =IF(AE180=1,AF180,NA()) -> #N/A | AT19: =IF(AE200=1,AF200,NA()) -> #N/A | AU19: =IF(AE220=1,AF220,NA()) -> #N/A
... A26: 19 | B26: =$B$3 -> 2 | C26: 19 | D26: =INDEX(Tc_pl,C26) -> 0.6 | E26: =INDEX(Tc_S,C26) -> 47.069643 | F26: =lam_total*D26*E26/3600 -> 0.78449405 | G26: =IF(F26<=0.000000000001,0,MAX(ROUNDUP(F26/rho_max-0.000000001,0),IF(redund="Yes",ROUNDUP(F26/rho_fail-0.000000001,0)+1,0))) -> 2 | H26: =MAX(1,ROUNDUP((P_req/(B26*C26)+G26*lpl)/2-0.000000001,0)) -> 65 | I26: =H26*u_w -> 65 | J26: =2*B26*u_d+aisle_w -> 6.5 | K26: =C26*u_h -> 40.85 | L26: =IF(G26=0,I26,I26/(2*G26)) -> 16.25 | M26: =((IF((lane_off+(L26))<=(v_sh^2/a_sh),(4/3)*(lane_off+(L26))^1.5/SQRT(a_sh),(4/3)*(v_sh^2/a_sh)^1.5/SQRT(a_sh)+((lane_off+(L26))^2-(v_sh^2/a_sh)^2)/(2*v_sh)+(v_sh/a_sh)*((lane_off+(L26))-(v_sh^2/a_sh))))-(IF((lane_off)<=(v_sh^2/a_sh),(4/3)*(lane_off)^1.5/SQRT(a_sh),(4/3)*(v_sh^2/a_sh)^1.5/SQRT(a_sh)+((lane_off)^2-(v_sh^2/a_sh)^2)/(2*v_sh)+(v_sh/a_sh)*((lane_off)-(v_sh^2/a_sh)))))/(L26) -> 9.5087165 | N26: =IF(((B26-1)*u_d/2*(1+f_hc)+lane_off)<=0,0,IF(((B26-1)*u_d/2*(1+f_hc)+lane_off)>=v_sh^2/a_sh,((B26-1)*u_d/2*(1+f_hc)+lane_off)/v_sh+v_sh/a_sh,2*SQRT(((B26-1)*u_d/2*(1+f_hc)+lane_off)/a_sh))) -> 4.0792156 | O26: =2*t_sh+2*t_turn+2*M26+2*N26 -> 85.175864 | P26: =SUMPRODUCT((Tc_idx<=C26)*(ROUNDUP(lam_total*INDEX(Tc_P,C26,0)*O26/(3600*rho_max)-0.000000001,0)+(ROUNDUP(lam_total*INDEX(Tc_P,C26,0)*O26/(3600*rho_max)-0.000000001,0)<min_sh)*(min_sh-ROUNDUP(lam_total*INDEX(Tc_P,C26,0)*O26/(3600*rho_max)-0.000000001,0)))) -> 21 | Q26: =ROUNDUP(P26-0.000000001,0)+spares -> 23 | R26: =B26*C26*(2*H26-G26*lpl) -> 4712 | S26: =R26*fill -> 4005.2 | T26: =I26*J26 -> 422.5 | U26: =T26*(K26+headroom) -> 17892.875 | V26: =G26*c_lift -> 300000 | W26: =Q26*c_shut -> 1150000 | X26: =R26*c_pos -> 471200 | Y26: =T26*c_m2+U26*c_m3 -> 705786.25 | Z26: =SUM(V26:Y26) -> 2626986.2 | AA26: =B26*u_d/(H26*u_w) -> 0.04 | AB26: =IF(G26=0,0,F26/G26) -> 0.39224702 | AC26: =IF(G26>1,F26/(G26-1),"n/a") -> 0.78449405 | AD26: =moves_day*m_pallet*9.81*INDEX(Tc_mh,C26)/3600000 -> 16.02954 | AE26: =IF(AND(K26<=H_max,H26<=300,OR(lane_policy="Free (optimize N_C)",B26=sku_pal),OR(env_use="No",AND(I26<=L_bldg,J26<=W_bldg),AND(I26<=W_bldg,J26<=L_bldg))),1,0) -> 0 | AF26: =IF(obj_mode="Total cost",Z26,IF(obj_mode="Shuttle cycle",O26,T26)) -> 2626986.2 | AG26: =IF(AE26=1,AF26*(1+A26*0.0000000001),1E+099) -> 1e+99 | AH26: =IF(AE26=1,"",IF(K26>H_max,"height",IF(AND(lane_policy<>"Free (optimize N_C)",B26<>sku_pal),"lane policy","footprint"))) -> height | AJ26: 20 | AK26: =IF(AE27=1,AF27,NA()) -> #N/A | AL26: =IF(AE47=1,AF47,NA()) -> #N/A | AM26: =IF(AE67=1,AF67,NA()) -> #N/A | AN26: =IF(AE87=1,AF87,NA()) -> #N/A | AO26: =IF(AE107=1,AF107,NA()) -> #N/A | AP26: =IF(AE127=1,AF127,NA()) -> #N/A | AQ26: =IF(AE147=1,AF147,NA()) -> #N/A | AR26: =IF(AE167=1,AF167,NA()) -> #N/A | AS26: =IF(AE187=1,AF187,NA()) -> #N/A | AT26: =IF(AE207=1,AF207,NA()) -> #N/A | AU26: =IF(AE227=1,AF227,NA()) -> #N/A
A27: 20 | B27: =$B$3 -> 2 | C27: 20 | D27: =INDEX(Tc_pl,C27) -> 0.6 | E27: =INDEX(Tc_S,C27) -> 47.24881 | F27: =lam_total*D27*E27/3600 -> 0.78748016 | G27: =IF(F27<=0.000000000001,0,MAX(ROUNDUP(F27/rho_max-0.000000001,0),IF(redund="Yes",ROUNDUP(F27/rho_fail-0.000000001,0)+1,0))) -> 2 | H27: =MAX(1,ROUNDUP((P_req/(B27*C27)+G27*lpl)/2-0.000000001,0)) -> 62 | I27: =H27*u_w -> 62 | J27: =2*B27*u_d+aisle_w -> 6.5 | K27: =C27*u_h -> 43 | L27: =IF(G27=0,I27,I27/(2*G27)) -> 15.5 | M27: =((IF((lane_off+(L27))<=(v_sh^2/a_sh),(4/3)*(lane_off+(L27))^1.5/SQRT(a_sh),(4/3)*(v_sh^2/a_sh)^1.5/SQRT(a_sh)+((lane_off+(L27))^2-(v_sh^2/a_sh)^2)/(2*v_sh)+(v_sh/a_sh)*((lane_off+(L27))-(v_sh^2/a_sh))))-(IF((lane_off)<=(v_sh^2/a_sh),(4/3)*(lane_off)^1.5/SQRT(a_sh),(4/3)*(v_sh^2/a_sh)^1.5/SQRT(a_sh)+((lane_off)^2-(v_sh^2/a_sh)^2)/(2*v_sh)+(v_sh/a_sh)*((lane_off)-(v_sh^2/a_sh)))))/(L27) -> 9.2397258 | N27: =IF(((B27-1)*u_d/2*(1+f_hc)+lane_off)<=0,0,IF(((B27-1)*u_d/2*(1+f_hc)+lane_off)>=v_sh^2/a_sh,((B27-1)*u_d/2*(1+f_hc)+lane_off)/v_sh+v_sh/a_sh,2*SQRT(((B27-1)*u_d/2*(1+f_hc)+lane_off)/a_sh))) -> 4.0792156 | O27: =2*t_sh+2*t_turn+2*M27+2*N27 -> 84.637883 | P27: =SUMPRODUCT((Tc_idx<=C27)*(ROUNDUP(lam_total*INDEX(Tc_P,C27,0)*O27/(3600*rho_max)-0.000000001,0)+(ROUNDUP(lam_total*INDEX(Tc_P,C27,0)*O27/(3600*rho_max)-0.000000001,0)<min_sh)*(min_sh-ROUNDUP(lam_total*INDEX(Tc_P,C27,0)*O27/(3600*rho_max)-0.000000001,0)))) -> 22 | Q27: =ROUNDUP(P27-0.000000001,0)+spares -> 24 | R27: =B27*C27*(2*H27-G27*lpl) -> 4720 | S27: =R27*fill -> 4012 | T27: =I27*J27 -> 403 | U27: =T27*(K27+headroom) -> 17933.5 | V27: =G27*c_lift -> 300000 | W27: =Q27*c_shut -> 1200000 | X27: =R27*c_pos -> 472000 | Y27: =T27*c_m2+U27*c_m3 -> 699205 | Z27: =SUM(V27:Y27) -> 2671205 | AA27: =B27*u_d/(H27*u_w) -> 0.041935484 | AB27: =IF(G27=0,0,F27/G27) -> 0.39374008 | AC27: =IF(G27>1,F27/(G27-1),"n/a") -> 0.78748016 | AD27: =moves_day*m_pallet*9.81*INDEX(Tc_mh,C27)/3600000 -> 16.31076 | AE27: =IF(AND(K27<=H_max,H27<=300,OR(lane_policy="Free (optimize N_C)",B27=sku_pal),OR(env_use="No",AND(I27<=L_bldg,J27<=W_bldg),AND(I27<=W_bldg,J27<=L_bldg))),1,0) -> 0 | AF27: =IF(obj_mode="Total cost",Z27,IF(obj_mode="Shuttle cycle",O27,T27)) -> 2671205 | AG27: =IF(AE27=1,AF27*(1+A27*0.0000000001),1E+099) -> 1e+99 | AH27: =IF(AE27=1,"",IF(K27>H_max,"height",IF(AND(lane_policy<>"Free (optimize N_C)",B27<>sku_pal),"lane policy","footprint"))) -> height
A28: 21 | B28: =$C$3 -> 3 | C28: 1 | D28: =INDEX(Tc_pl,C28) -> 0 | E28: =INDEX(Tc_S,C28) -> 0 | F28: =lam_total*D28*E28/3600 -> 0 | G28: =IF(F28<=0.000000000001,0,MAX(ROUNDUP(F28/rho_max-0.000000001,0),IF(redund="Yes",ROUNDUP(F28/rho_fail-0.000000001,0)+1,0))) -> 0 | H28: =MAX(1,ROUNDUP((P_req/(B28*C28)+G28*lpl)/2-0.000000001,0)) -> 785 | I28: =H28*u_w -> 785 | J28: =2*B28*u_d+aisle_w -> 9.1 | K28: =C28*u_h -> 2.15 | L28: =IF(G28=0,I28,I28/(2*G28)) -> 785 | M28: =((IF((lane_off+(L28))<=(v_sh^2/a_sh),(4/3)*(lane_off+(L28))^1.5/SQRT(a_sh),(4/3)*(v_sh^2/a_sh)^1.5/SQRT(a_sh)+((lane_off+(L28))^2-(v_sh^2/a_sh)^2)/(2*v_sh)+(v_sh/a_sh)*((lane_off+(L28))-(v_sh^2/a_sh))))-(IF((lane_off)<=(v_sh^2/a_sh),(4/3)*(lane_off)^1.5/SQRT(a_sh),(4/3)*(v_sh^2/a_sh)^1.5/SQRT(a_sh)+((lane_off)^2-(v_sh^2/a_sh)^2)/(2*v_sh)+(v_sh/a_sh)*((lane_off)-(v_sh^2/a_sh)))))/(L28) -> 284.08523 | N28: =IF(((B28-1)*u_d/2*(1+f_hc)+lane_off)<=0,0,IF(((B28-1)*u_d/2*(1+f_hc)+lane_off)>=v_sh^2/a_sh,((B28-1)*u_d/2*(1+f_hc)+lane_off)/v_sh+v_sh/a_sh,2*SQRT(((B28-1)*u_d/2*(1+f_hc)+lane_off)/a_sh))) -> 4.7833043 | O28: =2*t_sh+2*t_turn+2*M28+2*N28 -> 635.73707 | P28: =SUMPRODUCT((Tc_idx<=C28)*(ROUNDUP(lam_total*INDEX(Tc_P,C28,0)*O28/(3600*rho_max)-0.000000001,0)+(ROUNDUP(lam_total*INDEX(Tc_P,C28,0)*O28/(3600*rho_max)-0.000000001,0)<min_sh)*(min_sh-ROUNDUP(lam_total*INDEX(Tc_P,C28,0)*O28/(3600*rho_max)-0.000000001,0)))) -> 24 | Q28: =ROUNDUP(P28-0.000000001,0)+spares -> 26 | R28: =B28*C28*(2*H28-G28*lpl) -> 4710 | S28: =R28*fill -> 4003.5 | T28: =I28*J28 -> 7143.5 | U28: =T28*(K28+headroom) -> 26073.775 | V28: =G28*c_lift -> 0 | W28: =Q28*c_shut -> 1300000 | X28: =R28*c_pos -> 471000 | Y28: =T28*c_m2+U28*c_m3 -> 3639613.2 | Z28: =SUM(V28:Y28) -> 5410613.2 | AA28: =B28*u_d/(H28*u_w) -> 0.0049681529 | AB28: =IF(G28=0,0,F28/G28) -> 0 | AC28: =IF(G28>1,F28/(G28-1),"n/a") -> n/a | AD28: =moves_day*m_pallet*9.81*INDEX(Tc_mh,C28)/3600000 -> 0 | AE28: =IF(AND(K28<=H_max,H28<=300,OR(lane_policy="Free (optimize N_C)",B28=sku_pal),OR(env_use="No",AND(I28<=L_bldg,J28<=W_bldg),AND(I28<=W_bldg,J28<=L_bldg))),1,0) -> 0 | AF28: =IF(obj_mode="Total cost",Z28,IF(obj_mode="Shuttle cycle",O28,T28)) -> 5410613.2 | AG28: =IF(AE28=1,AF28*(1+A28*0.0000000001),1E+099) -> 1e+99 | AH28: =IF(AE28=1,"",IF(K28>H_max,"height",IF(AND(lane_policy<>"Free (optimize N_C)",B28<>sku_pal),"lane policy","footprint"))) -> footprint
A29: 22 | B29: =$C$3 -> 3 | C29: 2 | D29: =INDEX(Tc_pl,C29) -> 0.5 | E29: =INDEX(Tc_S,C29) -> 41.157143 | F29: =lam_total*D29*E29/3600 -> 0.57162698 | G29: =IF(F29<=0.000000000001,0,MAX(ROUNDUP(F29/rho_max-0.000000001,0),IF(redund="Yes",ROUNDUP(F29/rho_fail-0.000000001,0)+1,0))) -> 2 | H29: =MAX(1,ROUNDUP((P_req/(B29*C29)+G29*lpl)/2-0.000000001,0)) -> 396 | I29: =H29*u_w -> 396 | J29: =2*B29*u_d+aisle_w -> 9.1 | K29: =C29*u_h -> 4.3 | L29: =IF(G29=0,I29,I29/(2*G29)) -> 99 | M29: =((IF((lane_off+(L29))<=(v_sh^2/a_sh),(4/3)*(lane_off+(L29))^1.5/SQRT(a_sh),(4/3)*(v_sh^2/a_sh)^1.5/SQRT(a_sh)+((lane_off+(L29))^2-(v_sh^2/a_sh)^2)/(2*v_sh)+(v_sh/a_sh)*((lane_off+(L29))-(v_sh^2/a_sh))))-(IF((lane_off)<=(v_sh^2/a_sh),(4/3)*(lane_off)^1.5/SQRT(a_sh),(4/3)*(v_sh^2/a_sh)^1.5/SQRT(a_sh)+((lane_off)^2-(v_sh^2/a_sh)^2)/(2*v_sh)+(v_sh/a_sh)*((lane_off)-(v_sh^2/a_sh)))))/(L29) -> 39.081869 | N29: =IF(((B29-1)*u_d/2*(1+f_hc)+lane_off)<=0,0,IF(((B29-1)*u_d/2*(1+f_hc)+lane_off)>=v_sh^2/a_sh,((B29-1)*u_d/2*(1+f_hc)+lane_off)/v_sh+v_sh/a_sh,2*SQRT(((B29-1)*u_d/2*(1+f_hc)+lane_off)/a_sh))) -> 4.7833043 | O29: =2*t_sh+2*t_turn+2*M29+2*N29 -> 145.73035 | P29: =SUMPRODUCT((Tc_idx<=C29)*(ROUNDUP(lam_total*INDEX(Tc_P,C29,0)*O29/(3600*rho_max)-0.000000001,0)+(ROUNDUP(lam_total*INDEX(Tc_P,C29,0)*O29/(3600*rho_max)-0.000000001,0)<min_sh)*(min_sh-ROUNDUP(lam_total*INDEX(Tc_P,C29,0)*O29/(3600*rho_max)-0.000000001,0)))) -> 6 | Q29: =ROUNDUP(P29-0.000000001,0)+spares -> 8 | R29: =B29*C29*(2*H29-G29*lpl) -> 4716 | S29: =R29*fill -> 4008.6 | T29: =I29*J29 -> 3603.6 | U29: =T29*(K29+headroom) -> 20900.88 | V29: =G29*c_lift -> 300000 | W29: =Q29*c_shut -> 400000 | X29: =R29*c_pos -> 471600 | Y29: =T29*c_m2+U29*c_m3 -> 2068466.4 | Z29: =SUM(V29:Y29) -> 3240066.4 | AA29: =B29*u_d/(H29*u_w) -> 0.0098484848 | AB29: =IF(G29=0,0,F29/G29) -> 0.28581349 | AC29: =IF(G29>1,F29/(G29-1),"n/a") -> 0.57162698 | AD29: =moves_day*m_pallet*9.81*INDEX(Tc_mh,C29)/3600000 -> 5.6244 | AE29: =IF(AND(K29<=H_max,H29<=300,OR(lane_policy="Free (optimize N_C)",B29=sku_pal),OR(env_use="No",AND(I29<=L_bldg,J29<=W_bldg),AND(I29<=W_bldg,J29<=L_bldg))),1,0) -> 0 | AF29: =IF(obj_mode="Total cost",Z29,IF(obj_mode="Shuttle cycle",O29,T29)) -> 3240066.4 | AG29: =IF(AE29=1,AF29*(1+A29*0.0000000001),1E+099) -> 1e+99 | AH29: =IF(AE29=1,"",IF(K29>H_max,"height",IF(AND(lane_policy<>"Free (optimize N_C)",B29<>sku_pal),"lane policy","footprint"))) -> footprint
