Workbook

Sheet README
A1: APW 2026/27 – Six-way shuttle warehouse: parametric model workbook
A3: What this is
A4: Analytical model of the 45×30×20 m warehouse with six-way shuttles and lifts, with the parameters N_C, N_L, N_T, number of lifts, f and the ABC split as inputs.
A5: It reproduces the numbers of the guide document and lets you run the sweeps for the presentation.
A7: How to use
A8: 1. Go to Inputs and edit only the blue cells on yellow background (data from the assignment and my assumptions are labelled).
A9: 2. Read the results in Model (design, capacity, shuttle cycle, lifts, fleet, checks).
A10: 3. Sweeps shows D/W, number of lifts, peak factor and honeycombing sweeps with two charts.
A11: 4. DES_validation compares the analytical model with the discrete-event simulation (Python script, static values).
A13: Sheets
A14: Inputs – parameters. Model – results and checks. Sweeps – parametric studies. Tiers and Lift_grid – helper calculations. DES_validation – simulation results.
A16: Colour code
... A29: A1 pitch 1.25 × 0.85 m; A2 vertical pitch 1.85 m (150 mm read as rail/beam); A3 generic six-way shuttle; A4 single-command cycles; A5 f = 0.2; A6 tier 1 at ground level; A7 pallets of 1000 kg.

Sheet Inputs
A1: INPUTS – edit only the blue cells on yellow background
A3: Parameter | B3: Value | C3: Unit | D3: Note / source
A4: Shuttle kinematics (assignment data)
A5: Shuttle max speed | B5: 1.4 | C5: m/s | D5: Assignment slide 'Kinematic parameters'
A6: Shuttle acceleration = deceleration | B6: 0.5 | C6: m/s² | D6: Assignment
A7: Direction change time | B7: 4 | C7: s | D7: Assignment ('transit time')
A8: Shuttle load/unload time (rack / conveyor) | B8: 25 | C8: s | D8: Assignment
A9: Lift kinematics (assignment data)
A10: Lift max speed | B10: 1 | C10: m/s | D10: Assignment
A11: Lift acceleration | B11: 0.7 | C11: m/s² | D11: Assignment
A12: Lift positioning time | B12: 1 | C12: s | D12: Assignment
A13: Lift load/unload with chain conveyor | B13: 7 | C13: s | D13: Assignment
A14: Lift load/unload with shuttle | B14: 25 | C14: s | D14: Assignment
A15: Lift interface at the tiers | B15: Shuttle | D15: 'Shuttle' = 25 s hand-over; 'Chain' = chain conveyor at each tier (7 s)
A16: Geometry
A17: Position pitch across lanes (u_w) | B17: 0.85 | C17: m | D17: ASSUMPTION A1: pallet 800 + 50 mm clearance
A18: Position pitch along lane (u_d) | B18: 1.25 | C18: m | D18: ASSUMPTION A1: pallet 1200 + 50 mm clearance
A19: Vertical pitch (u_h) | B19: 1.85 | C19: m | D19: ASSUMPTION A2: 1700 + 150 mm (to confirm with professor)
A20: Building height | B20: 20 | C20: m | D20: Assignment
A21: Building length | B21: 45 | C21: m | D21: Assignment
A22: Building width | B22: 30 | C22: m | D22: Assignment
A23: Cross-aisle width | B23: 1.5 | C23: m | D23: ASSUMPTION: shuttle 1045 x 890 mm + clearance
A24: Offset aisle centre -> first slot / lift | B24: 1 | C24: m | D24: ASSUMPTION (as in the guide document)
A25: Design variables
A26: N_C – positions per lane (depth) | B26: 6 | C26: pos | D26: Assignment: 6 unit loads per SKU
A27: N_L – lanes per side of the cross-aisle | B27: 44 | C27: lanes | D27: Design choice (aisle length = N_L x u_w)
A28: N_T – number of tiers (max 20) | B28: 10 | C28: tiers | D28: 20 m / 1.85 m = 10.8 -> 10
A29: Number of lifts | B29: 3 | C29: lifts | D29: Design choice (N+1)
A30: Lift layout along the aisle | B30: Equispaced | D30: 'Equispaced' = (2k-1)L/(2n); 'End' = single lift at the aisle end
A31: Honeycombing factor f | B31: 0.2 | C31: - | D31: ASSUMPTION A5 (paper tests 0 - 0.2)
A32: Lanes replaced by each lift shaft | B32: 3 | C32: lanes | D32: ASSUMPTION (one side of the aisle)
A33: Average fill ratio | B33: 0.85 | C33: - | D33: ASSUMPTION
A34: Required capacity | B34: 4000 | C34: pallets | D34: Assignment (> 4000)
A35: Flows (assignment data)
A36: Inbound rate (24 h/day) | B36: 40 | C36: pallets/h | D36: Assignment
A37: Outbound rate (16 h/day) | B37: 60 | C37: pallets/h | D37: Assignment
A38: Peak design factor | B38: 1 | C38: x | D38: 1.25 = +25 % margin
A39: Inbound hours per day | B39: 24 | C39: h | D39: Assignment
A40: Outbound hours per day | B40: 16 | C40: h | D40: Assignment
A41: ABC distribution of transactions over tiers
...

Sheet Tiers
A1: TIER TABLE (helper sheet – formulas only)
A3: Tier | B3: Active | C3: Height h (m) | D3: p Uniform | E3: p ABC | F3: p selected | G3: Lift travel t(h) (s) | H3: Lift single cycle (s) | I3: q Uniform (tiers ≥2) | J3: q ABC (tiers ≥2) | K3: Tier load (tx/h) | L3: Shuttles assigned | M3: Shuttle utilization | N3: Status
A4: 1 | B4: =IF(A4<=N_T,1,0) -> 1 | C4: =IF(B4=1,(A4-1)*u_h,0) -> 0 | D4: =IF(B4=1,1/N_T,0) -> 0.1 | E4: =IF(B4=0,0,IF(A4<=nA,shareA/nA,IF(A4<=nA+nB,shareB/nB,IF(N_T-nA-nB>0,shareC/(N_T-nA-nB),0)))) -> 0.4 | F4: =IF(dist_mode="ABC",E4,D4) -> 0.4 | G4: =IF((C4)<=0,0,IF((C4)>=v_lift^2/a_lift,(C4)/v_lift+v_lift/a_lift,2*SQRT((C4)/a_lift))) -> 0 | H4: =IF(AND(A4>=2,B4=1),t_ch+t_I+2*G4+2*t_pos,0) -> 0 | I4: =IF(AND(A4>=2,B4=1),D4/(1-$D$4),0) -> 0 | J4: =IF(AND(A4>=2,B4=1),E4/(1-$E$4),0) -> 0 | K4: =lam_total*F4 -> 40 | L4: =Inputs!B56 -> 2 | M4: =IF(AND(B4=1,L4>0),K4*Tcyc_sh/3600/L4,"") -> 0.4538205 | N4: =IF(M4="","",IF(M4<=rho_max,"OK","CHECK")) -> OK
A5: 2 | B5: =IF(A5<=N_T,1,0) -> 1 | C5: =IF(B5=1,(A5-1)*u_h,0) -> 1.85 | D5: =IF(B5=1,1/N_T,0) -> 0.1 | E5: =IF(B5=0,0,IF(A5<=nA,shareA/nA,IF(A5<=nA+nB,shareB/nB,IF(N_T-nA-nB>0,shareC/(N_T-nA-nB),0)))) -> 0.4 | F5: =IF(dist_mode="ABC",E5,D5) -> 0.4 | G5: =IF((C5)<=0,0,IF((C5)>=v_lift^2/a_lift,(C5)/v_lift+v_lift/a_lift,2*SQRT((C5)/a_lift))) -> 3.2785714 | H5: =IF(AND(A5>=2,B5=1),t_ch+t_I+2*G5+2*t_pos,0) -> 40.557143 | I5: =IF(AND(A5>=2,B5=1),D5/(1-$D$4),0) -> 0.11111111 | J5: =IF(AND(A5>=2,B5=1),E5/(1-$E$4),0) -> 0.66666667 | K5: =lam_total*F5 -> 40 | L5: =Inputs!B57 -> 2 | M5: =IF(AND(B5=1,L5>0),K5*Tcyc_sh/3600/L5,"") -> 0.4538205 | N5: =IF(M5="","",IF(M5<=rho_max,"OK","CHECK")) -> OK
A6: 3 | B6: =IF(A6<=N_T,1,0) -> 1 | C6: =IF(B6=1,(A6-1)*u_h,0) -> 3.7 | D6: =IF(B6=1,1/N_T,0) -> 0.1 | E6: =IF(B6=0,0,IF(A6<=nA,shareA/nA,IF(A6<=nA+nB,shareB/nB,IF(N_T-nA-nB>0,shareC/(N_T-nA-nB),0)))) -> 0.05 | F6: =IF(dist_mode="ABC",E6,D6) -> 0.05 | G6: =IF((C6)<=0,0,IF((C6)>=v_lift^2/a_lift,(C6)/v_lift+v_lift/a_lift,2*SQRT((C6)/a_lift))) -> 5.1285714 | H6: =IF(AND(A6>=2,B6=1),t_ch+t_I+2*G6+2*t_pos,0) -> 44.257143 | I6: =IF(AND(A6>=2,B6=1),D6/(1-$D$4),0) -> 0.11111111 | J6: =IF(AND(A6>=2,B6=1),E6/(1-$E$4),0) -> 0.083333333 | K6: =lam_total*F6 -> 5 | L6: =Inputs!B58 -> 1 | M6: =IF(AND(B6=1,L6>0),K6*Tcyc_sh/3600/L6,"") -> 0.11345513 | N6: =IF(M6="","",IF(M6<=rho_max,"OK","CHECK")) -> OK
A7: 4 | B7: =IF(A7<=N_T,1,0) -> 1 | C7: =IF(B7=1,(A7-1)*u_h,0) -> 5.55 | D7: =IF(B7=1,1/N_T,0) -> 0.1 | E7: =IF(B7=0,0,IF(A7<=nA,shareA/nA,IF(A7<=nA+nB,shareB/nB,IF(N_T-nA-nB>0,shareC/(N_T-nA-nB),0)))) -> 0.05 | F7: =IF(dist_mode="ABC",E7,D7) -> 0.05 | G7: =IF((C7)<=0,0,IF((C7)>=v_lift^2/a_lift,(C7)/v_lift+v_lift/a_lift,2*SQRT((C7)/a_lift))) -> 6.9785714 | H7: =IF(AND(A7>=2,B7=1),t_ch+t_I+2*G7+2*t_pos,0) -> 47.957143 | I7: =IF(AND(A7>=2,B7=1),D7/(1-$D$4),0) -> 0.11111111 | J7: =IF(AND(A7>=2,B7=1),E7/(1-$E$4),0) -> 0.083333333 | K7: =lam_total*F7 -> 5 | L7: =Inputs!B59 -> 1 | M7: =IF(AND(B7=1,L7>0),K7*Tcyc_sh/3600/L7,"") -> 0.11345513 | N7: =IF(M7="","",IF(M7<=rho_max,"OK","CHECK")) -> OK
A8: 5 | B8: =IF(A8<=N_T,1,0) -> 1 | C8: =IF(B8=1,(A8-1)*u_h,0) -> 7.4 | D8: =IF(B8=1,1/N_T,0) -> 0.1 | E8: =IF(B8=0,0,IF(A8<=nA,shareA/nA,IF(A8<=nA+nB,shareB/nB,IF(N_T-nA-nB>0,shareC/(N_T-nA-nB),0)))) -> 0.05 | F8: =IF(dist_mode="ABC",E8,D8) -> 0.05 | G8: =IF((C8)<=0,0,IF((C8)>=v_lift^2/a_lift,(C8)/v_lift+v_lift/a_lift,2*SQRT((C8)/a_lift))) -> 8.8285714 | H8: =IF(AND(A8>=2,B8=1),t_ch+t_I+2*G8+2*t_pos,0) -> 51.657143 | I8: =IF(AND(A8>=2,B8=1),D8/(1-$D$4),0) -> 0.11111111 | J8: =IF(AND(A8>=2,B8=1),E8/(1-$E$4),0) -> 0.083333333 | K8: =lam_total*F8 -> 5 | L8: =Inputs!B60 -> 1 | M8: =IF(AND(B8=1,L8>0),K8*Tcyc_sh/3600/L8,"") -> 0.11345513 | N8: =IF(M8="","",IF(M8<=rho_max,"OK","CHECK")) -> OK
A9: 6 | B9: =IF(A9<=N_T,1,0) -> 1 | C9: =IF(B9=1,(A9-1)*u_h,0) -> 9.25 | D9: =IF(B9=1,1/N_T,0) -> 0.1 | E9: =IF(B9=0,0,IF(A9<=nA,shareA/nA,IF(A9<=nA+nB,shareB/nB,IF(N_T-nA-nB>0,shareC/(N_T-nA-nB),0)))) -> 0.01 | F9: =IF(dist_mode="ABC",E9,D9) -> 0.01 | G9: =IF((C9)<=0,0,IF((C9)>=v_lift^2/a_lift,(C9)/v_lift+v_lift/a_lift,2*SQRT((C9)/a_lift))) -> 10.678571 | H9: =IF(AND(A9>=2,B9=1),t_ch+t_I+2*G9+2*t_pos,0) -> 55.357143 | I9: =IF(AND(A9>=2,B9=1),D9/(1-$D$4),0) -> 0.11111111 | J9: =IF(AND(A9>=2,B9=1),E9/(1-$E$4),0) -> 0.016666667 | K9: =lam_total*F9 -> 1 | L9: =Inputs!B61 -> 0.4 | M9: =IF(AND(B9=1,L9>0),K9*Tcyc_sh/3600/L9,"") -> 0.056727563 | N9: =IF(M9="","",IF(M9<=rho_max,"OK","CHECK")) -> OK
A10: 7 | B10: =IF(A10<=N_T,1,0) -> 1 | C10: =IF(B10=1,(A10-1)*u_h,0) -> 11.1 | D10: =IF(B10=1,1/N_T,0) -> 0.1 | E10: =IF(B10=0,0,IF(A10<=nA,shareA/nA,IF(A10<=nA+nB,shareB/nB,IF(N_T-nA-nB>0,shareC/(N_T-nA-nB),0)))) -> 0.01 | F10: =IF(dist_mode="ABC",E10,D10) -> 0.01 | G10: =IF((C10)<=0,0,IF((C10)>=v_lift^2/a_lift,(C10)/v_lift+v_lift/a_lift,2*SQRT((C10)/a_lift))) -> 12.528571 | H10: =IF(AND(A10>=2,B10=1),t_ch+t_I+2*G10+2*t_pos,0) -> 59.057143 | I10: =IF(AND(A10>=2,B10=1),D10/(1-$D$4),0) -> 0.11111111 | J10: =IF(AND(A10>=2,B10=1),E10/(1-$E$4),0) -> 0.016666667 | K10: =lam_total*F10 -> 1 | L10: =Inputs!B62 -> 0.4 | M10: =IF(AND(B10=1,L10>0),K10*Tcyc_sh/3600/L10,"") -> 0.056727563 | N10: =IF(M10="","",IF(M10<=rho_max,"OK","CHECK")) -> OK
A11: 8 | B11: =IF(A11<=N_T,1,0) -> 1 | C11: =IF(B11=1,(A11-1)*u_h,0) -> 12.95 | D11: =IF(B11=1,1/N_T,0) -> 0.1 | E11: =IF(B11=0,0,IF(A11<=nA,shareA/nA,IF(A11<=nA+nB,shareB/nB,IF(N_T-nA-nB>0,shareC/(N_T-nA-nB),0)))) -> 0.01 | F11: =IF(dist_mode="ABC",E11,D11) -> 0.01 | G11: =IF((C11)<=0,0,IF((C11)>=v_lift^2/a_lift,(C11)/v_lift+v_lift/a_lift,2*SQRT((C11)/a_lift))) -> 14.378571 | H11: =IF(AND(A11>=2,B11=1),t_ch+t_I+2*G11+2*t_pos,0) -> 62.757143 | I11: =IF(AND(A11>=2,B11=1),D11/(1-$D$4),0) -> 0.11111111 | J11: =IF(AND(A11>=2,B11=1),E11/(1-$E$4),0) -> 0.016666667 | K11: =lam_total*F11 -> 1 | L11: =Inputs!B63 -> 0.4 | M11: =IF(AND(B11=1,L11>0),K11*Tcyc_sh/3600/L11,"") -> 0.056727563 | N11: =IF(M11="","",IF(M11<=rho_max,"OK","CHECK")) -> OK
A12: 9 | B12: =IF(A12<=N_T,1,0) -> 1 | C12: =IF(B12=1,(A12-1)*u_h,0) -> 14.8 | D12: =IF(B12=1,1/N_T,0) -> 0.1 | E12: =IF(B12=0,0,IF(A12<=nA,shareA/nA,IF(A12<=nA+nB,shareB/nB,IF(N_T-nA-nB>0,shareC/(N_T-nA-nB),0)))) -> 0.01 | F12: =IF(dist_mode="ABC",E12,D12) -> 0.01 | G12: =IF((C12)<=0,0,IF((C12)>=v_lift^2/a_lift,(C12)/v_lift+v_lift/a_lift,2*SQRT((C12)/a_lift))) -> 16.228571 | H12: =IF(AND(A12>=2,B12=1),t_ch+t_I+2*G12+2*t_pos,0) -> 66.457143 | I12: =IF(AND(A12>=2,B12=1),D12/(1-$D$4),0) -> 0.11111111 | J12: =IF(AND(A12>=2,B12=1),E12/(1-$E$4),0) -> 0.016666667 | K12: =lam_total*F12 -> 1 | L12: =Inputs!B64 -> 0.4 | M12: =IF(AND(B12=1,L12>0),K12*Tcyc_sh/3600/L12,"") -> 0.056727563 | N12: =IF(M12="","",IF(M12<=rho_max,"OK","CHECK")) -> OK
A13: 10 | B13: =IF(A13<=N_T,1,0) -> 1 | C13: =IF(B13=1,(A13-1)*u_h,0) -> 16.65 | D13: =IF(B13=1,1/N_T,0) -> 0.1 | E13: =IF(B13=0,0,IF(A13<=nA,shareA/nA,IF(A13<=nA+nB,shareB/nB,IF(N_T-nA-nB>0,shareC/(N_T-nA-nB),0)))) -> 0.01 | F13: =IF(dist_mode="ABC",E13,D13) -> 0.01 | G13: =IF((C13)<=0,0,IF((C13)>=v_lift^2/a_lift,(C13)/v_lift+v_lift/a_lift,2*SQRT((C13)/a_lift))) -> 18.078571 | H13: =IF(AND(A13>=2,B13=1),t_ch+t_I+2*G13+2*t_pos,0) -> 70.157143 | I13: =IF(AND(A13>=2,B13=1),D13/(1-$D$4),0) -> 0.11111111 | J13: =IF(AND(A13>=2,B13=1),E13/(1-$E$4),0) -> 0.016666667 | K13: =lam_total*F13 -> 1 | L13: =Inputs!B65 -> 0.4 | M13: =IF(AND(B13=1,L13>0),K13*Tcyc_sh/3600/L13,"") -> 0.056727563 | N13: =IF(M13="","",IF(M13<=rho_max,"OK","CHECK")) -> OK
A14: 11 | B14: =IF(A14<=N_T,1,0) -> 0 | C14: =IF(B14=1,(A14-1)*u_h,0) -> 0 | D14: =IF(B14=1,1/N_T,0) -> 0 | E14: =IF(B14=0,0,IF(A14<=nA,shareA/nA,IF(A14<=nA+nB,shareB/nB,IF(N_T-nA-nB>0,shareC/(N_T-nA-nB),0)))) -> 0 | F14: =IF(dist_mode="ABC",E14,D14) -> 0 | G14: =IF((C14)<=0,0,IF((C14)>=v_lift^2/a_lift,(C14)/v_lift+v_lift/a_lift,2*SQRT((C14)/a_lift))) -> 0 | H14: =IF(AND(A14>=2,B14=1),t_ch+t_I+2*G14+2*t_pos,0) -> 0 | I14: =IF(AND(A14>=2,B14=1),D14/(1-$D$4),0) -> 0 | J14: =IF(AND(A14>=2,B14=1),E14/(1-$E$4),0) -> 0 | K14: =lam_total*F14 -> 0 | L14: =Inputs!B66 -> 0 | M14: =IF(AND(B14=1,L14>0),K14*Tcyc_sh/3600/L14,"") | N14: =IF(M14="","",IF(M14<=rho_max,"OK","CHECK"))
A15: 12 | B15: =IF(A15<=N_T,1,0) -> 0 | C15: =IF(B15=1,(A15-1)*u_h,0) -> 0 | D15: =IF(B15=1,1/N_T,0) -> 0 | E15: =IF(B15=0,0,IF(A15<=nA,shareA/nA,IF(A15<=nA+nB,shareB/nB,IF(N_T-nA-nB>0,shareC/(N_T-nA-nB),0)))) -> 0 | F15: =IF(dist_mode="ABC",E15,D15) -> 0 | G15: =IF((C15)<=0,0,IF((C15)>=v_lift^2/a_lift,(C15)/v_lift+v_lift/a_lift,2*SQRT((C15)/a_lift))) -> 0 | H15: =IF(AND(A15>=2,B15=1),t_ch+t_I+2*G15+2*t_pos,0) -> 0 | I15: =IF(AND(A15>=2,B15=1),D15/(1-$D$4),0) -> 0 | J15: =IF(AND(A15>=2,B15=1),E15/(1-$E$4),0) -> 0 | K15: =lam_total*F15 -> 0 | L15: =Inputs!B67 -> 0 | M15: =IF(AND(B15=1,L15>0),K15*Tcyc_sh/3600/L15,"") | N15: =IF(M15="","",IF(M15<=rho_max,"OK","CHECK"))
... A23: 20 | B23: =IF(A23<=N_T,1,0) -> 0 | C23: =IF(B23=1,(A23-1)*u_h,0) -> 0 | D23: =IF(B23=1,1/N_T,0) -> 0 | E23: =IF(B23=0,0,IF(A23<=nA,shareA/nA,IF(A23<=nA+nB,shareB/nB,IF(N_T-nA-nB>0,shareC/(N_T-nA-nB),0)))) -> 0 | F23: =IF(dist_mode="ABC",E23,D23) -> 0 | G23: =IF((C23)<=0,0,IF((C23)>=v_lift^2/a_lift,(C23)/v_lift+v_lift/a_lift,2*SQRT((C23)/a_lift))) -> 0 | H23: =IF(AND(A23>=2,B23=1),t_ch+t_I+2*G23+2*t_pos,0) -> 0 | I23: =IF(AND(A23>=2,B23=1),D23/(1-$D$4),0) -> 0 | J23: =IF(AND(A23>=2,B23=1),E23/(1-$E$4),0) -> 0 | K23: =lam_total*F23 -> 0 | L23: =Inputs!B75 -> 0 | M23: =IF(AND(B23=1,L23>0),K23*Tcyc_sh/3600/L23,"") | N23: =IF(M23="","",IF(M23<=rho_max,"OK","CHECK"))
A25: Sum / check | D25: =SUM(D4:D23) -> 1 | E25: =SUM(E4:E23) -> 1 | F25: =SUM(F4:F23) -> 1 | K25: =SUM(K4:K23) -> 100 | L25: =SUM(L4:L23) -> 9

Sheet Lift_grid
A1: DUAL-COMMAND LIFT CYCLE GRID (helper sheet): weight q_i·q_j·T_dual(i,j), tiers ≥ 2
A3: Uniform distribution
C4: tier j → | D4: 1 | E4: 2 | F4: 3 | G4: 4 | H4: 5 | I4: 6 | J4: 7 | K4: 8 | L4: 9 | M4: 10 | N4: 11 | O4: 12 | P4: 13 | Q4: 14 | R4: 15 | S4: 16 | T4: 17 | U4: 18 | V4: 19 | W4: 20
C5: h_j (m) | D5: =Tiers!C4 -> 0 | E5: =Tiers!C5 -> 1.85 | F5: =Tiers!C6 -> 3.7 | G5: =Tiers!C7 -> 5.55 | H5: =Tiers!C8 -> 7.4 | I5: =Tiers!C9 -> 9.25 | J5: =Tiers!C10 -> 11.1 | K5: =Tiers!C11 -> 12.95 | L5: =Tiers!C12 -> 14.8 | M5: =Tiers!C13 -> 16.65 | N5: =Tiers!C14 -> 0 | O5: =Tiers!C15 -> 0 | P5: =Tiers!C16 -> 0 | Q5: =Tiers!C17 -> 0 | R5: =Tiers!C18 -> 0 | S5: =Tiers!C19 -> 0 | T5: =Tiers!C20 -> 0 | U5: =Tiers!C21 -> 0 | V5: =Tiers!C22 -> 0 | W5: =Tiers!C23 -> 0
C6: q_j | D6: =Tiers!I4 -> 0 | E6: =Tiers!I5 -> 0.11111111 | F6: =Tiers!I6 -> 0.11111111 | G6: =Tiers!I7 -> 0.11111111 | H6: =Tiers!I8 -> 0.11111111 | I6: =Tiers!I9 -> 0.11111111 | J6: =Tiers!I10 -> 0.11111111 | K6: =Tiers!I11 -> 0.11111111 | L6: =Tiers!I12 -> 0.11111111 | M6: =Tiers!I13 -> 0.11111111 | N6: =Tiers!I14 -> 0 | O6: =Tiers!I15 -> 0 | P6: =Tiers!I16 -> 0 | Q6: =Tiers!I17 -> 0 | R6: =Tiers!I18 -> 0 | S6: =Tiers!I19 -> 0 | T6: =Tiers!I20 -> 0 | U6: =Tiers!I21 -> 0 | V6: =Tiers!I22 -> 0 | W6: =Tiers!I23 -> 0
A7: tier i | B7: h_i (m) | C7: q_i
A8: 1 | B8: =Tiers!C4 -> 0 | C8: =Tiers!I4 -> 0 | D8: =$C8*D$6*(t_ch+IF(($B8)<=0,0,IF(($B8)>=v_lift^2/a_lift,($B8)/v_lift+v_lift/a_lift,2*SQRT(($B8)/a_lift)))+t_pos+t_I+IF((ABS($B8-D$5))<=0,0,IF((ABS($B8-D$5))>=v_lift^2/a_lift,(ABS($B8-D$5))/v_lift+v_lift/a_lift,2*SQRT((ABS($B8-D$5))/a_lift)))+t_pos+t_I+IF((D$5)<=0,0,IF((D$5)>=v_lift^2/a_lift,(D$5)/v_lift+v_lift/a_lift,2*SQRT((D$5)/a_lift)))+t_pos+t_ch) -> 0 | E8: =$C8*E$6*(t_ch+IF(($B8)<=0,0,IF(($B8)>=v_lift^2/a_lift,($B8)/v_lift+v_lift/a_lift,2*SQRT(($B8)/a_lift)))+t_pos+t_I+IF((ABS($B8-E$5))<=0,0,IF((ABS($B8-E$5))>=v_lift^2/a_lift,(ABS($B8-E$5))/v_lift+v_lift/a_lift,2*SQRT((ABS($B8-E$5))/a_lift)))+t_pos+t_I+IF((E$5)<=0,0,IF((E$5)>=v_lift^2/a_lift,(E$5)/v_lift+v_lift/a_lift,2*SQRT((E$5)/a_lift)))+t_pos+t_ch) -> 0 | F8: =$C8*F$6*(t_ch+IF(($B8)<=0,0,IF(($B8)>=v_lift^2/a_lift,($B8)/v_lift+v_lift/a_lift,2*SQRT(($B8)/a_lift)))+t_pos+t_I+IF((ABS($B8-F$5))<=0,0,IF((ABS($B8-F$5))>=v_lift^2/a_lift,(ABS($B8-F$5))/v_lift+v_lift/a_lift,2*SQRT((ABS($B8-F$5))/a_lift)))+t_pos+t_I+IF((F$5)<=0,0,IF((F$5)>=v_lift^2/a_lift,(F$5)/v_lift+v_lift/a_lift,2*SQRT((F$5)/a_lift)))+t_pos+t_ch) -> 0 | G8: =$C8*G$6*(t_ch+IF(($B8)<=0,0,IF(($B8)>=v_lift^2/a_lift,($B8)/v_lift+v_lift/a_lift,2*SQRT(($B8)/a_lift)))+t_pos+t_I+IF((ABS($B8-G$5))<=0,0,IF((ABS($B8-G$5))>=v_lift^2/a_lift,(ABS($B8-G$5))/v_lift+v_lift/a_lift,2*SQRT((ABS($B8-G$5))/a_lift)))+t_pos+t_I+IF((G$5)<=0,0,IF((G$5)>=v_lift^2/a_lift,(G$5)/v_lift+v_lift/a_lift,2*SQRT((G$5)/a_lift)))+t_pos+t_ch) -> 0 | H8: =$C8*H$6*(t_ch+IF(($B8)<=0,0,IF(($B8)>=v_lift^2/a_lift,($B8)/v_lift+v_lift/a_lift,2*SQRT(($B8)/a_lift)))+t_pos+t_I+IF((ABS($B8-H$5))<=0,0,IF((ABS($B8-H$5))>=v_lift^2/a_lift,(ABS($B8-H$5))/v_lift+v_lift/a_lift,2*SQRT((ABS($B8-H$5))/a_lift)))+t_pos+t_I+IF((H$5)<=0,0,IF((H$5)>=v_lift^2/a_lift,(H$5)/v_lift+v_lift/a_lift,2*SQRT((H$5)/a_lift)))+t_pos+t_ch) -> 0 | I8: =$C8*I$6*(t_ch+IF(($B8)<=0,0,IF(($B8)>=v_lift^2/a_lift,($B8)/v_lift+v_lift/a_lift,2*SQRT(($B8)/a_lift)))+t_pos+t_I+IF((ABS($B8-I$5))<=0,0,IF((ABS($B8-I$5))>=v_lift^2/a_lift,(ABS($B8-I$5))/v_lift+v_lift/a_lift,2*SQRT((ABS($B8-I$5))/a_lift)))+t_pos+t_I+IF((I$5)<=0,0,IF((I$5)>=v_lift^2/a_lift,(I$5)/v_lift+v_lift/a_lift,2*SQRT((I$5)/a_lift)))+t_pos+t_ch) -> 0 | J8: =$C8*J$6*(t_ch+IF(($B8)<=0,0,IF(($B8)>=v_lift^2/a_lift,($B8)/v_lift+v_lift/a_lift,2*SQRT(($B8)/a_lift)))+t_pos+t_I+IF((ABS($B8-J$5))<=0,0,IF((ABS($B8-J$5))>=v_lift^2/a_lift,(ABS($B8-J$5))/v_lift+v_lift/a_lift,2*SQRT((ABS($B8-J$5))/a_lift)))+t_pos+t_I+IF((J$5)<=0,0,IF((J$5)>=v_lift^2/a_lift,(J$5)/v_lift+v_lift/a_lift,2*SQRT((J$5)/a_lift)))+t_pos+t_ch) -> 0 | K8: =$C8*K$6*(t_ch+IF(($B8)<=0,0,IF(($B8)>=v_lift^2/a_lift,($B8)/v_lift+v_lift/a_lift,2*SQRT(($B8)/a_lift)))+t_pos+t_I+IF((ABS($B8-K$5))<=0,0,IF((ABS($B8-K$5))>=v_lift^2/a_lift,(ABS($B8-K$5))/v_lift+v_lift/a_lift,2*SQRT((ABS($B8-K$5))/a_lift)))+t_pos+t_I+IF((K$5)<=0,0,IF((K$5)>=v_lift^2/a_lift,(K$5)/v_lift+v_lift/a_lift,2*SQRT((K$5)/a_lift)))+t_pos+t_ch) -> 0 | ... W8: =$C8*W$6*(t_ch+IF(($B8)<=0,0,IF(($B8)>=v_lift^2/a_lift,($B8)/v_lift+v_lift/a_lift,2*SQRT(($B8)/a_lift)))+t_pos+t_I+IF((ABS($B8-W$5))<=0,0,IF((ABS($B8-W$5))>=v_lift^2/a_lift,(ABS($B8-W$5))/v_lift+v_lift/a_lift,2*SQRT((ABS($B8-W$5))/a_lift)))+t_pos+t_I+IF((W$5)<=0,0,IF((W$5)>=v_lift^2/a_lift,(W$5)/v_lift+v_lift/a_lift,2*SQRT((W$5)/a_lift)))+t_pos+t_ch) -> 0
A9: 2 | B9: =Tiers!C5 -> 1.85 | C9: =Tiers!I5 -> 0.11111111 | D9: =$C9*D$6*(t_ch+IF(($B9)<=0,0,IF(($B9)>=v_lift^2/a_lift,($B9)/v_lift+v_lift/a_lift,2*SQRT(($B9)/a_lift)))+t_pos+t_I+IF((ABS($B9-D$5))<=0,0,IF((ABS($B9-D$5))>=v_lift^2/a_lift,(ABS($B9-D$5))/v_lift+v_lift/a_lift,2*SQRT((ABS($B9-D$5))/a_lift)))+t_pos+t_I+IF((D$5)<=0,0,IF((D$5)>=v_lift^2/a_lift,(D$5)/v_lift+v_lift/a_lift,2*SQRT((D$5)/a_lift)))+t_pos+t_ch) -> 0 | E9: =$C9*E$6*(t_ch+IF(($B9)<=0,0,IF(($B9)>=v_lift^2/a_lift,($B9)/v_lift+v_lift/a_lift,2*SQRT(($B9)/a_lift)))+t_pos+t_I+IF((ABS($B9-E$5))<=0,0,IF((ABS($B9-E$5))>=v_lift^2/a_lift,(ABS($B9-E$5))/v_lift+v_lift/a_lift,2*SQRT((ABS($B9-E$5))/a_lift)))+t_pos+t_I+IF((E$5)<=0,0,IF((E$5)>=v_lift^2/a_lift,(E$5)/v_lift+v_lift/a_lift,2*SQRT((E$5)/a_lift)))+t_pos+t_ch) -> 0.90811287 | F9: =$C9*F$6*(t_ch+IF(($B9)<=0,0,IF(($B9)>=v_lift^2/a_lift,($B9)/v_lift+v_lift/a_lift,2*SQRT(($B9)/a_lift)))+t_pos+t_I+IF((ABS($B9-F$5))<=0,0,IF((ABS($B9-F$5))>=v_lift^2/a_lift,(ABS($B9-F$5))/v_lift+v_lift/a_lift,2*SQRT((ABS($B9-F$5))/a_lift)))+t_pos+t_I+IF((F$5)<=0,0,IF((F$5)>=v_lift^2/a_lift,(F$5)/v_lift+v_lift/a_lift,2*SQRT((F$5)/a_lift)))+t_pos+t_ch) -> 0.97142857 | G9: =$C9*G$6*(t_ch+IF(($B9)<=0,0,IF(($B9)>=v_lift^2/a_lift,($B9)/v_lift+v_lift/a_lift,2*SQRT(($B9)/a_lift)))+t_pos+t_I+IF((ABS($B9-G$5))<=0,0,IF((ABS($B9-G$5))>=v_lift^2/a_lift,(ABS($B9-G$5))/v_lift+v_lift/a_lift,2*SQRT((ABS($B9-G$5))/a_lift)))+t_pos+t_I+IF((G$5)<=0,0,IF((G$5)>=v_lift^2/a_lift,(G$5)/v_lift+v_lift/a_lift,2*SQRT((G$5)/a_lift)))+t_pos+t_ch) -> 1.0171076 | H9: =$C9*H$6*(t_ch+IF(($B9)<=0,0,IF(($B9)>=v_lift^2/a_lift,($B9)/v_lift+v_lift/a_lift,2*SQRT(($B9)/a_lift)))+t_pos+t_I+IF((ABS($B9-H$5))<=0,0,IF((ABS($B9-H$5))>=v_lift^2/a_lift,(ABS($B9-H$5))/v_lift+v_lift/a_lift,2*SQRT((ABS($B9-H$5))/a_lift)))+t_pos+t_I+IF((H$5)<=0,0,IF((H$5)>=v_lift^2/a_lift,(H$5)/v_lift+v_lift/a_lift,2*SQRT((H$5)/a_lift)))+t_pos+t_ch) -> 1.0627866 | I9: =$C9*I$6*(t_ch+IF(($B9)<=0,0,IF(($B9)>=v_lift^2/a_lift,($B9)/v_lift+v_lift/a_lift,2*SQRT(($B9)/a_lift)))+t_pos+t_I+IF((ABS($B9-I$5))<=0,0,IF((ABS($B9-I$5))>=v_lift^2/a_lift,(ABS($B9-I$5))/v_lift+v_lift/a_lift,2*SQRT((ABS($B9-I$5))/a_lift)))+t_pos+t_I+IF((I$5)<=0,0,IF((I$5)>=v_lift^2/a_lift,(I$5)/v_lift+v_lift/a_lift,2*SQRT((I$5)/a_lift)))+t_pos+t_ch) -> 1.1084656 | J9: =$C9*J$6*(t_ch+IF(($B9)<=0,0,IF(($B9)>=v_lift^2/a_lift,($B9)/v_lift+v_lift/a_lift,2*SQRT(($B9)/a_lift)))+t_pos+t_I+IF((ABS($B9-J$5))<=0,0,IF((ABS($B9-J$5))>=v_lift^2/a_lift,(ABS($B9-J$5))/v_lift+v_lift/a_lift,2*SQRT((ABS($B9-J$5))/a_lift)))+t_pos+t_I+IF((J$5)<=0,0,IF((J$5)>=v_lift^2/a_lift,(J$5)/v_lift+v_lift/a_lift,2*SQRT((J$5)/a_lift)))+t_pos+t_ch) -> 1.1541446 | K9: =$C9*K$6*(t_ch+IF(($B9)<=0,0,IF(($B9)>=v_lift^2/a_lift,($B9)/v_lift+v_lift/a_lift,2*SQRT(($B9)/a_lift)))+t_pos+t_I+IF((ABS($B9-K$5))<=0,0,IF((ABS($B9-K$5))>=v_lift^2/a_lift,(ABS($B9-K$5))/v_lift+v_lift/a_lift,2*SQRT((ABS($B9-K$5))/a_lift)))+t_pos+t_I+IF((K$5)<=0,0,IF((K$5)>=v_lift^2/a_lift,(K$5)/v_lift+v_lift/a_lift,2*SQRT((K$5)/a_lift)))+t_pos+t_ch) -> 1.1998236 | ... W9: =$C9*W$6*(t_ch+IF(($B9)<=0,0,IF(($B9)>=v_lift^2/a_lift,($B9)/v_lift+v_lift/a_lift,2*SQRT(($B9)/a_lift)))+t_pos+t_I+IF((ABS($B9-W$5))<=0,0,IF((ABS($B9-W$5))>=v_lift^2/a_lift,(ABS($B9-W$5))/v_lift+v_lift/a_lift,2*SQRT((ABS($B9-W$5))/a_lift)))+t_pos+t_I+IF((W$5)<=0,0,IF((W$5)>=v_lift^2/a_lift,(W$5)/v_lift+v_lift/a_lift,2*SQRT((W$5)/a_lift)))+t_pos+t_ch) -> 0
A10: 3 | B10: =Tiers!C6 -> 3.7 | C10: =Tiers!I6 -> 0.11111111 | D10: =$C10*D$6*(t_ch+IF(($B10)<=0,0,IF(($B10)>=v_lift^2/a_lift,($B10)/v_lift+v_lift/a_lift,2*SQRT(($B10)/a_lift)))+t_pos+t_I+IF((ABS($B10-D$5))<=0,0,IF((ABS($B10-D$5))>=v_lift^2/a_lift,(ABS($B10-D$5))/v_lift+v_lift/a_lift,2*SQRT((ABS($B10-D$5))/a_lift)))+t_pos+t_I+IF((D$5)<=0,0,IF((D$5)>=v_lift^2/a_lift,(D$5)/v_lift+v_lift/a_lift,2*SQRT((D$5)/a_lift)))+t_pos+t_ch) -> 0 | E10: =$C10*E$6*(t_ch+IF(($B10)<=0,0,IF(($B10)>=v_lift^2/a_lift,($B10)/v_lift+v_lift/a_lift,2*SQRT(($B10)/a_lift)))+t_pos+t_I+IF((ABS($B10-E$5))<=0,0,IF((ABS($B10-E$5))>=v_lift^2/a_lift,(ABS($B10-E$5))/v_lift+v_lift/a_lift,2*SQRT((ABS($B10-E$5))/a_lift)))+t_pos+t_I+IF((E$5)<=0,0,IF((E$5)>=v_lift^2/a_lift,(E$5)/v_lift+v_lift/a_lift,2*SQRT((E$5)/a_lift)))+t_pos+t_ch) -> 0.97142857 | F10: =$C10*F$6*(t_ch+IF(($B10)<=0,0,IF(($B10)>=v_lift^2/a_lift,($B10)/v_lift+v_lift/a_lift,2*SQRT(($B10)/a_lift)))+t_pos+t_I+IF((ABS($B10-F$5))<=0,0,IF((ABS($B10-F$5))>=v_lift^2/a_lift,(ABS($B10-F$5))/v_lift+v_lift/a_lift,2*SQRT((ABS($B10-F$5))/a_lift)))+t_pos+t_I+IF((F$5)<=0,0,IF((F$5)>=v_lift^2/a_lift,(F$5)/v_lift+v_lift/a_lift,2*SQRT((F$5)/a_lift)))+t_pos+t_ch) -> 0.95379189 | G10: =$C10*G$6*(t_ch+IF(($B10)<=0,0,IF(($B10)>=v_lift^2/a_lift,($B10)/v_lift+v_lift/a_lift,2*SQRT(($B10)/a_lift)))+t_pos+t_I+IF((ABS($B10-G$5))<=0,0,IF((ABS($B10-G$5))>=v_lift^2/a_lift,(ABS($B10-G$5))/v_lift+v_lift/a_lift,2*SQRT((ABS($B10-G$5))/a_lift)))+t_pos+t_I+IF((G$5)<=0,0,IF((G$5)>=v_lift^2/a_lift,(G$5)/v_lift+v_lift/a_lift,2*SQRT((G$5)/a_lift)))+t_pos+t_ch) -> 1.0171076 | H10: =$C10*H$6*(t_ch+IF(($B10)<=0,0,IF(($B10)>=v_lift^2/a_lift,($B10)/v_lift+v_lift/a_lift,2*SQRT(($B10)/a_lift)))+t_pos+t_I+IF((ABS($B10-H$5))<=0,0,IF((ABS($B10-H$5))>=v_lift^2/a_lift,(ABS($B10-H$5))/v_lift+v_lift/a_lift,2*SQRT((ABS($B10-H$5))/a_lift)))+t_pos+t_I+IF((H$5)<=0,0,IF((H$5)>=v_lift^2/a_lift,(H$5)/v_lift+v_lift/a_lift,2*SQRT((H$5)/a_lift)))+t_pos+t_ch) -> 1.0627866 | I10: =$C10*I$6*(t_ch+IF(($B10)<=0,0,IF(($B10)>=v_lift^2/a_lift,($B10)/v_lift+v_lift/a_lift,2*SQRT(($B10)/a_lift)))+t_pos+t_I+IF((ABS($B10-I$5))<=0,0,IF((ABS($B10-I$5))>=v_lift^2/a_lift,(ABS($B10-I$5))/v_lift+v_lift/a_lift,2*SQRT((ABS($B10-I$5))/a_lift)))+t_pos+t_I+IF((I$5)<=0,0,IF((I$5)>=v_lift^2/a_lift,(I$5)/v_lift+v_lift/a_lift,2*SQRT((I$5)/a_lift)))+t_pos+t_ch) -> 1.1084656 | J10: =$C10*J$6*(t_ch+IF(($B10)<=0,0,IF(($B10)>=v_lift^2/a_lift,($B10)/v_lift+v_lift/a_lift,2*SQRT(($B10)/a_lift)))+t_pos+t_I+IF((ABS($B10-J$5))<=0,0,IF((ABS($B10-J$5))>=v_lift^2/a_lift,(ABS($B10-J$5))/v_lift+v_lift/a_lift,2*SQRT((ABS($B10-J$5))/a_lift)))+t_pos+t_I+IF((J$5)<=0,0,IF((J$5)>=v_lift^2/a_lift,(J$5)/v_lift+v_lift/a_lift,2*SQRT((J$5)/a_lift)))+t_pos+t_ch) -> 1.1541446 | K10: =$C10*K$6*(t_ch+IF(($B10)<=0,0,IF(($B10)>=v_lift^2/a_lift,($B10)/v_lift+v_lift/a_lift,2*SQRT(($B10)/a_lift)))+t_pos+t_I+IF((ABS($B10-K$5))<=0,0,IF((ABS($B10-K$5))>=v_lift^2/a_lift,(ABS($B10-K$5))/v_lift+v_lift/a_lift,2*SQRT((ABS($B10-K$5))/a_lift)))+t_pos+t_I+IF((K$5)<=0,0,IF((K$5)>=v_lift^2/a_lift,(K$5)/v_lift+v_lift/a_lift,2*SQRT((K$5)/a_lift)))+t_pos+t_ch) -> 1.1998236 | ... W10: =$C10*W$6*(t_ch+IF(($B10)<=0,0,IF(($B10)>=v_lift^2/a_lift,($B10)/v_lift+v_lift/a_lift,2*SQRT(($B10)/a_lift)))+t_pos+t_I+IF((ABS($B10-W$5))<=0,0,IF((ABS($B10-W$5))>=v_lift^2/a_lift,(ABS($B10-W$5))/v_lift+v_lift/a_lift,2*SQRT((ABS($B10-W$5))/a_lift)))+t_pos+t_I+IF((W$5)<=0,0,IF((W$5)>=v_lift^2/a_lift,(W$5)/v_lift+v_lift/a_lift,2*SQRT((W$5)/a_lift)))+t_pos+t_ch) -> 0
A11: 4 | B11: =Tiers!C7 -> 5.55 | C11: =Tiers!I7 -> 0.11111111 | D11: =$C11*D$6*(t_ch+IF(($B11)<=0,0,IF(($B11)>=v_lift^2/a_lift,($B11)/v_lift+v_lift/a_lift,2*SQRT(($B11)/a_lift)))+t_pos+t_I+IF((ABS($B11-D$5))<=0,0,IF((ABS($B11-D$5))>=v_lift^2/a_lift,(ABS($B11-D$5))/v_lift+v_lift/a_lift,2*SQRT((ABS($B11-D$5))/a_lift)))+t_pos+t_I+IF((D$5)<=0,0,IF((D$5)>=v_lift^2/a_lift,(D$5)/v_lift+v_lift/a_lift,2*SQRT((D$5)/a_lift)))+t_pos+t_ch) -> 0 | E11: =$C11*E$6*(t_ch+IF(($B11)<=0,0,IF(($B11)>=v_lift^2/a_lift,($B11)/v_lift+v_lift/a_lift,2*SQRT(($B11)/a_lift)))+t_pos+t_I+IF((ABS($B11-E$5))<=0,0,IF((ABS($B11-E$5))>=v_lift^2/a_lift,(ABS($B11-E$5))/v_lift+v_lift/a_lift,2*SQRT((ABS($B11-E$5))/a_lift)))+t_pos+t_I+IF((E$5)<=0,0,IF((E$5)>=v_lift^2/a_lift,(E$5)/v_lift+v_lift/a_lift,2*SQRT((E$5)/a_lift)))+t_pos+t_ch) -> 1.0171076 | F11: =$C11*F$6*(t_ch+IF(($B11)<=0,0,IF(($B11)>=v_lift^2/a_lift,($B11)/v_lift+v_lift/a_lift,2*SQRT(($B11)/a_lift)))+t_pos+t_I+IF((ABS($B11-F$5))<=0,0,IF((ABS($B11-F$5))>=v_lift^2/a_lift,(ABS($B11-F$5))/v_lift+v_lift/a_lift,2*SQRT((ABS($B11-F$5))/a_lift)))+t_pos+t_I+IF((F$5)<=0,0,IF((F$5)>=v_lift^2/a_lift,(F$5)/v_lift+v_lift/a_lift,2*SQRT((F$5)/a_lift)))+t_pos+t_ch) -> 1.0171076 | G11: =$C11*G$6*(t_ch+IF(($B11)<=0,0,IF(($B11)>=v_lift^2/a_lift,($B11)/v_lift+v_lift/a_lift,2*SQRT(($B11)/a_lift)))+t_pos+t_I+IF((ABS($B11-G$5))<=0,0,IF((ABS($B11-G$5))>=v_lift^2/a_lift,(ABS($B11-G$5))/v_lift+v_lift/a_lift,2*SQRT((ABS($B11-G$5))/a_lift)))+t_pos+t_I+IF((G$5)<=0,0,IF((G$5)>=v_lift^2/a_lift,(G$5)/v_lift+v_lift/a_lift,2*SQRT((G$5)/a_lift)))+t_pos+t_ch) -> 0.9994709 | H11: =$C11*H$6*(t_ch+IF(($B11)<=0,0,IF(($B11)>=v_lift^2/a_lift,($B11)/v_lift+v_lift/a_lift,2*SQRT(($B11)/a_lift)))+t_pos+t_I+IF((ABS($B11-H$5))<=0,0,IF((ABS($B11-H$5))>=v_lift^2/a_lift,(ABS($B11-H$5))/v_lift+v_lift/a_lift,2*SQRT((ABS($B11-H$5))/a_lift)))+t_pos+t_I+IF((H$5)<=0,0,IF((H$5)>=v_lift^2/a_lift,(H$5)/v_lift+v_lift/a_lift,2*SQRT((H$5)/a_lift)))+t_pos+t_ch) -> 1.0627866 | I11: =$C11*I$6*(t_ch+IF(($B11)<=0,0,IF(($B11)>=v_lift^2/a_lift,($B11)/v_lift+v_lift/a_lift,2*SQRT(($B11)/a_lift)))+t_pos+t_I+IF((ABS($B11-I$5))<=0,0,IF((ABS($B11-I$5))>=v_lift^2/a_lift,(ABS($B11-I$5))/v_lift+v_lift/a_lift,2*SQRT((ABS($B11-I$5))/a_lift)))+t_pos+t_I+IF((I$5)<=0,0,IF((I$5)>=v_lift^2/a_lift,(I$5)/v_lift+v_lift/a_lift,2*SQRT((I$5)/a_lift)))+t_pos+t_ch) -> 1.1084656 | J11: =$C11*J$6*(t_ch+IF(($B11)<=0,0,IF(($B11)>=v_lift^2/a_lift,($B11)/v_lift+v_lift/a_lift,2*SQRT(($B11)/a_lift)))+t_pos+t_I+IF((ABS($B11-J$5))<=0,0,IF((ABS($B11-J$5))>=v_lift^2/a_lift,(ABS($B11-J$5))/v_lift+v_lift/a_lift,2*SQRT((ABS($B11-J$5))/a_lift)))+t_pos+t_I+IF((J$5)<=0,0,IF((J$5)>=v_lift^2/a_lift,(J$5)/v_lift+v_lift/a_lift,2*SQRT((J$5)/a_lift)))+t_pos+t_ch) -> 1.1541446 | K11: =$C11*K$6*(t_ch+IF(($B11)<=0,0,IF(($B11)>=v_lift^2/a_lift,($B11)/v_lift+v_lift/a_lift,2*SQRT(($B11)/a_lift)))+t_pos+t_I+IF((ABS($B11-K$5))<=0,0,IF((ABS($B11-K$5))>=v_lift^2/a_lift,(ABS($B11-K$5))/v_lift+v_lift/a_lift,2*SQRT((ABS($B11-K$5))/a_lift)))+t_pos+t_I+IF((K$5)<=0,0,IF((K$5)>=v_lift^2/a_lift,(K$5)/v_lift+v_lift/a_lift,2*SQRT((K$5)/a_lift)))+t_pos+t_ch) -> 1.1998236 | ... W11: =$C11*W$6*(t_ch+IF(($B11)<=0,0,IF(($B11)>=v_lift^2/a_lift,($B11)/v_lift+v_lift/a_lift,2*SQRT(($B11)/a_lift)))+t_pos+t_I+IF((ABS($B11-W$5))<=0,0,IF((ABS($B11-W$5))>=v_lift^2/a_lift,(ABS($B11-W$5))/v_lift+v_lift/a_lift,2*SQRT((ABS($B11-W$5))/a_lift)))+t_pos+t_I+IF((W$5)<=0,0,IF((W$5)>=v_lift^2/a_lift,(W$5)/v_lift+v_lift/a_lift,2*SQRT((W$5)/a_lift)))+t_pos+t_ch) -> 0
A12: 5 | B12: =Tiers!C8 -> 7.4 | C12: =Tiers!I8 -> 0.11111111 | D12: =$C12*D$6*(t_ch+IF(($B12)<=0,0,IF(($B12)>=v_lift^2/a_lift,($B12)/v_lift+v_lift/a_lift,2*SQRT(($B12)/a_lift)))+t_pos+t_I+IF((ABS($B12-D$5))<=0,0,IF((ABS($B12-D$5))>=v_lift^2/a_lift,(ABS($B12-D$5))/v_lift+v_lift/a_lift,2*SQRT((ABS($B12-D$5))/a_lift)))+t_pos+t_I+IF((D$5)<=0,0,IF((D$5)>=v_lift^2/a_lift,(D$5)/v_lift+v_lift/a_lift,2*SQRT((D$5)/a_lift)))+t_pos+t_ch) -> 0 | E12: =$C12*E$6*(t_ch+IF(($B12)<=0,0,IF(($B12)>=v_lift^2/a_lift,($B12)/v_lift+v_lift/a_lift,2*SQRT(($B12)/a_lift)))+t_pos+t_I+IF((ABS($B12-E$5))<=0,0,IF((ABS($B12-E$5))>=v_lift^2/a_lift,(ABS($B12-E$5))/v_lift+v_lift/a_lift,2*SQRT((ABS($B12-E$5))/a_lift)))+t_pos+t_I+IF((E$5)<=0,0,IF((E$5)>=v_lift^2/a_lift,(E$5)/v_lift+v_lift/a_lift,2*SQRT((E$5)/a_lift)))+t_pos+t_ch) -> 1.0627866 | F12: =$C12*F$6*(t_ch+IF(($B12)<=0,0,IF(($B12)>=v_lift^2/a_lift,($B12)/v_lift+v_lift/a_lift,2*SQRT(($B12)/a_lift)))+t_pos+t_I+IF((ABS($B12-F$5))<=0,0,IF((ABS($B12-F$5))>=v_lift^2/a_lift,(ABS($B12-F$5))/v_lift+v_lift/a_lift,2*SQRT((ABS($B12-F$5))/a_lift)))+t_pos+t_I+IF((F$5)<=0,0,IF((F$5)>=v_lift^2/a_lift,(F$5)/v_lift+v_lift/a_lift,2*SQRT((F$5)/a_lift)))+t_pos+t_ch) -> 1.0627866 | G12: =$C12*G$6*(t_ch+IF(($B12)<=0,0,IF(($B12)>=v_lift^2/a_lift,($B12)/v_lift+v_lift/a_lift,2*SQRT(($B12)/a_lift)))+t_pos+t_I+IF((ABS($B12-G$5))<=0,0,IF((ABS($B12-G$5))>=v_lift^2/a_lift,(ABS($B12-G$5))/v_lift+v_lift/a_lift,2*SQRT((ABS($B12-G$5))/a_lift)))+t_pos+t_I+IF((G$5)<=0,0,IF((G$5)>=v_lift^2/a_lift,(G$5)/v_lift+v_lift/a_lift,2*SQRT((G$5)/a_lift)))+t_pos+t_ch) -> 1.0627866 | H12: =$C12*H$6*(t_ch+IF(($B12)<=0,0,IF(($B12)>=v_lift^2/a_lift,($B12)/v_lift+v_lift/a_lift,2*SQRT(($B12)/a_lift)))+t_pos+t_I+IF((ABS($B12-H$5))<=0,0,IF((ABS($B12-H$5))>=v_lift^2/a_lift,(ABS($B12-H$5))/v_lift+v_lift/a_lift,2*SQRT((ABS($B12-H$5))/a_lift)))+t_pos+t_I+IF((H$5)<=0,0,IF((H$5)>=v_lift^2/a_lift,(H$5)/v_lift+v_lift/a_lift,2*SQRT((H$5)/a_lift)))+t_pos+t_ch) -> 1.0451499 | I12: =$C12*I$6*(t_ch+IF(($B12)<=0,0,IF(($B12)>=v_lift^2/a_lift,($B12)/v_lift+v_lift/a_lift,2*SQRT(($B12)/a_lift)))+t_pos+t_I+IF((ABS($B12-I$5))<=0,0,IF((ABS($B12-I$5))>=v_lift^2/a_lift,(ABS($B12-I$5))/v_lift+v_lift/a_lift,2*SQRT((ABS($B12-I$5))/a_lift)))+t_pos+t_I+IF((I$5)<=0,0,IF((I$5)>=v_lift^2/a_lift,(I$5)/v_lift+v_lift/a_lift,2*SQRT((I$5)/a_lift)))+t_pos+t_ch) -> 1.1084656 | J12: =$C12*J$6*(t_ch+IF(($B12)<=0,0,IF(($B12)>=v_lift^2/a_lift,($B12)/v_lift+v_lift/a_lift,2*SQRT(($B12)/a_lift)))+t_pos+t_I+IF((ABS($B12-J$5))<=0,0,IF((ABS($B12-J$5))>=v_lift^2/a_lift,(ABS($B12-J$5))/v_lift+v_lift/a_lift,2*SQRT((ABS($B12-J$5))/a_lift)))+t_pos+t_I+IF((J$5)<=0,0,IF((J$5)>=v_lift^2/a_lift,(J$5)/v_lift+v_lift/a_lift,2*SQRT((J$5)/a_lift)))+t_pos+t_ch) -> 1.1541446 | K12: =$C12*K$6*(t_ch+IF(($B12)<=0,0,IF(($B12)>=v_lift^2/a_lift,($B12)/v_lift+v_lift/a_lift,2*SQRT(($B12)/a_lift)))+t_pos+t_I+IF((ABS($B12-K$5))<=0,0,IF((ABS($B12-K$5))>=v_lift^2/a_lift,(ABS($B12-K$5))/v_lift+v_lift/a_lift,2*SQRT((ABS($B12-K$5))/a_lift)))+t_pos+t_I+IF((K$5)<=0,0,IF((K$5)>=v_lift^2/a_lift,(K$5)/v_lift+v_lift/a_lift,2*SQRT((K$5)/a_lift)))+t_pos+t_ch) -> 1.1998236 | ... W12: =$C12*W$6*(t_ch+IF(($B12)<=0,0,IF(($B12)>=v_lift^2/a_lift,($B12)/v_lift+v_lift/a_lift,2*SQRT(($B12)/a_lift)))+t_pos+t_I+IF((ABS($B12-W$5))<=0,0,IF((ABS($B12-W$5))>=v_lift^2/a_lift,(ABS($B12-W$5))/v_lift+v_lift/a_lift,2*SQRT((ABS($B12-W$5))/a_lift)))+t_pos+t_I+IF((W$5)<=0,0,IF((W$5)>=v_lift^2/a_lift,(W$5)/v_lift+v_lift/a_lift,2*SQRT((W$5)/a_lift)))+t_pos+t_ch) -> 0
A13: 6 | B13: =Tiers!C9 -> 9.25 | C13: =Tiers!I9 -> 0.11111111 | D13: =$C13*D$6*(t_ch+IF(($B13)<=0,0,IF(($B13)>=v_lift^2/a_lift,($B13)/v_lift+v_lift/a_lift,2*SQRT(($B13)/a_lift)))+t_pos+t_I+IF((ABS($B13-D$5))<=0,0,IF((ABS($B13-D$5))>=v_lift^2/a_lift,(ABS($B13-D$5))/v_lift+v_lift/a_lift,2*SQRT((ABS($B13-D$5))/a_lift)))+t_pos+t_I+IF((D$5)<=0,0,IF((D$5)>=v_lift^2/a_lift,(D$5)/v_lift+v_lift/a_lift,2*SQRT((D$5)/a_lift)))+t_pos+t_ch) -> 0 | E13: =$C13*E$6*(t_ch+IF(($B13)<=0,0,IF(($B13)>=v_lift^2/a_lift,($B13)/v_lift+v_lift/a_lift,2*SQRT(($B13)/a_lift)))+t_pos+t_I+IF((ABS($B13-E$5))<=0,0,IF((ABS($B13-E$5))>=v_lift^2/a_lift,(ABS($B13-E$5))/v_lift+v_lift/a_lift,2*SQRT((ABS($B13-E$5))/a_lift)))+t_pos+t_I+IF((E$5)<=0,0,IF((E$5)>=v_lift^2/a_lift,(E$5)/v_lift+v_lift/a_lift,2*SQRT((E$5)/a_lift)))+t_pos+t_ch) -> 1.1084656 | F13: =$C13*F$6*(t_ch+IF(($B13)<=0,0,IF(($B13)>=v_lift^2/a_lift,($B13)/v_lift+v_lift/a_lift,2*SQRT(($B13)/a_lift)))+t_pos+t_I+IF((ABS($B13-F$5))<=0,0,IF((ABS($B13-F$5))>=v_lift^2/a_lift,(ABS($B13-F$5))/v_lift+v_lift/a_lift,2*SQRT((ABS($B13-F$5))/a_lift)))+t_pos+t_I+IF((F$5)<=0,0,IF((F$5)>=v_lift^2/a_lift,(F$5)/v_lift+v_lift/a_lift,2*SQRT((F$5)/a_lift)))+t_pos+t_ch) -> 1.1084656 | G13: =$C13*G$6*(t_ch+IF(($B13)<=0,0,IF(($B13)>=v_lift^2/a_lift,($B13)/v_lift+v_lift/a_lift,2*SQRT(($B13)/a_lift)))+t_pos+t_I+IF((ABS($B13-G$5))<=0,0,IF((ABS($B13-G$5))>=v_lift^2/a_lift,(ABS($B13-G$5))/v_lift+v_lift/a_lift,2*SQRT((ABS($B13-G$5))/a_lift)))+t_pos+t_I+IF((G$5)<=0,0,IF((G$5)>=v_lift^2/a_lift,(G$5)/v_lift+v_lift/a_lift,2*SQRT((G$5)/a_lift)))+t_pos+t_ch) -> 1.1084656 | H13: =$C13*H$6*(t_ch+IF(($B13)<=0,0,IF(($B13)>=v_lift^2/a_lift,($B13)/v_lift+v_lift/a_lift,2*SQRT(($B13)/a_lift)))+t_pos+t_I+IF((ABS($B13-H$5))<=0,0,IF((ABS($B13-H$5))>=v_lift^2/a_lift,(ABS($B13-H$5))/v_lift+v_lift/a_lift,2*SQRT((ABS($B13-H$5))/a_lift)))+t_pos+t_I+IF((H$5)<=0,0,IF((H$5)>=v_lift^2/a_lift,(H$5)/v_lift+v_lift/a_lift,2*SQRT((H$5)/a_lift)))+t_pos+t_ch) -> 1.1084656 | I13: =$C13*I$6*(t_ch+IF(($B13)<=0,0,IF(($B13)>=v_lift^2/a_lift,($B13)/v_lift+v_lift/a_lift,2*SQRT(($B13)/a_lift)))+t_pos+t_I+IF((ABS($B13-I$5))<=0,0,IF((ABS($B13-I$5))>=v_lift^2/a_lift,(ABS($B13-I$5))/v_lift+v_lift/a_lift,2*SQRT((ABS($B13-I$5))/a_lift)))+t_pos+t_I+IF((I$5)<=0,0,IF((I$5)>=v_lift^2/a_lift,(I$5)/v_lift+v_lift/a_lift,2*SQRT((I$5)/a_lift)))+t_pos+t_ch) -> 1.0908289 | J13: =$C13*J$6*(t_ch+IF(($B13)<=0,0,IF(($B13)>=v_lift^2/a_lift,($B13)/v_lift+v_lift/a_lift,2*SQRT(($B13)/a_lift)))+t_pos+t_I+IF((ABS($B13-J$5))<=0,0,IF((ABS($B13-J$5))>=v_lift^2/a_lift,(ABS($B13-J$5))/v_lift+v_lift/a_lift,2*SQRT((ABS($B13-J$5))/a_lift)))+t_pos+t_I+IF((J$5)<=0,0,IF((J$5)>=v_lift^2/a_lift,(J$5)/v_lift+v_lift/a_lift,2*SQRT((J$5)/a_lift)))+t_pos+t_ch) -> 1.1541446 | K13: =$C13*K$6*(t_ch+IF(($B13)<=0,0,IF(($B13)>=v_lift^2/a_lift,($B13)/v_lift+v_lift/a_lift,2*SQRT(($B13)/a_lift)))+t_pos+t_I+IF((ABS($B13-K$5))<=0,0,IF((ABS($B13-K$5))>=v_lift^2/a_lift,(ABS($B13-K$5))/v_lift+v_lift/a_lift,2*SQRT((ABS($B13-K$5))/a_lift)))+t_pos+t_I+IF((K$5)<=0,0,IF((K$5)>=v_lift^2/a_lift,(K$5)/v_lift+v_lift/a_lift,2*SQRT((K$5)/a_lift)))+t_pos+t_ch) -> 1.1998236 | ... W13: =$C13*W$6*(t_ch+IF(($B13)<=0,0,IF(($B13)>=v_lift^2/a_lift,($B13)/v_lift+v_lift/a_lift,2*SQRT(($B13)/a_lift)))+t_pos+t_I+IF((ABS($B13-W$5))<=0,0,IF((ABS($B13-W$5))>=v_lift^2/a_lift,(ABS($B13-W$5))/v_lift+v_lift/a_lift,2*SQRT((ABS($B13-W$5))/a_lift)))+t_pos+t_I+IF((W$5)<=0,0,IF((W$5)>=v_lift^2/a_lift,(W$5)/v_lift+v_lift/a_lift,2*SQRT((W$5)/a_lift)))+t_pos+t_ch) -> 0
A14: 7 | B14: =Tiers!C10 -> 11.1 | C14: =Tiers!I10 -> 0.11111111 | D14: =$C14*D$6*(t_ch+IF(($B14)<=0,0,IF(($B14)>=v_lift^2/a_lift,($B14)/v_lift+v_lift/a_lift,2*SQRT(($B14)/a_lift)))+t_pos+t_I+IF((ABS($B14-D$5))<=0,0,IF((ABS($B14-D$5))>=v_lift^2/a_lift,(ABS($B14-D$5))/v_lift+v_lift/a_lift,2*SQRT((ABS($B14-D$5))/a_lift)))+t_pos+t_I+IF((D$5)<=0,0,IF((D$5)>=v_lift^2/a_lift,(D$5)/v_lift+v_lift/a_lift,2*SQRT((D$5)/a_lift)))+t_pos+t_ch) -> 0 | E14: =$C14*E$6*(t_ch+IF(($B14)<=0,0,IF(($B14)>=v_lift^2/a_lift,($B14)/v_lift+v_lift/a_lift,2*SQRT(($B14)/a_lift)))+t_pos+t_I+IF((ABS($B14-E$5))<=0,0,IF((ABS($B14-E$5))>=v_lift^2/a_lift,(ABS($B14-E$5))/v_lift+v_lift/a_lift,2*SQRT((ABS($B14-E$5))/a_lift)))+t_pos+t_I+IF((E$5)<=0,0,IF((E$5)>=v_lift^2/a_lift,(E$5)/v_lift+v_lift/a_lift,2*SQRT((E$5)/a_lift)))+t_pos+t_ch) -> 1.1541446 | F14: =$C14*F$6*(t_ch+IF(($B14)<=0,0,IF(($B14)>=v_lift^2/a_lift,($B14)/v_lift+v_lift/a_lift,2*SQRT(($B14)/a_lift)))+t_pos+t_I+IF((ABS($B14-F$5))<=0,0,IF((ABS($B14-F$5))>=v_lift^2/a_lift,(ABS($B14-F$5))/v_lift+v_lift/a_lift,2*SQRT((ABS($B14-F$5))/a_lift)))+t_pos+t_I+IF((F$5)<=0,0,IF((F$5)>=v_lift^2/a_lift,(F$5)/v_lift+v_lift/a_lift,2*SQRT((F$5)/a_lift)))+t_pos+t_ch) -> 1.1541446 | G14: =$C14*G$6*(t_ch+IF(($B14)<=0,0,IF(($B14)>=v_lift^2/a_lift,($B14)/v_lift+v_lift/a_lift,2*SQRT(($B14)/a_lift)))+t_pos+t_I+IF((ABS($B14-G$5))<=0,0,IF((ABS($B14-G$5))>=v_lift^2/a_lift,(ABS($B14-G$5))/v_lift+v_lift/a_lift,2*SQRT((ABS($B14-G$5))/a_lift)))+t_pos+t_I+IF((G$5)<=0,0,IF((G$5)>=v_lift^2/a_lift,(G$5)/v_lift+v_lift/a_lift,2*SQRT((G$5)/a_lift)))+t_pos+t_ch) -> 1.1541446 | H14: =$C14*H$6*(t_ch+IF(($B14)<=0,0,IF(($B14)>=v_lift^2/a_lift,($B14)/v_lift+v_lift/a_lift,2*SQRT(($B14)/a_lift)))+t_pos+t_I+IF((ABS($B14-H$5))<=0,0,IF((ABS($B14-H$5))>=v_lift^2/a_lift,(ABS($B14-H$5))/v_lift+v_lift/a_lift,2*SQRT((ABS($B14-H$5))/a_lift)))+t_pos+t_I+IF((H$5)<=0,0,IF((H$5)>=v_lift^2/a_lift,(H$5)/v_lift+v_lift/a_lift,2*SQRT((H$5)/a_lift)))+t_pos+t_ch) -> 1.1541446 | I14: =$C14*I$6*(t_ch+IF(($B14)<=0,0,IF(($B14)>=v_lift^2/a_lift,($B14)/v_lift+v_lift/a_lift,2*SQRT(($B14)/a_lift)))+t_pos+t_I+IF((ABS($B14-I$5))<=0,0,IF((ABS($B14-I$5))>=v_lift^2/a_lift,(ABS($B14-I$5))/v_lift+v_lift/a_lift,2*SQRT((ABS($B14-I$5))/a_lift)))+t_pos+t_I+IF((I$5)<=0,0,IF((I$5)>=v_lift^2/a_lift,(I$5)/v_lift+v_lift/a_lift,2*SQRT((I$5)/a_lift)))+t_pos+t_ch) -> 1.1541446 | J14: =$C14*J$6*(t_ch+IF(($B14)<=0,0,IF(($B14)>=v_lift^2/a_lift,($B14)/v_lift+v_lift/a_lift,2*SQRT(($B14)/a_lift)))+t_pos+t_I+IF((ABS($B14-J$5))<=0,0,IF((ABS($B14-J$5))>=v_lift^2/a_lift,(ABS($B14-J$5))/v_lift+v_lift/a_lift,2*SQRT((ABS($B14-J$5))/a_lift)))+t_pos+t_I+IF((J$5)<=0,0,IF((J$5)>=v_lift^2/a_lift,(J$5)/v_lift+v_lift/a_lift,2*SQRT((J$5)/a_lift)))+t_pos+t_ch) -> 1.1365079 | K14: =$C14*K$6*(t_ch+IF(($B14)<=0,0,IF(($B14)>=v_lift^2/a_lift,($B14)/v_lift+v_lift/a_lift,2*SQRT(($B14)/a_lift)))+t_pos+t_I+IF((ABS($B14-K$5))<=0,0,IF((ABS($B14-K$5))>=v_lift^2/a_lift,(ABS($B14-K$5))/v_lift+v_lift/a_lift,2*SQRT((ABS($B14-K$5))/a_lift)))+t_pos+t_I+IF((K$5)<=0,0,IF((K$5)>=v_lift^2/a_lift,(K$5)/v_lift+v_lift/a_lift,2*SQRT((K$5)/a_lift)))+t_pos+t_ch) -> 1.1998236 | ... W14: =$C14*W$6*(t_ch+IF(($B14)<=0,0,IF(($B14)>=v_lift^2/a_lift,($B14)/v_lift+v_lift/a_lift,2*SQRT(($B14)/a_lift)))+t_pos+t_I+IF((ABS($B14-W$5))<=0,0,IF((ABS($B14-W$5))>=v_lift^2/a_lift,(ABS($B14-W$5))/v_lift+v_lift/a_lift,2*SQRT((ABS($B14-W$5))/a_lift)))+t_pos+t_I+IF((W$5)<=0,0,IF((W$5)>=v_lift^2/a_lift,(W$5)/v_lift+v_lift/a_lift,2*SQRT((W$5)/a_lift)))+t_pos+t_ch) -> 0
A15: 8 | B15: =Tiers!C11 -> 12.95 | C15: =Tiers!I11 -> 0.11111111 | D15: =$C15*D$6*(t_ch+IF(($B15)<=0,0,IF(($B15)>=v_lift^2/a_lift,($B15)/v_lift+v_lift/a_lift,2*SQRT(($B15)/a_lift)))+t_pos+t_I+IF((ABS($B15-D$5))<=0,0,IF((ABS($B15-D$5))>=v_lift^2/a_lift,(ABS($B15-D$5))/v_lift+v_lift/a_lift,2*SQRT((ABS($B15-D$5))/a_lift)))+t_pos+t_I+IF((D$5)<=0,0,IF((D$5)>=v_lift^2/a_lift,(D$5)/v_lift+v_lift/a_lift,2*SQRT((D$5)/a_lift)))+t_pos+t_ch) -> 0 | E15: =$C15*E$6*(t_ch+IF(($B15)<=0,0,IF(($B15)>=v_lift^2/a_lift,($B15)/v_lift+v_lift/a_lift,2*SQRT(($B15)/a_lift)))+t_pos+t_I+IF((ABS($B15-E$5))<=0,0,IF((ABS($B15-E$5))>=v_lift^2/a_lift,(ABS($B15-E$5))/v_lift+v_lift/a_lift,2*SQRT((ABS($B15-E$5))/a_lift)))+t_pos+t_I+IF((E$5)<=0,0,IF((E$5)>=v_lift^2/a_lift,(E$5)/v_lift+v_lift/a_lift,2*SQRT((E$5)/a_lift)))+t_pos+t_ch) -> 1.1998236 | F15: =$C15*F$6*(t_ch+IF(($B15)<=0,0,IF(($B15)>=v_lift^2/a_lift,($B15)/v_lift+v_lift/a_lift,2*SQRT(($B15)/a_lift)))+t_pos+t_I+IF((ABS($B15-F$5))<=0,0,IF((ABS($B15-F$5))>=v_lift^2/a_lift,(ABS($B15-F$5))/v_lift+v_lift/a_lift,2*SQRT((ABS($B15-F$5))/a_lift)))+t_pos+t_I+IF((F$5)<=0,0,IF((F$5)>=v_lift^2/a_lift,(F$5)/v_lift+v_lift/a_lift,2*SQRT((F$5)/a_lift)))+t_pos+t_ch) -> 1.1998236 | G15: =$C15*G$6*(t_ch+IF(($B15)<=0,0,IF(($B15)>=v_lift^2/a_lift,($B15)/v_lift+v_lift/a_lift,2*SQRT(($B15)/a_lift)))+t_pos+t_I+IF((ABS($B15-G$5))<=0,0,IF((ABS($B15-G$5))>=v_lift^2/a_lift,(ABS($B15-G$5))/v_lift+v_lift/a_lift,2*SQRT((ABS($B15-G$5))/a_lift)))+t_pos+t_I+IF((G$5)<=0,0,IF((G$5)>=v_lift^2/a_lift,(G$5)/v_lift+v_lift/a_lift,2*SQRT((G$5)/a_lift)))+t_pos+t_ch) -> 1.1998236 | H15: =$C15*H$6*(t_ch+IF(($B15)<=0,0,IF(($B15)>=v_lift^2/a_lift,($B15)/v_lift+v_lift/a_lift,2*SQRT(($B15)/a_lift)))+t_pos+t_I+IF((ABS($B15-H$5))<=0,0,IF((ABS($B15-H$5))>=v_lift^2/a_lift,(ABS($B15-H$5))/v_lift+v_lift/a_lift,2*SQRT((ABS($B15-H$5))/a_lift)))+t_pos+t_I+IF((H$5)<=0,0,IF((H$5)>=v_lift^2/a_lift,(H$5)/v_lift+v_lift/a_lift,2*SQRT((H$5)/a_lift)))+t_pos+t_ch) -> 1.1998236 | I15: =$C15*I$6*(t_ch+IF(($B15)<=0,0,IF(($B15)>=v_lift^2/a_lift,($B15)/v_lift+v_lift/a_lift,2*SQRT(($B15)/a_lift)))+t_pos+t_I+IF((ABS($B15-I$5))<=0,0,IF((ABS($B15-I$5))>=v_lift^2/a_lift,(ABS($B15-I$5))/v_lift+v_lift/a_lift,2*SQRT((ABS($B15-I$5))/a_lift)))+t_pos+t_I+IF((I$5)<=0,0,IF((I$5)>=v_lift^2/a_lift,(I$5)/v_lift+v_lift/a_lift,2*SQRT((I$5)/a_lift)))+t_pos+t_ch) -> 1.1998236 | J15: =$C15*J$6*(t_ch+IF(($B15)<=0,0,IF(($B15)>=v_lift^2/a_lift,($B15)/v_lift+v_lift/a_lift,2*SQRT(($B15)/a_lift)))+t_pos+t_I+IF((ABS($B15-J$5))<=0,0,IF((ABS($B15-J$5))>=v_lift^2/a_lift,(ABS($B15-J$5))/v_lift+v_lift/a_lift,2*SQRT((ABS($B15-J$5))/a_lift)))+t_pos+t_I+IF((J$5)<=0,0,IF((J$5)>=v_lift^2/a_lift,(J$5)/v_lift+v_lift/a_lift,2*SQRT((J$5)/a_lift)))+t_pos+t_ch) -> 1.1998236 | K15: =$C15*K$6*(t_ch+IF(($B15)<=0,0,IF(($B15)>=v_lift^2/a_lift,($B15)/v_lift+v_lift/a_lift,2*SQRT(($B15)/a_lift)))+t_pos+t_I+IF((ABS($B15-K$5))<=0,0,IF((ABS($B15-K$5))>=v_lift^2/a_lift,(ABS($B15-K$5))/v_lift+v_lift/a_lift,2*SQRT((ABS($B15-K$5))/a_lift)))+t_pos+t_I+IF((K$5)<=0,0,IF((K$5)>=v_lift^2/a_lift,(K$5)/v_lift+v_lift/a_lift,2*SQRT((K$5)/a_lift)))+t_pos+t_ch) -> 1.1821869 | ... W15: =$C15*W$6*(t_ch+IF(($B15)<=0,0,IF(($B15)>=v_lift^2/a_lift,($B15)/v_lift+v_lift/a_lift,2*SQRT(($B15)/a_lift)))+t_pos+t_I+IF((ABS($B15-W$5))<=0,0,IF((ABS($B15-W$5))>=v_lift^2/a_lift,(ABS($B15-W$5))/v_lift+v_lift/a_lift,2*SQRT((ABS($B15-W$5))/a_lift)))+t_pos+t_I+IF((W$5)<=0,0,IF((W$5)>=v_lift^2/a_lift,(W$5)/v_lift+v_lift/a_lift,2*SQRT((W$5)/a_lift)))+t_pos+t_ch) -> 0
A16: 9 | B16: =Tiers!C12 -> 14.8 | C16: =Tiers!I12 -> 0.11111111 | D16: =$C16*D$6*(t_ch+IF(($B16)<=0,0,IF(($B16)>=v_lift^2/a_lift,($B16)/v_lift+v_lift/a_lift,2*SQRT(($B16)/a_lift)))+t_pos+t_I+IF((ABS($B16-D$5))<=0,0,IF((ABS($B16-D$5))>=v_lift^2/a_lift,(ABS($B16-D$5))/v_lift+v_lift/a_lift,2*SQRT((ABS($B16-D$5))/a_lift)))+t_pos+t_I+IF((D$5)<=0,0,IF((D$5)>=v_lift^2/a_lift,(D$5)/v_lift+v_lift/a_lift,2*SQRT((D$5)/a_lift)))+t_pos+t_ch) -> 0 | E16: =$C16*E$6*(t_ch+IF(($B16)<=0,0,IF(($B16)>=v_lift^2/a_lift,($B16)/v_lift+v_lift/a_lift,2*SQRT(($B16)/a_lift)))+t_pos+t_I+IF((ABS($B16-E$5))<=0,0,IF((ABS($B16-E$5))>=v_lift^2/a_lift,(ABS($B16-E$5))/v_lift+v_lift/a_lift,2*SQRT((ABS($B16-E$5))/a_lift)))+t_pos+t_I+IF((E$5)<=0,0,IF((E$5)>=v_lift^2/a_lift,(E$5)/v_lift+v_lift/a_lift,2*SQRT((E$5)/a_lift)))+t_pos+t_ch) -> 1.2455026 | F16: =$C16*F$6*(t_ch+IF(($B16)<=0,0,IF(($B16)>=v_lift^2/a_lift,($B16)/v_lift+v_lift/a_lift,2*SQRT(($B16)/a_lift)))+t_pos+t_I+IF((ABS($B16-F$5))<=0,0,IF((ABS($B16-F$5))>=v_lift^2/a_lift,(ABS($B16-F$5))/v_lift+v_lift/a_lift,2*SQRT((ABS($B16-F$5))/a_lift)))+t_pos+t_I+IF((F$5)<=0,0,IF((F$5)>=v_lift^2/a_lift,(F$5)/v_lift+v_lift/a_lift,2*SQRT((F$5)/a_lift)))+t_pos+t_ch) -> 1.2455026 | G16: =$C16*G$6*(t_ch+IF(($B16)<=0,0,IF(($B16)>=v_lift^2/a_lift,($B16)/v_lift+v_lift/a_lift,2*SQRT(($B16)/a_lift)))+t_pos+t_I+IF((ABS($B16-G$5))<=0,0,IF((ABS($B16-G$5))>=v_lift^2/a_lift,(ABS($B16-G$5))/v_lift+v_lift/a_lift,2*SQRT((ABS($B16-G$5))/a_lift)))+t_pos+t_I+IF((G$5)<=0,0,IF((G$5)>=v_lift^2/a_lift,(G$5)/v_lift+v_lift/a_lift,2*SQRT((G$5)/a_lift)))+t_pos+t_ch) -> 1.2455026 | H16: =$C16*H$6*(t_ch+IF(($B16)<=0,0,IF(($B16)>=v_lift^2/a_lift,($B16)/v_lift+v_lift/a_lift,2*SQRT(($B16)/a_lift)))+t_pos+t_I+IF((ABS($B16-H$5))<=0,0,IF((ABS($B16-H$5))>=v_lift^2/a_lift,(ABS($B16-H$5))/v_lift+v_lift/a_lift,2*SQRT((ABS($B16-H$5))/a_lift)))+t_pos+t_I+IF((H$5)<=0,0,IF((H$5)>=v_lift^2/a_lift,(H$5)/v_lift+v_lift/a_lift,2*SQRT((H$5)/a_lift)))+t_pos+t_ch) -> 1.2455026 | I16: =$C16*I$6*(t_ch+IF(($B16)<=0,0,IF(($B16)>=v_lift^2/a_lift,($B16)/v_lift+v_lift/a_lift,2*SQRT(($B16)/a_lift)))+t_pos+t_I+IF((ABS($B16-I$5))<=0,0,IF((ABS($B16-I$5))>=v_lift^2/a_lift,(ABS($B16-I$5))/v_lift+v_lift/a_lift,2*SQRT((ABS($B16-I$5))/a_lift)))+t_pos+t_I+IF((I$5)<=0,0,IF((I$5)>=v_lift^2/a_lift,(I$5)/v_lift+v_lift/a_lift,2*SQRT((I$5)/a_lift)))+t_pos+t_ch) -> 1.2455026 | J16: =$C16*J$6*(t_ch+IF(($B16)<=0,0,IF(($B16)>=v_lift^2/a_lift,($B16)/v_lift+v_lift/a_lift,2*SQRT(($B16)/a_lift)))+t_pos+t_I+IF((ABS($B16-J$5))<=0,0,IF((ABS($B16-J$5))>=v_lift^2/a_lift,(ABS($B16-J$5))/v_lift+v_lift/a_lift,2*SQRT((ABS($B16-J$5))/a_lift)))+t_pos+t_I+IF((J$5)<=0,0,IF((J$5)>=v_lift^2/a_lift,(J$5)/v_lift+v_lift/a_lift,2*SQRT((J$5)/a_lift)))+t_pos+t_ch) -> 1.2455026 | K16: =$C16*K$6*(t_ch+IF(($B16)<=0,0,IF(($B16)>=v_lift^2/a_lift,($B16)/v_lift+v_lift/a_lift,2*SQRT(($B16)/a_lift)))+t_pos+t_I+IF((ABS($B16-K$5))<=0,0,IF((ABS($B16-K$5))>=v_lift^2/a_lift,(ABS($B16-K$5))/v_lift+v_lift/a_lift,2*SQRT((ABS($B16-K$5))/a_lift)))+t_pos+t_I+IF((K$5)<=0,0,IF((K$5)>=v_lift^2/a_lift,(K$5)/v_lift+v_lift/a_lift,2*SQRT((K$5)/a_lift)))+t_pos+t_ch) -> 1.2455026 | ... W16: =$C16*W$6*(t_ch+IF(($B16)<=0,0,IF(($B16)>=v_lift^2/a_lift,($B16)/v_lift+v_lift/a_lift,2*SQRT(($B16)/a_lift)))+t_pos+t_I+IF((ABS($B16-W$5))<=0,0,IF((ABS($B16-W$5))>=v_lift^2/a_lift,(ABS($B16-W$5))/v_lift+v_lift/a_lift,2*SQRT((ABS($B16-W$5))/a_lift)))+t_pos+t_I+IF((W$5)<=0,0,IF((W$5)>=v_lift^2/a_lift,(W$5)/v_lift+v_lift/a_lift,2*SQRT((W$5)/a_lift)))+t_pos+t_ch) -> 0
A17: 10 | B17: =Tiers!C13 -> 16.65 | C17: =Tiers!I13 -> 0.11111111 | D17: =$C17*D$6*(t_ch+IF(($B17)<=0,0,IF(($B17)>=v_lift^2/a_lift,($B17)/v_lift+v_lift/a_lift,2*SQRT(($B17)/a_lift)))+t_pos+t_I+IF((ABS($B17-D$5))<=0,0,IF((ABS($B17-D$5))>=v_lift^2/a_lift,(ABS($B17-D$5))/v_lift+v_lift/a_lift,2*SQRT((ABS($B17-D$5))/a_lift)))+t_pos+t_I+IF((D$5)<=0,0,IF((D$5)>=v_lift^2/a_lift,(D$5)/v_lift+v_lift/a_lift,2*SQRT((D$5)/a_lift)))+t_pos+t_ch) -> 0 | E17: =$C17*E$6*(t_ch+IF(($B17)<=0,0,IF(($B17)>=v_lift^2/a_lift,($B17)/v_lift+v_lift/a_lift,2*SQRT(($B17)/a_lift)))+t_pos+t_I+IF((ABS($B17-E$5))<=0,0,IF((ABS($B17-E$5))>=v_lift^2/a_lift,(ABS($B17-E$5))/v_lift+v_lift/a_lift,2*SQRT((ABS($B17-E$5))/a_lift)))+t_pos+t_I+IF((E$5)<=0,0,IF((E$5)>=v_lift^2/a_lift,(E$5)/v_lift+v_lift/a_lift,2*SQRT((E$5)/a_lift)))+t_pos+t_ch) -> 1.2911817 | F17: =$C17*F$6*(t_ch+IF(($B17)<=0,0,IF(($B17)>=v_lift^2/a_lift,($B17)/v_lift+v_lift/a_lift,2*SQRT(($B17)/a_lift)))+t_pos+t_I+IF((ABS($B17-F$5))<=0,0,IF((ABS($B17-F$5))>=v_lift^2/a_lift,(ABS($B17-F$5))/v_lift+v_lift/a_lift,2*SQRT((ABS($B17-F$5))/a_lift)))+t_pos+t_I+IF((F$5)<=0,0,IF((F$5)>=v_lift^2/a_lift,(F$5)/v_lift+v_lift/a_lift,2*SQRT((F$5)/a_lift)))+t_pos+t_ch) -> 1.2911817 | G17: =$C17*G$6*(t_ch+IF(($B17)<=0,0,IF(($B17)>=v_lift^2/a_lift,($B17)/v_lift+v_lift/a_lift,2*SQRT(($B17)/a_lift)))+t_pos+t_I+IF((ABS($B17-G$5))<=0,0,IF((ABS($B17-G$5))>=v_lift^2/a_lift,(ABS($B17-G$5))/v_lift+v_lift/a_lift,2*SQRT((ABS($B17-G$5))/a_lift)))+t_pos+t_I+IF((G$5)<=0,0,IF((G$5)>=v_lift^2/a_lift,(G$5)/v_lift+v_lift/a_lift,2*SQRT((G$5)/a_lift)))+t_pos+t_ch) -> 1.2911817 | H17: =$C17*H$6*(t_ch+IF(($B17)<=0,0,IF(($B17)>=v_lift^2/a_lift,($B17)/v_lift+v_lift/a_lift,2*SQRT(($B17)/a_lift)))+t_pos+t_I+IF((ABS($B17-H$5))<=0,0,IF((ABS($B17-H$5))>=v_lift^2/a_lift,(ABS($B17-H$5))/v_lift+v_lift/a_lift,2*SQRT((ABS($B17-H$5))/a_lift)))+t_pos+t_I+IF((H$5)<=0,0,IF((H$5)>=v_lift^2/a_lift,(H$5)/v_lift+v_lift/a_lift,2*SQRT((H$5)/a_lift)))+t_pos+t_ch) -> 1.2911817 | I17: =$C17*I$6*(t_ch+IF(($B17)<=0,0,IF(($B17)>=v_lift^2/a_lift,($B17)/v_lift+v_lift/a_lift,2*SQRT(($B17)/a_lift)))+t_pos+t_I+IF((ABS($B17-I$5))<=0,0,IF((ABS($B17-I$5))>=v_lift^2/a_lift,(ABS($B17-I$5))/v_lift+v_lift/a_lift,2*SQRT((ABS($B17-I$5))/a_lift)))+t_pos+t_I+IF((I$5)<=0,0,IF((I$5)>=v_lift^2/a_lift,(I$5)/v_lift+v_lift/a_lift,2*SQRT((I$5)/a_lift)))+t_pos+t_ch) -> 1.2911817 | J17: =$C17*J$6*(t_ch+IF(($B17)<=0,0,IF(($B17)>=v_lift^2/a_lift,($B17)/v_lift+v_lift/a_lift,2*SQRT(($B17)/a_lift)))+t_pos+t_I+IF((ABS($B17-J$5))<=0,0,IF((ABS($B17-J$5))>=v_lift^2/a_lift,(ABS($B17-J$5))/v_lift+v_lift/a_lift,2*SQRT((ABS($B17-J$5))/a_lift)))+t_pos+t_I+IF((J$5)<=0,0,IF((J$5)>=v_lift^2/a_lift,(J$5)/v_lift+v_lift/a_lift,2*SQRT((J$5)/a_lift)))+t_pos+t_ch) -> 1.2911817 | K17: =$C17*K$6*(t_ch+IF(($B17)<=0,0,IF(($B17)>=v_lift^2/a_lift,($B17)/v_lift+v_lift/a_lift,2*SQRT(($B17)/a_lift)))+t_pos+t_I+IF((ABS($B17-K$5))<=0,0,IF((ABS($B17-K$5))>=v_lift^2/a_lift,(ABS($B17-K$5))/v_lift+v_lift/a_lift,2*SQRT((ABS($B17-K$5))/a_lift)))+t_pos+t_I+IF((K$5)<=0,0,IF((K$5)>=v_lift^2/a_lift,(K$5)/v_lift+v_lift/a_lift,2*SQRT((K$5)/a_lift)))+t_pos+t_ch) -> 1.2911817 | ... W17: =$C17*W$6*(t_ch+IF(($B17)<=0,0,IF(($B17)>=v_lift^2/a_lift,($B17)/v_lift+v_lift/a_lift,2*SQRT(($B17)/a_lift)))+t_pos+t_I+IF((ABS($B17-W$5))<=0,0,IF((ABS($B17-W$5))>=v_lift^2/a_lift,(ABS($B17-W$5))/v_lift+v_lift/a_lift,2*SQRT((ABS($B17-W$5))/a_lift)))+t_pos+t_I+IF((W$5)<=0,0,IF((W$5)>=v_lift^2/a_lift,(W$5)/v_lift+v_lift/a_lift,2*SQRT((W$5)/a_lift)))+t_pos+t_ch) -> 0
A18: 11 | B18: =Tiers!C14 -> 0 | C18: =Tiers!I14 -> 0 | D18: =$C18*D$6*(t_ch+IF(($B18)<=0,0,IF(($B18)>=v_lift^2/a_lift,($B18)/v_lift+v_lift/a_lift,2*SQRT(($B18)/a_lift)))+t_pos+t_I+IF((ABS($B18-D$5))<=0,0,IF((ABS($B18-D$5))>=v_lift^2/a_lift,(ABS($B18-D$5))/v_lift+v_lift/a_lift,2*SQRT((ABS($B18-D$5))/a_lift)))+t_pos+t_I+IF((D$5)<=0,0,IF((D$5)>=v_lift^2/a_lift,(D$5)/v_lift+v_lift/a_lift,2*SQRT((D$5)/a_lift)))+t_pos+t_ch) -> 0 | E18: =$C18*E$6*(t_ch+IF(($B18)<=0,0,IF(($B18)>=v_lift^2/a_lift,($B18)/v_lift+v_lift/a_lift,2*SQRT(($B18)/a_lift)))+t_pos+t_I+IF((ABS($B18-E$5))<=0,0,IF((ABS($B18-E$5))>=v_lift^2/a_lift,(ABS($B18-E$5))/v_lift+v_lift/a_lift,2*SQRT((ABS($B18-E$5))/a_lift)))+t_pos+t_I+IF((E$5)<=0,0,IF((E$5)>=v_lift^2/a_lift,(E$5)/v_lift+v_lift/a_lift,2*SQRT((E$5)/a_lift)))+t_pos+t_ch) -> 0 | F18: =$C18*F$6*(t_ch+IF(($B18)<=0,0,IF(($B18)>=v_lift^2/a_lift,($B18)/v_lift+v_lift/a_lift,2*SQRT(($B18)/a_lift)))+t_pos+t_I+IF((ABS($B18-F$5))<=0,0,IF((ABS($B18-F$5))>=v_lift^2/a_lift,(ABS($B18-F$5))/v_lift+v_lift/a_lift,2*SQRT((ABS($B18-F$5))/a_lift)))+t_pos+t_I+IF((F$5)<=0,0,IF((F$5)>=v_lift^2/a_lift,(F$5)/v_lift+v_lift/a_lift,2*SQRT((F$5)/a_lift)))+t_pos+t_ch) -> 0 | G18: =$C18*G$6*(t_ch+IF(($B18)<=0,0,IF(($B18)>=v_lift^2/a_lift,($B18)/v_lift+v_lift/a_lift,2*SQRT(($B18)/a_lift)))+t_pos+t_I+IF((ABS($B18-G$5))<=0,0,IF((ABS($B18-G$5))>=v_lift^2/a_lift,(ABS($B18-G$5))/v_lift+v_lift/a_lift,2*SQRT((ABS($B18-G$5))/a_lift)))+t_pos+t_I+IF((G$5)<=0,0,IF((G$5)>=v_lift^2/a_lift,(G$5)/v_lift+v_lift/a_lift,2*SQRT((G$5)/a_lift)))+t_pos+t_ch) -> 0 | H18: =$C18*H$6*(t_ch+IF(($B18)<=0,0,IF(($B18)>=v_lift^2/a_lift,($B18)/v_lift+v_lift/a_lift,2*SQRT(($B18)/a_lift)))+t_pos+t_I+IF((ABS($B18-H$5))<=0,0,IF((ABS($B18-H$5))>=v_lift^2/a_lift,(ABS($B18-H$5))/v_lift+v_lift/a_lift,2*SQRT((ABS($B18-H$5))/a_lift)))+t_pos+t_I+IF((H$5)<=0,0,IF((H$5)>=v_lift^2/a_lift,(H$5)/v_lift+v_lift/a_lift,2*SQRT((H$5)/a_lift)))+t_pos+t_ch) -> 0 | I18: =$C18*I$6*(t_ch+IF(($B18)<=0,0,IF(($B18)>=v_lift^2/a_lift,($B18)/v_lift+v_lift/a_lift,2*SQRT(($B18)/a_lift)))+t_pos+t_I+IF((ABS($B18-I$5))<=0,0,IF((ABS($B18-I$5))>=v_lift^2/a_lift,(ABS($B18-I$5))/v_lift+v_lift/a_lift,2*SQRT((ABS($B18-I$5))/a_lift)))+t_pos+t_I+IF((I$5)<=0,0,IF((I$5)>=v_lift^2/a_lift,(I$5)/v_lift+v_lift/a_lift,2*SQRT((I$5)/a_lift)))+t_pos+t_ch) -> 0 | J18: =$C18*J$6*(t_ch+IF(($B18)<=0,0,IF(($B18)>=v_lift^2/a_lift,($B18)/v_lift+v_lift/a_lift,2*SQRT(($B18)/a_lift)))+t_pos+t_I+IF((ABS($B18-J$5))<=0,0,IF((ABS($B18-J$5))>=v_lift^2/a_lift,(ABS($B18-J$5))/v_lift+v_lift/a_lift,2*SQRT((ABS($B18-J$5))/a_lift)))+t_pos+t_I+IF((J$5)<=0,0,IF((J$5)>=v_lift^2/a_lift,(J$5)/v_lift+v_lift/a_lift,2*SQRT((J$5)/a_lift)))+t_pos+t_ch) -> 0 | K18: =$C18*K$6*(t_ch+IF(($B18)<=0,0,IF(($B18)>=v_lift^2/a_lift,($B18)/v_lift+v_lift/a_lift,2*SQRT(($B18)/a_lift)))+t_pos+t_I+IF((ABS($B18-K$5))<=0,0,IF((ABS($B18-K$5))>=v_lift^2/a_lift,(ABS($B18-K$5))/v_lift+v_lift/a_lift,2*SQRT((ABS($B18-K$5))/a_lift)))+t_pos+t_I+IF((K$5)<=0,0,IF((K$5)>=v_lift^2/a_lift,(K$5)/v_lift+v_lift/a_lift,2*SQRT((K$5)/a_lift)))+t_pos+t_ch) -> 0 | ... W18: =$C18*W$6*(t_ch+IF(($B18)<=0,0,IF(($B18)>=v_lift^2/a_lift,($B18)/v_lift+v_lift/a_lift,2*SQRT(($B18)/a_lift)))+t_pos+t_I+IF((ABS($B18-W$5))<=0,0,IF((ABS($B18-W$5))>=v_lift^2/a_lift,(ABS($B18-W$5))/v_lift+v_lift/a_lift,2*SQRT((ABS($B18-W$5))/a_lift)))+t_pos+t_I+IF((W$5)<=0,0,IF((W$5)>=v_lift^2/a_lift,(W$5)/v_lift+v_lift/a_lift,2*SQRT((W$5)/a_lift)))+t_pos+t_ch) -> 0
A19: 12 | B19: =Tiers!C15 -> 0 | C19: =Tiers!I15 -> 0 | D19: =$C19*D$6*(t_ch+IF(($B19)<=0,0,IF(($B19)>=v_lift^2/a_lift,($B19)/v_lift+v_lift/a_lift,2*SQRT(($B19)/a_lift)))+t_pos+t_I+IF((ABS($B19-D$5))<=0,0,IF((ABS($B19-D$5))>=v_lift^2/a_lift,(ABS($B19-D$5))/v_lift+v_lift/a_lift,2*SQRT((ABS($B19-D$5))/a_lift)))+t_pos+t_I+IF((D$5)<=0,0,IF((D$5)>=v_lift^2/a_lift,(D$5)/v_lift+v_lift/a_lift,2*SQRT((D$5)/a_lift)))+t_pos+t_ch) -> 0 | E19: =$C19*E$6*(t_ch+IF(($B19)<=0,0,IF(($B19)>=v_lift^2/a_lift,($B19)/v_lift+v_lift/a_lift,2*SQRT(($B19)/a_lift)))+t_pos+t_I+IF((ABS($B19-E$5))<=0,0,IF((ABS($B19-E$5))>=v_lift^2/a_lift,(ABS($B19-E$5))/v_lift+v_lift/a_lift,2*SQRT((ABS($B19-E$5))/a_lift)))+t_pos+t_I+IF((E$5)<=0,0,IF((E$5)>=v_lift^2/a_lift,(E$5)/v_lift+v_lift/a_lift,2*SQRT((E$5)/a_lift)))+t_pos+t_ch) -> 0 | F19: =$C19*F$6*(t_ch+IF(($B19)<=0,0,IF(($B19)>=v_lift^2/a_lift,($B19)/v_lift+v_lift/a_lift,2*SQRT(($B19)/a_lift)))+t_pos+t_I+IF((ABS($B19-F$5))<=0,0,IF((ABS($B19-F$5))>=v_lift^2/a_lift,(ABS($B19-F$5))/v_lift+v_lift/a_lift,2*SQRT((ABS($B19-F$5))/a_lift)))+t_pos+t_I+IF((F$5)<=0,0,IF((F$5)>=v_lift^2/a_lift,(F$5)/v_lift+v_lift/a_lift,2*SQRT((F$5)/a_lift)))+t_pos+t_ch) -> 0 | G19: =$C19*G$6*(t_ch+IF(($B19)<=0,0,IF(($B19)>=v_lift^2/a_lift,($B19)/v_lift+v_lift/a_lift,2*SQRT(($B19)/a_lift)))+t_pos+t_I+IF((ABS($B19-G$5))<=0,0,IF((ABS($B19-G$5))>=v_lift^2/a_lift,(ABS($B19-G$5))/v_lift+v_lift/a_lift,2*SQRT((ABS($B19-G$5))/a_lift)))+t_pos+t_I+IF((G$5)<=0,0,IF((G$5)>=v_lift^2/a_lift,(G$5)/v_lift+v_lift/a_lift,2*SQRT((G$5)/a_lift)))+t_pos+t_ch) -> 0 | H19: =$C19*H$6*(t_ch+IF(($B19)<=0,0,IF(($B19)>=v_lift^2/a_lift,($B19)/v_lift+v_lift/a_lift,2*SQRT(($B19)/a_lift)))+t_pos+t_I+IF((ABS($B19-H$5))<=0,0,IF((ABS($B19-H$5))>=v_lift^2/a_lift,(ABS($B19-H$5))/v_lift+v_lift/a_lift,2*SQRT((ABS($B19-H$5))/a_lift)))+t_pos+t_I+IF((H$5)<=0,0,IF((H$5)>=v_lift^2/a_lift,(H$5)/v_lift+v_lift/a_lift,2*SQRT((H$5)/a_lift)))+t_pos+t_ch) -> 0 | I19: =$C19*I$6*(t_ch+IF(($B19)<=0,0,IF(($B19)>=v_lift^2/a_lift,($B19)/v_lift+v_lift/a_lift,2*SQRT(($B19)/a_lift)))+t_pos+t_I+IF((ABS($B19-I$5))<=0,0,IF((ABS($B19-I$5))>=v_lift^2/a_lift,(ABS($B19-I$5))/v_lift+v_lift/a_lift,2*SQRT((ABS($B19-I$5))/a_lift)))+t_pos+t_I+IF((I$5)<=0,0,IF((I$5)>=v_lift^2/a_lift,(I$5)/v_lift+v_lift/a_lift,2*SQRT((I$5)/a_lift)))+t_pos+t_ch) -> 0 | J19: =$C19*J$6*(t_ch+IF(($B19)<=0,0,IF(($B19)>=v_lift^2/a_lift,($B19)/v_lift+v_lift/a_lift,2*SQRT(($B19)/a_lift)))+t_pos+t_I+IF((ABS($B19-J$5))<=0,0,IF((ABS($B19-J$5))>=v_lift^2/a_lift,(ABS($B19-J$5))/v_lift+v_lift/a_lift,2*SQRT((ABS($B19-J$5))/a_lift)))+t_pos+t_I+IF((J$5)<=0,0,IF((J$5)>=v_lift^2/a_lift,(J$5)/v_lift+v_lift/a_lift,2*SQRT((J$5)/a_lift)))+t_pos+t_ch) -> 0 | K19: =$C19*K$6*(t_ch+IF(($B19)<=0,0,IF(($B19)>=v_lift^2/a_lift,($B19)/v_lift+v_lift/a_lift,2*SQRT(($B19)/a_lift)))+t_pos+t_I+IF((ABS($B19-K$5))<=0,0,IF((ABS($B19-K$5))>=v_lift^2/a_lift,(ABS($B19-K$5))/v_lift+v_lift/a_lift,2*SQRT((ABS($B19-K$5))/a_lift)))+t_pos+t_I+IF((K$5)<=0,0,IF((K$5)>=v_lift^2/a_lift,(K$5)/v_lift+v_lift/a_lift,2*SQRT((K$5)/a_lift)))+t_pos+t_ch) -> 0 | ... W19: =$C19*W$6*(t_ch+IF(($B19)<=0,0,IF(($B19)>=v_lift^2/a_lift,($B19)/v_lift+v_lift/a_lift,2*SQRT(($B19)/a_lift)))+t_pos+t_I+IF((ABS($B19-W$5))<=0,0,IF((ABS($B19-W$5))>=v_lift^2/a_lift,(ABS($B19-W$5))/v_lift+v_lift/a_lift,2*SQRT((ABS($B19-W$5))/a_lift)))+t_pos+t_I+IF((W$5)<=0,0,IF((W$5)>=v_lift^2/a_lift,(W$5)/v_lift+v_lift/a_lift,2*SQRT((W$5)/a_lift)))+t_pos+t_ch) -> 0
